{
 "cells": [
  {
   "cell_type": "code",
   "execution_count": 17,
   "id": "106a866f-39a2-4b20-8ba6-f5ec3d556561",
   "metadata": {},
   "outputs": [],
   "source": [
    "yoi = [2020]\n",
    "toi = ['15RTN', '15RTP', '14RNS']\n",
    "spath = f\"C:/Users/mcecil/CGA/CDL/CDL_HLS_dataframe{yoi[0]}.csv\"\n",
    "url_file = f\"C:/Users/mcecil/CGA/CDL/CDL_HLS_dataframe{yoi[0]}.csv\"\n",
    "index_file = f'C:/Users/mcecil/CGA/CDL/mask_index_{yoi[0]}.csv'\n",
    "kml_file = 'C:/Users/mcecil/CGA/CDL/sentinel_tile_grid.kml'\n",
    "geojson_file = 'C:/Users/mcecil/CGA/CDL/aoi.geojson'  ## chip file, lat-long\n",
    "geojson_rpj_file = 'C:/Users/mcecil/CGA/CDL/aoi_rpj.geojson'\n",
    "hdf_dir = 'C:/Users/mcecil/CGA/CDL/hdf/'\n",
    "tiff_dir = 'C:/Users/mcecil/CGA/CDL/tif/'\n",
    "mask_dir = 'C:/Users/mcecil/CGA/CDL/mask/'\n",
    "\n",
    "tile_src_path = \"C:/Users/mcecil/CGA/CDL/tile_src.csv\""
   ]
  },
  {
   "cell_type": "code",
   "execution_count": null,
   "id": "890a508e-f65d-4df7-84e9-172ba05b627d",
   "metadata": {},
   "outputs": [],
   "source": [
    "\n",
    "# Switch plotting backend\n",
    "import matplotlib\n",
    "matplotlib.use('agg')\n",
    "\n",
    "# Import required modules\n",
    "#import cartopy.crs as ccrs\n",
    "import os\n",
    "from datetime import datetime\n",
    "import pandas as pd\n",
    "import geopandas\n",
    "import pyhdf\n",
    "import rasterio\n",
    "import rasterio.mask\n",
    "import matplotlib.pyplot as pp\n",
    "import nasa_hls\n",
    "import numpy as np\n",
    "import time\n",
    "import fiona\n",
    "from pathlib import Path\n",
    "import time\n",
    "import urllib.request as urlreq\n",
    "pd.set_option('display.max_columns', None)\n",
    "pd.set_option('display.max_rows', None)\n"
   ]
  },
  {
   "cell_type": "code",
   "execution_count": null,
   "id": "94492d6e-242f-49aa-a8a8-ca1ccbbb3ced",
   "metadata": {},
   "outputs": [],
   "source": [
    "# Load the HLS tiles and place there coordinates into a numpy array for processing later\n",
    "fiona.drvsupport.supported_drivers['KML'] = 'rw'\n",
    "tile_src = geopandas.read_file(kml_file, driver='KML')\n",
    "tile_name = []\n",
    "tile_x = []\n",
    "tile_y = []\n",
    "for tile_ind in range(tile_src.shape[0]):\n",
    "    tile_name.append(tile_src.iloc[tile_ind].Name)\n",
    "    tile_x.append(tile_src.iloc[tile_ind].geometry.centroid.x)\n",
    "    tile_y.append(tile_src.iloc[tile_ind].geometry.centroid.y)\n",
    "tile_name = np.array(tile_name)\n",
    "tile_x = np.array(tile_x)\n",
    "tile_y = np.array(tile_y)\n",
    "tile_src = pd.concat([tile_src, tile_src.bounds], axis = 1)\n",
    "#del tile_src\n",
    "tile_src.head(5)"
   ]
  },
  {
   "cell_type": "code",
   "execution_count": null,
   "id": "ae1ee1ab-d276-4bd8-ad3d-fe29d7182664",
   "metadata": {},
   "outputs": [],
   "source": [
    "# Load the HLS query csv for this year\n",
    "qfn = open(url_file)\n",
    "qtile = []\n",
    "qyear = []\n",
    "qmonth = []\n",
    "qday = []\n",
    "qdate = []\n",
    "qurl = []\n",
    "for i, line in enumerate(qfn):\n",
    "    if (i == 0): # Skip header\n",
    "        continue\n",
    "    dummy = line.split(\",\")\n",
    "    qtile.append(dummy[2])\n",
    "    qdate.append(dummy[3])\n",
    "    qurl.append(dummy[4])\n",
    "    \n",
    "    qday.append(int(dummy[3].split(\"-\")[2]))\n",
    "    qmonth.append(int(dummy[3].split(\"-\")[1]))\n",
    "    qyear.append(int(dummy[3].split(\"-\")[0]))\n",
    "qfn.close()\n",
    "qdate = np.array(qdate)\n",
    "qtile = np.array(qtile)\n",
    "qurl = np.array(qurl)\n",
    "qmonth = np.array(qmonth)\n",
    "qyear = np.array(qyear)"
   ]
  },
  {
   "cell_type": "code",
   "execution_count": null,
   "id": "db83c256-6c7b-4f86-86e0-afcbe0c1e1f0",
   "metadata": {},
   "outputs": [],
   "source": [
    "# Create the index file\n",
    "# fn_index = open(index_file, \"w\")\n",
    "# fn_index.write('EventID,Name,FireDate,MaskDate,BurnAcres,Tile,MaskFile')\n",
    "# fn_index.close()"
   ]
  },
  {
   "cell_type": "markdown",
   "id": "4ecd3a8f-73b7-400c-a0ae-0cff713066d3",
   "metadata": {},
   "source": [
    "Load geojson used for query. "
   ]
  },
  {
   "cell_type": "code",
   "execution_count": null,
   "id": "f600d0ca-467b-4ec2-a8f3-8f4b76434d6b",
   "metadata": {},
   "outputs": [],
   "source": [
    "aoi_src = geopandas.read_file(geojson_file) ## this could be a list\n",
    "nfeatures = aoi_src.shape[0]\n",
    "aoi_src = pd.concat([aoi_src, aoi_src.bounds], axis = 1)\n",
    "aoi_src['centroid_x'] = aoi_src.centroid.x\n",
    "aoi_src['centroid_y'] = aoi_src.centroid.y\n",
    "aoi_src.head(5)"
   ]
  },
  {
   "cell_type": "markdown",
   "id": "0319bc23-2006-4d35-b46e-d6d037a70f76",
   "metadata": {},
   "source": [
    "Loop through aoi_src (chips), associate closest tile, add ID field, download hdf"
   ]
  },
  {
   "cell_type": "code",
   "execution_count": null,
   "id": "d81f4f7d-d6b9-46b9-a4a5-f58f16b9700f",
   "metadata": {},
   "outputs": [],
   "source": [
    "for aoi_ind in range(nfeatures):\n",
    "    aoi_row = aoi_src.iloc[aoi_ind]\n",
    "    print(aoi_row)\n",
    "    print(aoi_src.bounds)\n",
    "    aoi_x = float(aoi_row.centroid_x)\n",
    "    aoi_y = float(aoi_row.centroid_y)\n",
    "        \n",
    "    # Identify what tile the burn scar is in\n",
    "    s = (tile_x-aoi_x)**2+(tile_y-aoi_y)**2\n",
    "    tname = tile_name[np.argmin(s)]\n",
    "    print(s)\n",
    "    print(tname)\n",
    "    aoi_src.at[aoi_ind, 'tile'] = tname\n",
    "    aoi_src.at[aoi_ind, 'chip_id'] = 'chip_' + str(aoi_ind)\n",
    "    \n",
    "    \n",
    "    # Subset potential images based on tile and date\n",
    "    tile_mask = qtile == tname\n",
    "    # Subset based on date\n",
    "    date_mask1 = (qyear == yoi[0])\n",
    "  #  diff = (qmonth-bs_month)%12\n",
    "   # date_mask2 = ((diff <= month_threshold[1]) & (diff >= month_threshold[0]))\n",
    "    date_mask = date_mask1  #& date_mask2\n",
    "    \n",
    "    mask = tile_mask & date_mask\n",
    "    candidate_dates = qdate[mask]\n",
    "    candidate_tiles = qtile[mask]\n",
    "    candidate_urls = qurl[mask]\n",
    "    # Loop through images and check cloud cover\n",
    "    for cd, ct, cu in zip(candidate_dates, candidate_tiles, candidate_urls):     \n",
    "        local_name = cu.split('/')[-1].replace(\"\\n\", \"\")\n",
    "        # Download a candidate file to check cloud cover\n",
    "        try:\n",
    "            urlreq.urlretrieve(cu, filename=hdf_dir+local_name)\n",
    "        except:\n",
    "            continue\n",
    "#aoi_src.head(5)"
   ]
  },
  {
   "cell_type": "markdown",
   "id": "104f3200-7d45-4911-91ea-527a67e56f27",
   "metadata": {},
   "source": [
    "Extract cloud cover and spatial coverage from metadata (NOT WORKING)"
   ]
  },
  {
   "cell_type": "code",
   "execution_count": null,
   "id": "f4fa0074-2fca-42f6-8ed3-545a8e05e3f7",
   "metadata": {},
   "outputs": [],
   "source": [
    "for aoi_ind in range(nfeatures):\n",
    "    aoi_row = aoi_src.iloc[aoi_ind]\n",
    "    print(aoi_row)\n",
    "    print(aoi_src.bounds)\n",
    "    aoi_x = float(aoi_row.centroid_x)\n",
    "    aoi_y = float(aoi_row.centroid_y)\n",
    "        \n",
    "    # Identify what tile the burn scar is in\n",
    "    s = (tile_x-aoi_x)**2+(tile_y-aoi_y)**2\n",
    "    tname = tile_name[np.argmin(s)]\n",
    "    print(s)\n",
    "    print(tname)\n",
    "    aoi_src.at[aoi_ind, 'tile'] = tname\n",
    "    aoi_src.at[aoi_ind, 'chip_id'] = 'chip_' + str(aoi_ind)\n",
    "    \n",
    "    # Subset potential images based on tile and date\n",
    "    tile_mask = qtile == tname\n",
    "    # Subset based on date\n",
    "    date_mask1 = (qyear == yoi[0])\n",
    "  #  diff = (qmonth-bs_month)%12\n",
    "   # date_mask2 = ((diff <= month_threshold[1]) & (diff >= month_threshold[0]))\n",
    "    date_mask = date_mask1  #& date_mask2\n",
    "    \n",
    "    mask = tile_mask & date_mask\n",
    "    candidate_dates = qdate[mask]\n",
    "    candidate_tiles = qtile[mask]\n",
    "    candidate_urls = qurl[mask]\n",
    "    # Loop through images and check cloud cover\n",
    "    for cd, ct, cu in zip(candidate_dates, candidate_tiles, candidate_urls):\n",
    "       # print(cu)\n",
    "        local_name = cu.split('/')[-1].replace(\"\\n\", \"\")\n",
    "        \n",
    "        if local_name != \"HLS.S30.T14RNS.2020117.v1.4.hdf\":\n",
    "            continue\n",
    "        # Download a candidate file to check cloud cover\n",
    "        try:\n",
    "            md = nasa_hls.get_metadata_from_hdf(hdf_dir+local_name, fields=['cloud_cover', 'spatial_coverage'])\n",
    "            print(md)\n",
    "       #     if ((md[\"cloud_cover\"] < cldfrac_threshold) and (md['spatial_coverage'] > spacecov_threshold)):\n",
    "        except:\n",
    "            continue\n",
    "        \n",
    "aoi_src.head(5)"
   ]
  },
  {
   "cell_type": "markdown",
   "id": "bd8e2252-4cf9-44ea-bb3c-84628f7d1f10",
   "metadata": {},
   "source": [
    "Convert HDF to single-layer TIF (Using HLS library, DOES NOT WORK)"
   ]
  },
  {
   "cell_type": "code",
   "execution_count": 19,
   "id": "9654ff4a-7955-4dbe-9978-8b6f61ac5d1d",
   "metadata": {},
   "outputs": [
    {
     "name": "stderr",
     "output_type": "stream",
     "text": [
      "ERROR DURING CONVERSION WITH CMD: gdal_translate HDF4_EOS:EOS_GRID:'C:\\Users\\mcecil\\CGA\\CDL\\hdf\\HLS.S30.T14RNS.2020002.v1.4.hdf':Grid:B01 C:\\Users\\mcecil\\CGA\\CDL\\tif\\HLS.S30.T14RNS.2020002.v1.4\\HLS.S30.T14RNS.2020002.v1.4__Coastal_Aerosol.tif.\n",
      "Traceback (most recent call last):\n",
      "  File \"C:\\Users\\mcecil\\AppData\\Local\\anaconda3\\envs\\IBM_CDL\\lib\\site-packages\\nasa_hls\\hdf2tiff_conversion.py\", line 82, in convert_hdf2tiffs\n",
      "    subprocess.check_call(cmd, shell=True)\n",
      "  File \"C:\\Users\\mcecil\\AppData\\Local\\anaconda3\\envs\\IBM_CDL\\lib\\subprocess.py\", line 369, in check_call\n",
      "    raise CalledProcessError(retcode, cmd)\n",
      "subprocess.CalledProcessError: Command 'gdal_translate HDF4_EOS:EOS_GRID:'C:\\Users\\mcecil\\CGA\\CDL\\hdf\\HLS.S30.T14RNS.2020002.v1.4.hdf':Grid:B01 C:\\Users\\mcecil\\CGA\\CDL\\tif\\HLS.S30.T14RNS.2020002.v1.4\\HLS.S30.T14RNS.2020002.v1.4__Coastal_Aerosol.tif' returned non-zero exit status 1.\n"
     ]
    },
    {
     "name": "stdout",
     "output_type": "stream",
     "text": [
      "geometry      POLYGON ((-98.46590447567304 28.48216163356960...\n",
      "minx                                                 -98.492844\n",
      "miny                                                  28.482162\n",
      "maxx                                                 -98.465904\n",
      "maxy                                                  28.491892\n",
      "centroid_x                                           -98.479374\n",
      "centroid_y                                            28.487027\n",
      "tile                                                      14RNS\n",
      "chip_id                                                  chip_0\n",
      "Name: 0, dtype: object\n",
      "        minx       miny       maxx       maxy\n",
      "0 -98.492844  28.482162 -98.465904  28.491892\n",
      "[69873.57854445 26546.24690202 22692.05707804 ... 15908.73972509\n",
      " 12442.80659328  9532.39628432]\n",
      "14RNS\n"
     ]
    },
    {
     "name": "stderr",
     "output_type": "stream",
     "text": [
      "ERROR DURING CONVERSION WITH CMD: gdal_translate HDF4_EOS:EOS_GRID:'C:\\Users\\mcecil\\CGA\\CDL\\hdf\\HLS.S30.T14RNS.2020002.v1.4.hdf':Grid:B02 C:\\Users\\mcecil\\CGA\\CDL\\tif\\HLS.S30.T14RNS.2020002.v1.4\\HLS.S30.T14RNS.2020002.v1.4__Blue.tif.\n",
      "Traceback (most recent call last):\n",
      "  File \"C:\\Users\\mcecil\\AppData\\Local\\anaconda3\\envs\\IBM_CDL\\lib\\site-packages\\nasa_hls\\hdf2tiff_conversion.py\", line 82, in convert_hdf2tiffs\n",
      "    subprocess.check_call(cmd, shell=True)\n",
      "  File \"C:\\Users\\mcecil\\AppData\\Local\\anaconda3\\envs\\IBM_CDL\\lib\\subprocess.py\", line 369, in check_call\n",
      "    raise CalledProcessError(retcode, cmd)\n",
      "subprocess.CalledProcessError: Command 'gdal_translate HDF4_EOS:EOS_GRID:'C:\\Users\\mcecil\\CGA\\CDL\\hdf\\HLS.S30.T14RNS.2020002.v1.4.hdf':Grid:B02 C:\\Users\\mcecil\\CGA\\CDL\\tif\\HLS.S30.T14RNS.2020002.v1.4\\HLS.S30.T14RNS.2020002.v1.4__Blue.tif' returned non-zero exit status 1.\n",
      "ERROR DURING CONVERSION WITH CMD: gdal_translate HDF4_EOS:EOS_GRID:'C:\\Users\\mcecil\\CGA\\CDL\\hdf\\HLS.S30.T14RNS.2020002.v1.4.hdf':Grid:B03 C:\\Users\\mcecil\\CGA\\CDL\\tif\\HLS.S30.T14RNS.2020002.v1.4\\HLS.S30.T14RNS.2020002.v1.4__Green.tif.\n",
      "Traceback (most recent call last):\n",
      "  File \"C:\\Users\\mcecil\\AppData\\Local\\anaconda3\\envs\\IBM_CDL\\lib\\site-packages\\nasa_hls\\hdf2tiff_conversion.py\", line 82, in convert_hdf2tiffs\n",
      "    subprocess.check_call(cmd, shell=True)\n",
      "  File \"C:\\Users\\mcecil\\AppData\\Local\\anaconda3\\envs\\IBM_CDL\\lib\\subprocess.py\", line 369, in check_call\n",
      "    raise CalledProcessError(retcode, cmd)\n",
      "subprocess.CalledProcessError: Command 'gdal_translate HDF4_EOS:EOS_GRID:'C:\\Users\\mcecil\\CGA\\CDL\\hdf\\HLS.S30.T14RNS.2020002.v1.4.hdf':Grid:B03 C:\\Users\\mcecil\\CGA\\CDL\\tif\\HLS.S30.T14RNS.2020002.v1.4\\HLS.S30.T14RNS.2020002.v1.4__Green.tif' returned non-zero exit status 1.\n",
      "ERROR DURING CONVERSION WITH CMD: gdal_translate HDF4_EOS:EOS_GRID:'C:\\Users\\mcecil\\CGA\\CDL\\hdf\\HLS.S30.T14RNS.2020002.v1.4.hdf':Grid:B04 C:\\Users\\mcecil\\CGA\\CDL\\tif\\HLS.S30.T14RNS.2020002.v1.4\\HLS.S30.T14RNS.2020002.v1.4__Red.tif.\n",
      "Traceback (most recent call last):\n",
      "  File \"C:\\Users\\mcecil\\AppData\\Local\\anaconda3\\envs\\IBM_CDL\\lib\\site-packages\\nasa_hls\\hdf2tiff_conversion.py\", line 82, in convert_hdf2tiffs\n",
      "    subprocess.check_call(cmd, shell=True)\n",
      "  File \"C:\\Users\\mcecil\\AppData\\Local\\anaconda3\\envs\\IBM_CDL\\lib\\subprocess.py\", line 369, in check_call\n",
      "    raise CalledProcessError(retcode, cmd)\n",
      "subprocess.CalledProcessError: Command 'gdal_translate HDF4_EOS:EOS_GRID:'C:\\Users\\mcecil\\CGA\\CDL\\hdf\\HLS.S30.T14RNS.2020002.v1.4.hdf':Grid:B04 C:\\Users\\mcecil\\CGA\\CDL\\tif\\HLS.S30.T14RNS.2020002.v1.4\\HLS.S30.T14RNS.2020002.v1.4__Red.tif' returned non-zero exit status 1.\n",
      "ERROR DURING CONVERSION WITH CMD: gdal_translate HDF4_EOS:EOS_GRID:'C:\\Users\\mcecil\\CGA\\CDL\\hdf\\HLS.S30.T14RNS.2020002.v1.4.hdf':Grid:B05 C:\\Users\\mcecil\\CGA\\CDL\\tif\\HLS.S30.T14RNS.2020002.v1.4\\HLS.S30.T14RNS.2020002.v1.4__Red_Edge1.tif.\n",
      "Traceback (most recent call last):\n",
      "  File \"C:\\Users\\mcecil\\AppData\\Local\\anaconda3\\envs\\IBM_CDL\\lib\\site-packages\\nasa_hls\\hdf2tiff_conversion.py\", line 82, in convert_hdf2tiffs\n",
      "    subprocess.check_call(cmd, shell=True)\n",
      "  File \"C:\\Users\\mcecil\\AppData\\Local\\anaconda3\\envs\\IBM_CDL\\lib\\subprocess.py\", line 369, in check_call\n",
      "    raise CalledProcessError(retcode, cmd)\n",
      "subprocess.CalledProcessError: Command 'gdal_translate HDF4_EOS:EOS_GRID:'C:\\Users\\mcecil\\CGA\\CDL\\hdf\\HLS.S30.T14RNS.2020002.v1.4.hdf':Grid:B05 C:\\Users\\mcecil\\CGA\\CDL\\tif\\HLS.S30.T14RNS.2020002.v1.4\\HLS.S30.T14RNS.2020002.v1.4__Red_Edge1.tif' returned non-zero exit status 1.\n",
      "ERROR DURING CONVERSION WITH CMD: gdal_translate HDF4_EOS:EOS_GRID:'C:\\Users\\mcecil\\CGA\\CDL\\hdf\\HLS.S30.T14RNS.2020002.v1.4.hdf':Grid:B06 C:\\Users\\mcecil\\CGA\\CDL\\tif\\HLS.S30.T14RNS.2020002.v1.4\\HLS.S30.T14RNS.2020002.v1.4__Red_Edge2.tif.\n",
      "Traceback (most recent call last):\n",
      "  File \"C:\\Users\\mcecil\\AppData\\Local\\anaconda3\\envs\\IBM_CDL\\lib\\site-packages\\nasa_hls\\hdf2tiff_conversion.py\", line 82, in convert_hdf2tiffs\n",
      "    subprocess.check_call(cmd, shell=True)\n",
      "  File \"C:\\Users\\mcecil\\AppData\\Local\\anaconda3\\envs\\IBM_CDL\\lib\\subprocess.py\", line 369, in check_call\n",
      "    raise CalledProcessError(retcode, cmd)\n",
      "subprocess.CalledProcessError: Command 'gdal_translate HDF4_EOS:EOS_GRID:'C:\\Users\\mcecil\\CGA\\CDL\\hdf\\HLS.S30.T14RNS.2020002.v1.4.hdf':Grid:B06 C:\\Users\\mcecil\\CGA\\CDL\\tif\\HLS.S30.T14RNS.2020002.v1.4\\HLS.S30.T14RNS.2020002.v1.4__Red_Edge2.tif' returned non-zero exit status 1.\n",
      "ERROR DURING CONVERSION WITH CMD: gdal_translate HDF4_EOS:EOS_GRID:'C:\\Users\\mcecil\\CGA\\CDL\\hdf\\HLS.S30.T14RNS.2020002.v1.4.hdf':Grid:B07 C:\\Users\\mcecil\\CGA\\CDL\\tif\\HLS.S30.T14RNS.2020002.v1.4\\HLS.S30.T14RNS.2020002.v1.4__Red_Edge3.tif.\n",
      "Traceback (most recent call last):\n",
      "  File \"C:\\Users\\mcecil\\AppData\\Local\\anaconda3\\envs\\IBM_CDL\\lib\\site-packages\\nasa_hls\\hdf2tiff_conversion.py\", line 82, in convert_hdf2tiffs\n",
      "    subprocess.check_call(cmd, shell=True)\n",
      "  File \"C:\\Users\\mcecil\\AppData\\Local\\anaconda3\\envs\\IBM_CDL\\lib\\subprocess.py\", line 369, in check_call\n",
      "    raise CalledProcessError(retcode, cmd)\n",
      "subprocess.CalledProcessError: Command 'gdal_translate HDF4_EOS:EOS_GRID:'C:\\Users\\mcecil\\CGA\\CDL\\hdf\\HLS.S30.T14RNS.2020002.v1.4.hdf':Grid:B07 C:\\Users\\mcecil\\CGA\\CDL\\tif\\HLS.S30.T14RNS.2020002.v1.4\\HLS.S30.T14RNS.2020002.v1.4__Red_Edge3.tif' returned non-zero exit status 1.\n",
      "ERROR DURING CONVERSION WITH CMD: gdal_translate HDF4_EOS:EOS_GRID:'C:\\Users\\mcecil\\CGA\\CDL\\hdf\\HLS.S30.T14RNS.2020002.v1.4.hdf':Grid:B08 C:\\Users\\mcecil\\CGA\\CDL\\tif\\HLS.S30.T14RNS.2020002.v1.4\\HLS.S30.T14RNS.2020002.v1.4__NIR_Broad.tif.\n",
      "Traceback (most recent call last):\n",
      "  File \"C:\\Users\\mcecil\\AppData\\Local\\anaconda3\\envs\\IBM_CDL\\lib\\site-packages\\nasa_hls\\hdf2tiff_conversion.py\", line 82, in convert_hdf2tiffs\n",
      "    subprocess.check_call(cmd, shell=True)\n",
      "  File \"C:\\Users\\mcecil\\AppData\\Local\\anaconda3\\envs\\IBM_CDL\\lib\\subprocess.py\", line 369, in check_call\n",
      "    raise CalledProcessError(retcode, cmd)\n",
      "subprocess.CalledProcessError: Command 'gdal_translate HDF4_EOS:EOS_GRID:'C:\\Users\\mcecil\\CGA\\CDL\\hdf\\HLS.S30.T14RNS.2020002.v1.4.hdf':Grid:B08 C:\\Users\\mcecil\\CGA\\CDL\\tif\\HLS.S30.T14RNS.2020002.v1.4\\HLS.S30.T14RNS.2020002.v1.4__NIR_Broad.tif' returned non-zero exit status 1.\n",
      "ERROR DURING CONVERSION WITH CMD: gdal_translate HDF4_EOS:EOS_GRID:'C:\\Users\\mcecil\\CGA\\CDL\\hdf\\HLS.S30.T14RNS.2020002.v1.4.hdf':Grid:B8A C:\\Users\\mcecil\\CGA\\CDL\\tif\\HLS.S30.T14RNS.2020002.v1.4\\HLS.S30.T14RNS.2020002.v1.4__NIR_Narrow.tif.\n",
      "Traceback (most recent call last):\n",
      "  File \"C:\\Users\\mcecil\\AppData\\Local\\anaconda3\\envs\\IBM_CDL\\lib\\site-packages\\nasa_hls\\hdf2tiff_conversion.py\", line 82, in convert_hdf2tiffs\n",
      "    subprocess.check_call(cmd, shell=True)\n",
      "  File \"C:\\Users\\mcecil\\AppData\\Local\\anaconda3\\envs\\IBM_CDL\\lib\\subprocess.py\", line 369, in check_call\n",
      "    raise CalledProcessError(retcode, cmd)\n",
      "subprocess.CalledProcessError: Command 'gdal_translate HDF4_EOS:EOS_GRID:'C:\\Users\\mcecil\\CGA\\CDL\\hdf\\HLS.S30.T14RNS.2020002.v1.4.hdf':Grid:B8A C:\\Users\\mcecil\\CGA\\CDL\\tif\\HLS.S30.T14RNS.2020002.v1.4\\HLS.S30.T14RNS.2020002.v1.4__NIR_Narrow.tif' returned non-zero exit status 1.\n",
      "ERROR DURING CONVERSION WITH CMD: gdal_translate HDF4_EOS:EOS_GRID:'C:\\Users\\mcecil\\CGA\\CDL\\hdf\\HLS.S30.T14RNS.2020002.v1.4.hdf':Grid:B09 C:\\Users\\mcecil\\CGA\\CDL\\tif\\HLS.S30.T14RNS.2020002.v1.4\\HLS.S30.T14RNS.2020002.v1.4__Water_Vapor.tif.\n",
      "Traceback (most recent call last):\n",
      "  File \"C:\\Users\\mcecil\\AppData\\Local\\anaconda3\\envs\\IBM_CDL\\lib\\site-packages\\nasa_hls\\hdf2tiff_conversion.py\", line 82, in convert_hdf2tiffs\n",
      "    subprocess.check_call(cmd, shell=True)\n",
      "  File \"C:\\Users\\mcecil\\AppData\\Local\\anaconda3\\envs\\IBM_CDL\\lib\\subprocess.py\", line 369, in check_call\n",
      "    raise CalledProcessError(retcode, cmd)\n",
      "subprocess.CalledProcessError: Command 'gdal_translate HDF4_EOS:EOS_GRID:'C:\\Users\\mcecil\\CGA\\CDL\\hdf\\HLS.S30.T14RNS.2020002.v1.4.hdf':Grid:B09 C:\\Users\\mcecil\\CGA\\CDL\\tif\\HLS.S30.T14RNS.2020002.v1.4\\HLS.S30.T14RNS.2020002.v1.4__Water_Vapor.tif' returned non-zero exit status 1.\n",
      "ERROR DURING CONVERSION WITH CMD: gdal_translate HDF4_EOS:EOS_GRID:'C:\\Users\\mcecil\\CGA\\CDL\\hdf\\HLS.S30.T14RNS.2020002.v1.4.hdf':Grid:B10 C:\\Users\\mcecil\\CGA\\CDL\\tif\\HLS.S30.T14RNS.2020002.v1.4\\HLS.S30.T14RNS.2020002.v1.4__Cirrus.tif.\n",
      "Traceback (most recent call last):\n",
      "  File \"C:\\Users\\mcecil\\AppData\\Local\\anaconda3\\envs\\IBM_CDL\\lib\\site-packages\\nasa_hls\\hdf2tiff_conversion.py\", line 82, in convert_hdf2tiffs\n",
      "    subprocess.check_call(cmd, shell=True)\n",
      "  File \"C:\\Users\\mcecil\\AppData\\Local\\anaconda3\\envs\\IBM_CDL\\lib\\subprocess.py\", line 369, in check_call\n",
      "    raise CalledProcessError(retcode, cmd)\n",
      "subprocess.CalledProcessError: Command 'gdal_translate HDF4_EOS:EOS_GRID:'C:\\Users\\mcecil\\CGA\\CDL\\hdf\\HLS.S30.T14RNS.2020002.v1.4.hdf':Grid:B10 C:\\Users\\mcecil\\CGA\\CDL\\tif\\HLS.S30.T14RNS.2020002.v1.4\\HLS.S30.T14RNS.2020002.v1.4__Cirrus.tif' returned non-zero exit status 1.\n",
      "ERROR DURING CONVERSION WITH CMD: gdal_translate HDF4_EOS:EOS_GRID:'C:\\Users\\mcecil\\CGA\\CDL\\hdf\\HLS.S30.T14RNS.2020002.v1.4.hdf':Grid:B11 C:\\Users\\mcecil\\CGA\\CDL\\tif\\HLS.S30.T14RNS.2020002.v1.4\\HLS.S30.T14RNS.2020002.v1.4__SWIR1.tif.\n",
      "Traceback (most recent call last):\n",
      "  File \"C:\\Users\\mcecil\\AppData\\Local\\anaconda3\\envs\\IBM_CDL\\lib\\site-packages\\nasa_hls\\hdf2tiff_conversion.py\", line 82, in convert_hdf2tiffs\n",
      "    subprocess.check_call(cmd, shell=True)\n",
      "  File \"C:\\Users\\mcecil\\AppData\\Local\\anaconda3\\envs\\IBM_CDL\\lib\\subprocess.py\", line 369, in check_call\n",
      "    raise CalledProcessError(retcode, cmd)\n",
      "subprocess.CalledProcessError: Command 'gdal_translate HDF4_EOS:EOS_GRID:'C:\\Users\\mcecil\\CGA\\CDL\\hdf\\HLS.S30.T14RNS.2020002.v1.4.hdf':Grid:B11 C:\\Users\\mcecil\\CGA\\CDL\\tif\\HLS.S30.T14RNS.2020002.v1.4\\HLS.S30.T14RNS.2020002.v1.4__SWIR1.tif' returned non-zero exit status 1.\n",
      "ERROR DURING CONVERSION WITH CMD: gdal_translate HDF4_EOS:EOS_GRID:'C:\\Users\\mcecil\\CGA\\CDL\\hdf\\HLS.S30.T14RNS.2020002.v1.4.hdf':Grid:B12 C:\\Users\\mcecil\\CGA\\CDL\\tif\\HLS.S30.T14RNS.2020002.v1.4\\HLS.S30.T14RNS.2020002.v1.4__SWIR2.tif.\n",
      "Traceback (most recent call last):\n",
      "  File \"C:\\Users\\mcecil\\AppData\\Local\\anaconda3\\envs\\IBM_CDL\\lib\\site-packages\\nasa_hls\\hdf2tiff_conversion.py\", line 82, in convert_hdf2tiffs\n",
      "    subprocess.check_call(cmd, shell=True)\n",
      "  File \"C:\\Users\\mcecil\\AppData\\Local\\anaconda3\\envs\\IBM_CDL\\lib\\subprocess.py\", line 369, in check_call\n",
      "    raise CalledProcessError(retcode, cmd)\n",
      "subprocess.CalledProcessError: Command 'gdal_translate HDF4_EOS:EOS_GRID:'C:\\Users\\mcecil\\CGA\\CDL\\hdf\\HLS.S30.T14RNS.2020002.v1.4.hdf':Grid:B12 C:\\Users\\mcecil\\CGA\\CDL\\tif\\HLS.S30.T14RNS.2020002.v1.4\\HLS.S30.T14RNS.2020002.v1.4__SWIR2.tif' returned non-zero exit status 1.\n",
      "ERROR DURING CONVERSION WITH CMD: gdal_translate HDF4_EOS:EOS_GRID:'C:\\Users\\mcecil\\CGA\\CDL\\hdf\\HLS.S30.T14RNS.2020002.v1.4.hdf':Grid:QA C:\\Users\\mcecil\\CGA\\CDL\\tif\\HLS.S30.T14RNS.2020002.v1.4\\HLS.S30.T14RNS.2020002.v1.4__QA.tif.\n",
      "Traceback (most recent call last):\n",
      "  File \"C:\\Users\\mcecil\\AppData\\Local\\anaconda3\\envs\\IBM_CDL\\lib\\site-packages\\nasa_hls\\hdf2tiff_conversion.py\", line 82, in convert_hdf2tiffs\n",
      "    subprocess.check_call(cmd, shell=True)\n",
      "  File \"C:\\Users\\mcecil\\AppData\\Local\\anaconda3\\envs\\IBM_CDL\\lib\\subprocess.py\", line 369, in check_call\n",
      "    raise CalledProcessError(retcode, cmd)\n",
      "subprocess.CalledProcessError: Command 'gdal_translate HDF4_EOS:EOS_GRID:'C:\\Users\\mcecil\\CGA\\CDL\\hdf\\HLS.S30.T14RNS.2020002.v1.4.hdf':Grid:QA C:\\Users\\mcecil\\CGA\\CDL\\tif\\HLS.S30.T14RNS.2020002.v1.4\\HLS.S30.T14RNS.2020002.v1.4__QA.tif' returned non-zero exit status 1.\n",
      "ERROR DURING CONVERSION WITH CMD: gdal_translate HDF4_EOS:EOS_GRID:'C:\\Users\\mcecil\\CGA\\CDL\\hdf\\HLS.S30.T14RNS.2020005.v1.4.hdf':Grid:B01 C:\\Users\\mcecil\\CGA\\CDL\\tif\\HLS.S30.T14RNS.2020005.v1.4\\HLS.S30.T14RNS.2020005.v1.4__Coastal_Aerosol.tif.\n",
      "Traceback (most recent call last):\n",
      "  File \"C:\\Users\\mcecil\\AppData\\Local\\anaconda3\\envs\\IBM_CDL\\lib\\site-packages\\nasa_hls\\hdf2tiff_conversion.py\", line 82, in convert_hdf2tiffs\n",
      "    subprocess.check_call(cmd, shell=True)\n",
      "  File \"C:\\Users\\mcecil\\AppData\\Local\\anaconda3\\envs\\IBM_CDL\\lib\\subprocess.py\", line 369, in check_call\n",
      "    raise CalledProcessError(retcode, cmd)\n",
      "subprocess.CalledProcessError: Command 'gdal_translate HDF4_EOS:EOS_GRID:'C:\\Users\\mcecil\\CGA\\CDL\\hdf\\HLS.S30.T14RNS.2020005.v1.4.hdf':Grid:B01 C:\\Users\\mcecil\\CGA\\CDL\\tif\\HLS.S30.T14RNS.2020005.v1.4\\HLS.S30.T14RNS.2020005.v1.4__Coastal_Aerosol.tif' returned non-zero exit status 1.\n",
      "ERROR DURING CONVERSION WITH CMD: gdal_translate HDF4_EOS:EOS_GRID:'C:\\Users\\mcecil\\CGA\\CDL\\hdf\\HLS.S30.T14RNS.2020005.v1.4.hdf':Grid:B02 C:\\Users\\mcecil\\CGA\\CDL\\tif\\HLS.S30.T14RNS.2020005.v1.4\\HLS.S30.T14RNS.2020005.v1.4__Blue.tif.\n",
      "Traceback (most recent call last):\n",
      "  File \"C:\\Users\\mcecil\\AppData\\Local\\anaconda3\\envs\\IBM_CDL\\lib\\site-packages\\nasa_hls\\hdf2tiff_conversion.py\", line 82, in convert_hdf2tiffs\n",
      "    subprocess.check_call(cmd, shell=True)\n",
      "  File \"C:\\Users\\mcecil\\AppData\\Local\\anaconda3\\envs\\IBM_CDL\\lib\\subprocess.py\", line 369, in check_call\n",
      "    raise CalledProcessError(retcode, cmd)\n",
      "subprocess.CalledProcessError: Command 'gdal_translate HDF4_EOS:EOS_GRID:'C:\\Users\\mcecil\\CGA\\CDL\\hdf\\HLS.S30.T14RNS.2020005.v1.4.hdf':Grid:B02 C:\\Users\\mcecil\\CGA\\CDL\\tif\\HLS.S30.T14RNS.2020005.v1.4\\HLS.S30.T14RNS.2020005.v1.4__Blue.tif' returned non-zero exit status 1.\n",
      "ERROR DURING CONVERSION WITH CMD: gdal_translate HDF4_EOS:EOS_GRID:'C:\\Users\\mcecil\\CGA\\CDL\\hdf\\HLS.S30.T14RNS.2020005.v1.4.hdf':Grid:B03 C:\\Users\\mcecil\\CGA\\CDL\\tif\\HLS.S30.T14RNS.2020005.v1.4\\HLS.S30.T14RNS.2020005.v1.4__Green.tif.\n",
      "Traceback (most recent call last):\n",
      "  File \"C:\\Users\\mcecil\\AppData\\Local\\anaconda3\\envs\\IBM_CDL\\lib\\site-packages\\nasa_hls\\hdf2tiff_conversion.py\", line 82, in convert_hdf2tiffs\n",
      "    subprocess.check_call(cmd, shell=True)\n",
      "  File \"C:\\Users\\mcecil\\AppData\\Local\\anaconda3\\envs\\IBM_CDL\\lib\\subprocess.py\", line 369, in check_call\n",
      "    raise CalledProcessError(retcode, cmd)\n",
      "subprocess.CalledProcessError: Command 'gdal_translate HDF4_EOS:EOS_GRID:'C:\\Users\\mcecil\\CGA\\CDL\\hdf\\HLS.S30.T14RNS.2020005.v1.4.hdf':Grid:B03 C:\\Users\\mcecil\\CGA\\CDL\\tif\\HLS.S30.T14RNS.2020005.v1.4\\HLS.S30.T14RNS.2020005.v1.4__Green.tif' returned non-zero exit status 1.\n",
      "ERROR DURING CONVERSION WITH CMD: gdal_translate HDF4_EOS:EOS_GRID:'C:\\Users\\mcecil\\CGA\\CDL\\hdf\\HLS.S30.T14RNS.2020005.v1.4.hdf':Grid:B04 C:\\Users\\mcecil\\CGA\\CDL\\tif\\HLS.S30.T14RNS.2020005.v1.4\\HLS.S30.T14RNS.2020005.v1.4__Red.tif.\n",
      "Traceback (most recent call last):\n",
      "  File \"C:\\Users\\mcecil\\AppData\\Local\\anaconda3\\envs\\IBM_CDL\\lib\\site-packages\\nasa_hls\\hdf2tiff_conversion.py\", line 82, in convert_hdf2tiffs\n",
      "    subprocess.check_call(cmd, shell=True)\n",
      "  File \"C:\\Users\\mcecil\\AppData\\Local\\anaconda3\\envs\\IBM_CDL\\lib\\subprocess.py\", line 369, in check_call\n",
      "    raise CalledProcessError(retcode, cmd)\n",
      "subprocess.CalledProcessError: Command 'gdal_translate HDF4_EOS:EOS_GRID:'C:\\Users\\mcecil\\CGA\\CDL\\hdf\\HLS.S30.T14RNS.2020005.v1.4.hdf':Grid:B04 C:\\Users\\mcecil\\CGA\\CDL\\tif\\HLS.S30.T14RNS.2020005.v1.4\\HLS.S30.T14RNS.2020005.v1.4__Red.tif' returned non-zero exit status 1.\n",
      "ERROR DURING CONVERSION WITH CMD: gdal_translate HDF4_EOS:EOS_GRID:'C:\\Users\\mcecil\\CGA\\CDL\\hdf\\HLS.S30.T14RNS.2020005.v1.4.hdf':Grid:B05 C:\\Users\\mcecil\\CGA\\CDL\\tif\\HLS.S30.T14RNS.2020005.v1.4\\HLS.S30.T14RNS.2020005.v1.4__Red_Edge1.tif.\n",
      "Traceback (most recent call last):\n",
      "  File \"C:\\Users\\mcecil\\AppData\\Local\\anaconda3\\envs\\IBM_CDL\\lib\\site-packages\\nasa_hls\\hdf2tiff_conversion.py\", line 82, in convert_hdf2tiffs\n",
      "    subprocess.check_call(cmd, shell=True)\n",
      "  File \"C:\\Users\\mcecil\\AppData\\Local\\anaconda3\\envs\\IBM_CDL\\lib\\subprocess.py\", line 369, in check_call\n",
      "    raise CalledProcessError(retcode, cmd)\n",
      "subprocess.CalledProcessError: Command 'gdal_translate HDF4_EOS:EOS_GRID:'C:\\Users\\mcecil\\CGA\\CDL\\hdf\\HLS.S30.T14RNS.2020005.v1.4.hdf':Grid:B05 C:\\Users\\mcecil\\CGA\\CDL\\tif\\HLS.S30.T14RNS.2020005.v1.4\\HLS.S30.T14RNS.2020005.v1.4__Red_Edge1.tif' returned non-zero exit status 1.\n",
      "ERROR DURING CONVERSION WITH CMD: gdal_translate HDF4_EOS:EOS_GRID:'C:\\Users\\mcecil\\CGA\\CDL\\hdf\\HLS.S30.T14RNS.2020005.v1.4.hdf':Grid:B06 C:\\Users\\mcecil\\CGA\\CDL\\tif\\HLS.S30.T14RNS.2020005.v1.4\\HLS.S30.T14RNS.2020005.v1.4__Red_Edge2.tif.\n",
      "Traceback (most recent call last):\n",
      "  File \"C:\\Users\\mcecil\\AppData\\Local\\anaconda3\\envs\\IBM_CDL\\lib\\site-packages\\nasa_hls\\hdf2tiff_conversion.py\", line 82, in convert_hdf2tiffs\n",
      "    subprocess.check_call(cmd, shell=True)\n",
      "  File \"C:\\Users\\mcecil\\AppData\\Local\\anaconda3\\envs\\IBM_CDL\\lib\\subprocess.py\", line 369, in check_call\n",
      "    raise CalledProcessError(retcode, cmd)\n",
      "subprocess.CalledProcessError: Command 'gdal_translate HDF4_EOS:EOS_GRID:'C:\\Users\\mcecil\\CGA\\CDL\\hdf\\HLS.S30.T14RNS.2020005.v1.4.hdf':Grid:B06 C:\\Users\\mcecil\\CGA\\CDL\\tif\\HLS.S30.T14RNS.2020005.v1.4\\HLS.S30.T14RNS.2020005.v1.4__Red_Edge2.tif' returned non-zero exit status 1.\n",
      "ERROR DURING CONVERSION WITH CMD: gdal_translate HDF4_EOS:EOS_GRID:'C:\\Users\\mcecil\\CGA\\CDL\\hdf\\HLS.S30.T14RNS.2020005.v1.4.hdf':Grid:B07 C:\\Users\\mcecil\\CGA\\CDL\\tif\\HLS.S30.T14RNS.2020005.v1.4\\HLS.S30.T14RNS.2020005.v1.4__Red_Edge3.tif.\n",
      "Traceback (most recent call last):\n",
      "  File \"C:\\Users\\mcecil\\AppData\\Local\\anaconda3\\envs\\IBM_CDL\\lib\\site-packages\\nasa_hls\\hdf2tiff_conversion.py\", line 82, in convert_hdf2tiffs\n",
      "    subprocess.check_call(cmd, shell=True)\n",
      "  File \"C:\\Users\\mcecil\\AppData\\Local\\anaconda3\\envs\\IBM_CDL\\lib\\subprocess.py\", line 369, in check_call\n",
      "    raise CalledProcessError(retcode, cmd)\n",
      "subprocess.CalledProcessError: Command 'gdal_translate HDF4_EOS:EOS_GRID:'C:\\Users\\mcecil\\CGA\\CDL\\hdf\\HLS.S30.T14RNS.2020005.v1.4.hdf':Grid:B07 C:\\Users\\mcecil\\CGA\\CDL\\tif\\HLS.S30.T14RNS.2020005.v1.4\\HLS.S30.T14RNS.2020005.v1.4__Red_Edge3.tif' returned non-zero exit status 1.\n",
      "ERROR DURING CONVERSION WITH CMD: gdal_translate HDF4_EOS:EOS_GRID:'C:\\Users\\mcecil\\CGA\\CDL\\hdf\\HLS.S30.T14RNS.2020005.v1.4.hdf':Grid:B08 C:\\Users\\mcecil\\CGA\\CDL\\tif\\HLS.S30.T14RNS.2020005.v1.4\\HLS.S30.T14RNS.2020005.v1.4__NIR_Broad.tif.\n",
      "Traceback (most recent call last):\n",
      "  File \"C:\\Users\\mcecil\\AppData\\Local\\anaconda3\\envs\\IBM_CDL\\lib\\site-packages\\nasa_hls\\hdf2tiff_conversion.py\", line 82, in convert_hdf2tiffs\n",
      "    subprocess.check_call(cmd, shell=True)\n",
      "  File \"C:\\Users\\mcecil\\AppData\\Local\\anaconda3\\envs\\IBM_CDL\\lib\\subprocess.py\", line 369, in check_call\n",
      "    raise CalledProcessError(retcode, cmd)\n",
      "subprocess.CalledProcessError: Command 'gdal_translate HDF4_EOS:EOS_GRID:'C:\\Users\\mcecil\\CGA\\CDL\\hdf\\HLS.S30.T14RNS.2020005.v1.4.hdf':Grid:B08 C:\\Users\\mcecil\\CGA\\CDL\\tif\\HLS.S30.T14RNS.2020005.v1.4\\HLS.S30.T14RNS.2020005.v1.4__NIR_Broad.tif' returned non-zero exit status 1.\n",
      "ERROR DURING CONVERSION WITH CMD: gdal_translate HDF4_EOS:EOS_GRID:'C:\\Users\\mcecil\\CGA\\CDL\\hdf\\HLS.S30.T14RNS.2020005.v1.4.hdf':Grid:B8A C:\\Users\\mcecil\\CGA\\CDL\\tif\\HLS.S30.T14RNS.2020005.v1.4\\HLS.S30.T14RNS.2020005.v1.4__NIR_Narrow.tif.\n",
      "Traceback (most recent call last):\n",
      "  File \"C:\\Users\\mcecil\\AppData\\Local\\anaconda3\\envs\\IBM_CDL\\lib\\site-packages\\nasa_hls\\hdf2tiff_conversion.py\", line 82, in convert_hdf2tiffs\n",
      "    subprocess.check_call(cmd, shell=True)\n",
      "  File \"C:\\Users\\mcecil\\AppData\\Local\\anaconda3\\envs\\IBM_CDL\\lib\\subprocess.py\", line 369, in check_call\n",
      "    raise CalledProcessError(retcode, cmd)\n",
      "subprocess.CalledProcessError: Command 'gdal_translate HDF4_EOS:EOS_GRID:'C:\\Users\\mcecil\\CGA\\CDL\\hdf\\HLS.S30.T14RNS.2020005.v1.4.hdf':Grid:B8A C:\\Users\\mcecil\\CGA\\CDL\\tif\\HLS.S30.T14RNS.2020005.v1.4\\HLS.S30.T14RNS.2020005.v1.4__NIR_Narrow.tif' returned non-zero exit status 1.\n",
      "ERROR DURING CONVERSION WITH CMD: gdal_translate HDF4_EOS:EOS_GRID:'C:\\Users\\mcecil\\CGA\\CDL\\hdf\\HLS.S30.T14RNS.2020005.v1.4.hdf':Grid:B09 C:\\Users\\mcecil\\CGA\\CDL\\tif\\HLS.S30.T14RNS.2020005.v1.4\\HLS.S30.T14RNS.2020005.v1.4__Water_Vapor.tif.\n",
      "Traceback (most recent call last):\n",
      "  File \"C:\\Users\\mcecil\\AppData\\Local\\anaconda3\\envs\\IBM_CDL\\lib\\site-packages\\nasa_hls\\hdf2tiff_conversion.py\", line 82, in convert_hdf2tiffs\n",
      "    subprocess.check_call(cmd, shell=True)\n",
      "  File \"C:\\Users\\mcecil\\AppData\\Local\\anaconda3\\envs\\IBM_CDL\\lib\\subprocess.py\", line 369, in check_call\n",
      "    raise CalledProcessError(retcode, cmd)\n",
      "subprocess.CalledProcessError: Command 'gdal_translate HDF4_EOS:EOS_GRID:'C:\\Users\\mcecil\\CGA\\CDL\\hdf\\HLS.S30.T14RNS.2020005.v1.4.hdf':Grid:B09 C:\\Users\\mcecil\\CGA\\CDL\\tif\\HLS.S30.T14RNS.2020005.v1.4\\HLS.S30.T14RNS.2020005.v1.4__Water_Vapor.tif' returned non-zero exit status 1.\n",
      "ERROR DURING CONVERSION WITH CMD: gdal_translate HDF4_EOS:EOS_GRID:'C:\\Users\\mcecil\\CGA\\CDL\\hdf\\HLS.S30.T14RNS.2020005.v1.4.hdf':Grid:B10 C:\\Users\\mcecil\\CGA\\CDL\\tif\\HLS.S30.T14RNS.2020005.v1.4\\HLS.S30.T14RNS.2020005.v1.4__Cirrus.tif.\n",
      "Traceback (most recent call last):\n",
      "  File \"C:\\Users\\mcecil\\AppData\\Local\\anaconda3\\envs\\IBM_CDL\\lib\\site-packages\\nasa_hls\\hdf2tiff_conversion.py\", line 82, in convert_hdf2tiffs\n",
      "    subprocess.check_call(cmd, shell=True)\n",
      "  File \"C:\\Users\\mcecil\\AppData\\Local\\anaconda3\\envs\\IBM_CDL\\lib\\subprocess.py\", line 369, in check_call\n",
      "    raise CalledProcessError(retcode, cmd)\n",
      "subprocess.CalledProcessError: Command 'gdal_translate HDF4_EOS:EOS_GRID:'C:\\Users\\mcecil\\CGA\\CDL\\hdf\\HLS.S30.T14RNS.2020005.v1.4.hdf':Grid:B10 C:\\Users\\mcecil\\CGA\\CDL\\tif\\HLS.S30.T14RNS.2020005.v1.4\\HLS.S30.T14RNS.2020005.v1.4__Cirrus.tif' returned non-zero exit status 1.\n",
      "ERROR DURING CONVERSION WITH CMD: gdal_translate HDF4_EOS:EOS_GRID:'C:\\Users\\mcecil\\CGA\\CDL\\hdf\\HLS.S30.T14RNS.2020005.v1.4.hdf':Grid:B11 C:\\Users\\mcecil\\CGA\\CDL\\tif\\HLS.S30.T14RNS.2020005.v1.4\\HLS.S30.T14RNS.2020005.v1.4__SWIR1.tif.\n",
      "Traceback (most recent call last):\n",
      "  File \"C:\\Users\\mcecil\\AppData\\Local\\anaconda3\\envs\\IBM_CDL\\lib\\site-packages\\nasa_hls\\hdf2tiff_conversion.py\", line 82, in convert_hdf2tiffs\n",
      "    subprocess.check_call(cmd, shell=True)\n",
      "  File \"C:\\Users\\mcecil\\AppData\\Local\\anaconda3\\envs\\IBM_CDL\\lib\\subprocess.py\", line 369, in check_call\n",
      "    raise CalledProcessError(retcode, cmd)\n",
      "subprocess.CalledProcessError: Command 'gdal_translate HDF4_EOS:EOS_GRID:'C:\\Users\\mcecil\\CGA\\CDL\\hdf\\HLS.S30.T14RNS.2020005.v1.4.hdf':Grid:B11 C:\\Users\\mcecil\\CGA\\CDL\\tif\\HLS.S30.T14RNS.2020005.v1.4\\HLS.S30.T14RNS.2020005.v1.4__SWIR1.tif' returned non-zero exit status 1.\n",
      "ERROR DURING CONVERSION WITH CMD: gdal_translate HDF4_EOS:EOS_GRID:'C:\\Users\\mcecil\\CGA\\CDL\\hdf\\HLS.S30.T14RNS.2020005.v1.4.hdf':Grid:B12 C:\\Users\\mcecil\\CGA\\CDL\\tif\\HLS.S30.T14RNS.2020005.v1.4\\HLS.S30.T14RNS.2020005.v1.4__SWIR2.tif.\n",
      "Traceback (most recent call last):\n",
      "  File \"C:\\Users\\mcecil\\AppData\\Local\\anaconda3\\envs\\IBM_CDL\\lib\\site-packages\\nasa_hls\\hdf2tiff_conversion.py\", line 82, in convert_hdf2tiffs\n",
      "    subprocess.check_call(cmd, shell=True)\n",
      "  File \"C:\\Users\\mcecil\\AppData\\Local\\anaconda3\\envs\\IBM_CDL\\lib\\subprocess.py\", line 369, in check_call\n",
      "    raise CalledProcessError(retcode, cmd)\n",
      "subprocess.CalledProcessError: Command 'gdal_translate HDF4_EOS:EOS_GRID:'C:\\Users\\mcecil\\CGA\\CDL\\hdf\\HLS.S30.T14RNS.2020005.v1.4.hdf':Grid:B12 C:\\Users\\mcecil\\CGA\\CDL\\tif\\HLS.S30.T14RNS.2020005.v1.4\\HLS.S30.T14RNS.2020005.v1.4__SWIR2.tif' returned non-zero exit status 1.\n",
      "ERROR DURING CONVERSION WITH CMD: gdal_translate HDF4_EOS:EOS_GRID:'C:\\Users\\mcecil\\CGA\\CDL\\hdf\\HLS.S30.T14RNS.2020005.v1.4.hdf':Grid:QA C:\\Users\\mcecil\\CGA\\CDL\\tif\\HLS.S30.T14RNS.2020005.v1.4\\HLS.S30.T14RNS.2020005.v1.4__QA.tif.\n",
      "Traceback (most recent call last):\n",
      "  File \"C:\\Users\\mcecil\\AppData\\Local\\anaconda3\\envs\\IBM_CDL\\lib\\site-packages\\nasa_hls\\hdf2tiff_conversion.py\", line 82, in convert_hdf2tiffs\n",
      "    subprocess.check_call(cmd, shell=True)\n",
      "  File \"C:\\Users\\mcecil\\AppData\\Local\\anaconda3\\envs\\IBM_CDL\\lib\\subprocess.py\", line 369, in check_call\n",
      "    raise CalledProcessError(retcode, cmd)\n",
      "subprocess.CalledProcessError: Command 'gdal_translate HDF4_EOS:EOS_GRID:'C:\\Users\\mcecil\\CGA\\CDL\\hdf\\HLS.S30.T14RNS.2020005.v1.4.hdf':Grid:QA C:\\Users\\mcecil\\CGA\\CDL\\tif\\HLS.S30.T14RNS.2020005.v1.4\\HLS.S30.T14RNS.2020005.v1.4__QA.tif' returned non-zero exit status 1.\n",
      "ERROR DURING CONVERSION WITH CMD: gdal_translate HDF4_EOS:EOS_GRID:'C:\\Users\\mcecil\\CGA\\CDL\\hdf\\HLS.S30.T14RNS.2020007.v1.4.hdf':Grid:B01 C:\\Users\\mcecil\\CGA\\CDL\\tif\\HLS.S30.T14RNS.2020007.v1.4\\HLS.S30.T14RNS.2020007.v1.4__Coastal_Aerosol.tif.\n",
      "Traceback (most recent call last):\n",
      "  File \"C:\\Users\\mcecil\\AppData\\Local\\anaconda3\\envs\\IBM_CDL\\lib\\site-packages\\nasa_hls\\hdf2tiff_conversion.py\", line 82, in convert_hdf2tiffs\n",
      "    subprocess.check_call(cmd, shell=True)\n",
      "  File \"C:\\Users\\mcecil\\AppData\\Local\\anaconda3\\envs\\IBM_CDL\\lib\\subprocess.py\", line 369, in check_call\n",
      "    raise CalledProcessError(retcode, cmd)\n",
      "subprocess.CalledProcessError: Command 'gdal_translate HDF4_EOS:EOS_GRID:'C:\\Users\\mcecil\\CGA\\CDL\\hdf\\HLS.S30.T14RNS.2020007.v1.4.hdf':Grid:B01 C:\\Users\\mcecil\\CGA\\CDL\\tif\\HLS.S30.T14RNS.2020007.v1.4\\HLS.S30.T14RNS.2020007.v1.4__Coastal_Aerosol.tif' returned non-zero exit status 1.\n",
      "ERROR DURING CONVERSION WITH CMD: gdal_translate HDF4_EOS:EOS_GRID:'C:\\Users\\mcecil\\CGA\\CDL\\hdf\\HLS.S30.T14RNS.2020007.v1.4.hdf':Grid:B02 C:\\Users\\mcecil\\CGA\\CDL\\tif\\HLS.S30.T14RNS.2020007.v1.4\\HLS.S30.T14RNS.2020007.v1.4__Blue.tif.\n",
      "Traceback (most recent call last):\n",
      "  File \"C:\\Users\\mcecil\\AppData\\Local\\anaconda3\\envs\\IBM_CDL\\lib\\site-packages\\nasa_hls\\hdf2tiff_conversion.py\", line 82, in convert_hdf2tiffs\n",
      "    subprocess.check_call(cmd, shell=True)\n",
      "  File \"C:\\Users\\mcecil\\AppData\\Local\\anaconda3\\envs\\IBM_CDL\\lib\\subprocess.py\", line 369, in check_call\n",
      "    raise CalledProcessError(retcode, cmd)\n",
      "subprocess.CalledProcessError: Command 'gdal_translate HDF4_EOS:EOS_GRID:'C:\\Users\\mcecil\\CGA\\CDL\\hdf\\HLS.S30.T14RNS.2020007.v1.4.hdf':Grid:B02 C:\\Users\\mcecil\\CGA\\CDL\\tif\\HLS.S30.T14RNS.2020007.v1.4\\HLS.S30.T14RNS.2020007.v1.4__Blue.tif' returned non-zero exit status 1.\n",
      "ERROR DURING CONVERSION WITH CMD: gdal_translate HDF4_EOS:EOS_GRID:'C:\\Users\\mcecil\\CGA\\CDL\\hdf\\HLS.S30.T14RNS.2020007.v1.4.hdf':Grid:B03 C:\\Users\\mcecil\\CGA\\CDL\\tif\\HLS.S30.T14RNS.2020007.v1.4\\HLS.S30.T14RNS.2020007.v1.4__Green.tif.\n",
      "Traceback (most recent call last):\n",
      "  File \"C:\\Users\\mcecil\\AppData\\Local\\anaconda3\\envs\\IBM_CDL\\lib\\site-packages\\nasa_hls\\hdf2tiff_conversion.py\", line 82, in convert_hdf2tiffs\n",
      "    subprocess.check_call(cmd, shell=True)\n",
      "  File \"C:\\Users\\mcecil\\AppData\\Local\\anaconda3\\envs\\IBM_CDL\\lib\\subprocess.py\", line 369, in check_call\n",
      "    raise CalledProcessError(retcode, cmd)\n",
      "subprocess.CalledProcessError: Command 'gdal_translate HDF4_EOS:EOS_GRID:'C:\\Users\\mcecil\\CGA\\CDL\\hdf\\HLS.S30.T14RNS.2020007.v1.4.hdf':Grid:B03 C:\\Users\\mcecil\\CGA\\CDL\\tif\\HLS.S30.T14RNS.2020007.v1.4\\HLS.S30.T14RNS.2020007.v1.4__Green.tif' returned non-zero exit status 1.\n",
      "ERROR DURING CONVERSION WITH CMD: gdal_translate HDF4_EOS:EOS_GRID:'C:\\Users\\mcecil\\CGA\\CDL\\hdf\\HLS.S30.T14RNS.2020007.v1.4.hdf':Grid:B04 C:\\Users\\mcecil\\CGA\\CDL\\tif\\HLS.S30.T14RNS.2020007.v1.4\\HLS.S30.T14RNS.2020007.v1.4__Red.tif.\n",
      "Traceback (most recent call last):\n",
      "  File \"C:\\Users\\mcecil\\AppData\\Local\\anaconda3\\envs\\IBM_CDL\\lib\\site-packages\\nasa_hls\\hdf2tiff_conversion.py\", line 82, in convert_hdf2tiffs\n",
      "    subprocess.check_call(cmd, shell=True)\n",
      "  File \"C:\\Users\\mcecil\\AppData\\Local\\anaconda3\\envs\\IBM_CDL\\lib\\subprocess.py\", line 369, in check_call\n",
      "    raise CalledProcessError(retcode, cmd)\n",
      "subprocess.CalledProcessError: Command 'gdal_translate HDF4_EOS:EOS_GRID:'C:\\Users\\mcecil\\CGA\\CDL\\hdf\\HLS.S30.T14RNS.2020007.v1.4.hdf':Grid:B04 C:\\Users\\mcecil\\CGA\\CDL\\tif\\HLS.S30.T14RNS.2020007.v1.4\\HLS.S30.T14RNS.2020007.v1.4__Red.tif' returned non-zero exit status 1.\n",
      "ERROR DURING CONVERSION WITH CMD: gdal_translate HDF4_EOS:EOS_GRID:'C:\\Users\\mcecil\\CGA\\CDL\\hdf\\HLS.S30.T14RNS.2020007.v1.4.hdf':Grid:B05 C:\\Users\\mcecil\\CGA\\CDL\\tif\\HLS.S30.T14RNS.2020007.v1.4\\HLS.S30.T14RNS.2020007.v1.4__Red_Edge1.tif.\n",
      "Traceback (most recent call last):\n",
      "  File \"C:\\Users\\mcecil\\AppData\\Local\\anaconda3\\envs\\IBM_CDL\\lib\\site-packages\\nasa_hls\\hdf2tiff_conversion.py\", line 82, in convert_hdf2tiffs\n",
      "    subprocess.check_call(cmd, shell=True)\n",
      "  File \"C:\\Users\\mcecil\\AppData\\Local\\anaconda3\\envs\\IBM_CDL\\lib\\subprocess.py\", line 369, in check_call\n",
      "    raise CalledProcessError(retcode, cmd)\n",
      "subprocess.CalledProcessError: Command 'gdal_translate HDF4_EOS:EOS_GRID:'C:\\Users\\mcecil\\CGA\\CDL\\hdf\\HLS.S30.T14RNS.2020007.v1.4.hdf':Grid:B05 C:\\Users\\mcecil\\CGA\\CDL\\tif\\HLS.S30.T14RNS.2020007.v1.4\\HLS.S30.T14RNS.2020007.v1.4__Red_Edge1.tif' returned non-zero exit status 1.\n",
      "ERROR DURING CONVERSION WITH CMD: gdal_translate HDF4_EOS:EOS_GRID:'C:\\Users\\mcecil\\CGA\\CDL\\hdf\\HLS.S30.T14RNS.2020007.v1.4.hdf':Grid:B06 C:\\Users\\mcecil\\CGA\\CDL\\tif\\HLS.S30.T14RNS.2020007.v1.4\\HLS.S30.T14RNS.2020007.v1.4__Red_Edge2.tif.\n",
      "Traceback (most recent call last):\n",
      "  File \"C:\\Users\\mcecil\\AppData\\Local\\anaconda3\\envs\\IBM_CDL\\lib\\site-packages\\nasa_hls\\hdf2tiff_conversion.py\", line 82, in convert_hdf2tiffs\n",
      "    subprocess.check_call(cmd, shell=True)\n",
      "  File \"C:\\Users\\mcecil\\AppData\\Local\\anaconda3\\envs\\IBM_CDL\\lib\\subprocess.py\", line 369, in check_call\n",
      "    raise CalledProcessError(retcode, cmd)\n",
      "subprocess.CalledProcessError: Command 'gdal_translate HDF4_EOS:EOS_GRID:'C:\\Users\\mcecil\\CGA\\CDL\\hdf\\HLS.S30.T14RNS.2020007.v1.4.hdf':Grid:B06 C:\\Users\\mcecil\\CGA\\CDL\\tif\\HLS.S30.T14RNS.2020007.v1.4\\HLS.S30.T14RNS.2020007.v1.4__Red_Edge2.tif' returned non-zero exit status 1.\n",
      "ERROR DURING CONVERSION WITH CMD: gdal_translate HDF4_EOS:EOS_GRID:'C:\\Users\\mcecil\\CGA\\CDL\\hdf\\HLS.S30.T14RNS.2020007.v1.4.hdf':Grid:B07 C:\\Users\\mcecil\\CGA\\CDL\\tif\\HLS.S30.T14RNS.2020007.v1.4\\HLS.S30.T14RNS.2020007.v1.4__Red_Edge3.tif.\n",
      "Traceback (most recent call last):\n",
      "  File \"C:\\Users\\mcecil\\AppData\\Local\\anaconda3\\envs\\IBM_CDL\\lib\\site-packages\\nasa_hls\\hdf2tiff_conversion.py\", line 82, in convert_hdf2tiffs\n",
      "    subprocess.check_call(cmd, shell=True)\n",
      "  File \"C:\\Users\\mcecil\\AppData\\Local\\anaconda3\\envs\\IBM_CDL\\lib\\subprocess.py\", line 369, in check_call\n",
      "    raise CalledProcessError(retcode, cmd)\n",
      "subprocess.CalledProcessError: Command 'gdal_translate HDF4_EOS:EOS_GRID:'C:\\Users\\mcecil\\CGA\\CDL\\hdf\\HLS.S30.T14RNS.2020007.v1.4.hdf':Grid:B07 C:\\Users\\mcecil\\CGA\\CDL\\tif\\HLS.S30.T14RNS.2020007.v1.4\\HLS.S30.T14RNS.2020007.v1.4__Red_Edge3.tif' returned non-zero exit status 1.\n",
      "ERROR DURING CONVERSION WITH CMD: gdal_translate HDF4_EOS:EOS_GRID:'C:\\Users\\mcecil\\CGA\\CDL\\hdf\\HLS.S30.T14RNS.2020007.v1.4.hdf':Grid:B08 C:\\Users\\mcecil\\CGA\\CDL\\tif\\HLS.S30.T14RNS.2020007.v1.4\\HLS.S30.T14RNS.2020007.v1.4__NIR_Broad.tif.\n",
      "Traceback (most recent call last):\n",
      "  File \"C:\\Users\\mcecil\\AppData\\Local\\anaconda3\\envs\\IBM_CDL\\lib\\site-packages\\nasa_hls\\hdf2tiff_conversion.py\", line 82, in convert_hdf2tiffs\n",
      "    subprocess.check_call(cmd, shell=True)\n",
      "  File \"C:\\Users\\mcecil\\AppData\\Local\\anaconda3\\envs\\IBM_CDL\\lib\\subprocess.py\", line 369, in check_call\n",
      "    raise CalledProcessError(retcode, cmd)\n",
      "subprocess.CalledProcessError: Command 'gdal_translate HDF4_EOS:EOS_GRID:'C:\\Users\\mcecil\\CGA\\CDL\\hdf\\HLS.S30.T14RNS.2020007.v1.4.hdf':Grid:B08 C:\\Users\\mcecil\\CGA\\CDL\\tif\\HLS.S30.T14RNS.2020007.v1.4\\HLS.S30.T14RNS.2020007.v1.4__NIR_Broad.tif' returned non-zero exit status 1.\n",
      "ERROR DURING CONVERSION WITH CMD: gdal_translate HDF4_EOS:EOS_GRID:'C:\\Users\\mcecil\\CGA\\CDL\\hdf\\HLS.S30.T14RNS.2020007.v1.4.hdf':Grid:B8A C:\\Users\\mcecil\\CGA\\CDL\\tif\\HLS.S30.T14RNS.2020007.v1.4\\HLS.S30.T14RNS.2020007.v1.4__NIR_Narrow.tif.\n",
      "Traceback (most recent call last):\n",
      "  File \"C:\\Users\\mcecil\\AppData\\Local\\anaconda3\\envs\\IBM_CDL\\lib\\site-packages\\nasa_hls\\hdf2tiff_conversion.py\", line 82, in convert_hdf2tiffs\n",
      "    subprocess.check_call(cmd, shell=True)\n",
      "  File \"C:\\Users\\mcecil\\AppData\\Local\\anaconda3\\envs\\IBM_CDL\\lib\\subprocess.py\", line 369, in check_call\n",
      "    raise CalledProcessError(retcode, cmd)\n",
      "subprocess.CalledProcessError: Command 'gdal_translate HDF4_EOS:EOS_GRID:'C:\\Users\\mcecil\\CGA\\CDL\\hdf\\HLS.S30.T14RNS.2020007.v1.4.hdf':Grid:B8A C:\\Users\\mcecil\\CGA\\CDL\\tif\\HLS.S30.T14RNS.2020007.v1.4\\HLS.S30.T14RNS.2020007.v1.4__NIR_Narrow.tif' returned non-zero exit status 1.\n",
      "ERROR DURING CONVERSION WITH CMD: gdal_translate HDF4_EOS:EOS_GRID:'C:\\Users\\mcecil\\CGA\\CDL\\hdf\\HLS.S30.T14RNS.2020007.v1.4.hdf':Grid:B09 C:\\Users\\mcecil\\CGA\\CDL\\tif\\HLS.S30.T14RNS.2020007.v1.4\\HLS.S30.T14RNS.2020007.v1.4__Water_Vapor.tif.\n",
      "Traceback (most recent call last):\n",
      "  File \"C:\\Users\\mcecil\\AppData\\Local\\anaconda3\\envs\\IBM_CDL\\lib\\site-packages\\nasa_hls\\hdf2tiff_conversion.py\", line 82, in convert_hdf2tiffs\n",
      "    subprocess.check_call(cmd, shell=True)\n",
      "  File \"C:\\Users\\mcecil\\AppData\\Local\\anaconda3\\envs\\IBM_CDL\\lib\\subprocess.py\", line 369, in check_call\n",
      "    raise CalledProcessError(retcode, cmd)\n",
      "subprocess.CalledProcessError: Command 'gdal_translate HDF4_EOS:EOS_GRID:'C:\\Users\\mcecil\\CGA\\CDL\\hdf\\HLS.S30.T14RNS.2020007.v1.4.hdf':Grid:B09 C:\\Users\\mcecil\\CGA\\CDL\\tif\\HLS.S30.T14RNS.2020007.v1.4\\HLS.S30.T14RNS.2020007.v1.4__Water_Vapor.tif' returned non-zero exit status 1.\n",
      "ERROR DURING CONVERSION WITH CMD: gdal_translate HDF4_EOS:EOS_GRID:'C:\\Users\\mcecil\\CGA\\CDL\\hdf\\HLS.S30.T14RNS.2020007.v1.4.hdf':Grid:B10 C:\\Users\\mcecil\\CGA\\CDL\\tif\\HLS.S30.T14RNS.2020007.v1.4\\HLS.S30.T14RNS.2020007.v1.4__Cirrus.tif.\n",
      "Traceback (most recent call last):\n",
      "  File \"C:\\Users\\mcecil\\AppData\\Local\\anaconda3\\envs\\IBM_CDL\\lib\\site-packages\\nasa_hls\\hdf2tiff_conversion.py\", line 82, in convert_hdf2tiffs\n",
      "    subprocess.check_call(cmd, shell=True)\n",
      "  File \"C:\\Users\\mcecil\\AppData\\Local\\anaconda3\\envs\\IBM_CDL\\lib\\subprocess.py\", line 369, in check_call\n",
      "    raise CalledProcessError(retcode, cmd)\n",
      "subprocess.CalledProcessError: Command 'gdal_translate HDF4_EOS:EOS_GRID:'C:\\Users\\mcecil\\CGA\\CDL\\hdf\\HLS.S30.T14RNS.2020007.v1.4.hdf':Grid:B10 C:\\Users\\mcecil\\CGA\\CDL\\tif\\HLS.S30.T14RNS.2020007.v1.4\\HLS.S30.T14RNS.2020007.v1.4__Cirrus.tif' returned non-zero exit status 1.\n",
      "ERROR DURING CONVERSION WITH CMD: gdal_translate HDF4_EOS:EOS_GRID:'C:\\Users\\mcecil\\CGA\\CDL\\hdf\\HLS.S30.T14RNS.2020007.v1.4.hdf':Grid:B11 C:\\Users\\mcecil\\CGA\\CDL\\tif\\HLS.S30.T14RNS.2020007.v1.4\\HLS.S30.T14RNS.2020007.v1.4__SWIR1.tif.\n",
      "Traceback (most recent call last):\n",
      "  File \"C:\\Users\\mcecil\\AppData\\Local\\anaconda3\\envs\\IBM_CDL\\lib\\site-packages\\nasa_hls\\hdf2tiff_conversion.py\", line 82, in convert_hdf2tiffs\n",
      "    subprocess.check_call(cmd, shell=True)\n",
      "  File \"C:\\Users\\mcecil\\AppData\\Local\\anaconda3\\envs\\IBM_CDL\\lib\\subprocess.py\", line 369, in check_call\n",
      "    raise CalledProcessError(retcode, cmd)\n",
      "subprocess.CalledProcessError: Command 'gdal_translate HDF4_EOS:EOS_GRID:'C:\\Users\\mcecil\\CGA\\CDL\\hdf\\HLS.S30.T14RNS.2020007.v1.4.hdf':Grid:B11 C:\\Users\\mcecil\\CGA\\CDL\\tif\\HLS.S30.T14RNS.2020007.v1.4\\HLS.S30.T14RNS.2020007.v1.4__SWIR1.tif' returned non-zero exit status 1.\n",
      "ERROR DURING CONVERSION WITH CMD: gdal_translate HDF4_EOS:EOS_GRID:'C:\\Users\\mcecil\\CGA\\CDL\\hdf\\HLS.S30.T14RNS.2020007.v1.4.hdf':Grid:B12 C:\\Users\\mcecil\\CGA\\CDL\\tif\\HLS.S30.T14RNS.2020007.v1.4\\HLS.S30.T14RNS.2020007.v1.4__SWIR2.tif.\n",
      "Traceback (most recent call last):\n",
      "  File \"C:\\Users\\mcecil\\AppData\\Local\\anaconda3\\envs\\IBM_CDL\\lib\\site-packages\\nasa_hls\\hdf2tiff_conversion.py\", line 82, in convert_hdf2tiffs\n",
      "    subprocess.check_call(cmd, shell=True)\n",
      "  File \"C:\\Users\\mcecil\\AppData\\Local\\anaconda3\\envs\\IBM_CDL\\lib\\subprocess.py\", line 369, in check_call\n",
      "    raise CalledProcessError(retcode, cmd)\n",
      "subprocess.CalledProcessError: Command 'gdal_translate HDF4_EOS:EOS_GRID:'C:\\Users\\mcecil\\CGA\\CDL\\hdf\\HLS.S30.T14RNS.2020007.v1.4.hdf':Grid:B12 C:\\Users\\mcecil\\CGA\\CDL\\tif\\HLS.S30.T14RNS.2020007.v1.4\\HLS.S30.T14RNS.2020007.v1.4__SWIR2.tif' returned non-zero exit status 1.\n",
      "ERROR DURING CONVERSION WITH CMD: gdal_translate HDF4_EOS:EOS_GRID:'C:\\Users\\mcecil\\CGA\\CDL\\hdf\\HLS.S30.T14RNS.2020007.v1.4.hdf':Grid:QA C:\\Users\\mcecil\\CGA\\CDL\\tif\\HLS.S30.T14RNS.2020007.v1.4\\HLS.S30.T14RNS.2020007.v1.4__QA.tif.\n",
      "Traceback (most recent call last):\n",
      "  File \"C:\\Users\\mcecil\\AppData\\Local\\anaconda3\\envs\\IBM_CDL\\lib\\site-packages\\nasa_hls\\hdf2tiff_conversion.py\", line 82, in convert_hdf2tiffs\n",
      "    subprocess.check_call(cmd, shell=True)\n",
      "  File \"C:\\Users\\mcecil\\AppData\\Local\\anaconda3\\envs\\IBM_CDL\\lib\\subprocess.py\", line 369, in check_call\n",
      "    raise CalledProcessError(retcode, cmd)\n",
      "subprocess.CalledProcessError: Command 'gdal_translate HDF4_EOS:EOS_GRID:'C:\\Users\\mcecil\\CGA\\CDL\\hdf\\HLS.S30.T14RNS.2020007.v1.4.hdf':Grid:QA C:\\Users\\mcecil\\CGA\\CDL\\tif\\HLS.S30.T14RNS.2020007.v1.4\\HLS.S30.T14RNS.2020007.v1.4__QA.tif' returned non-zero exit status 1.\n",
      "ERROR DURING CONVERSION WITH CMD: gdal_translate HDF4_EOS:EOS_GRID:'C:\\Users\\mcecil\\CGA\\CDL\\hdf\\HLS.S30.T14RNS.2020010.v1.4.hdf':Grid:B01 C:\\Users\\mcecil\\CGA\\CDL\\tif\\HLS.S30.T14RNS.2020010.v1.4\\HLS.S30.T14RNS.2020010.v1.4__Coastal_Aerosol.tif.\n",
      "Traceback (most recent call last):\n",
      "  File \"C:\\Users\\mcecil\\AppData\\Local\\anaconda3\\envs\\IBM_CDL\\lib\\site-packages\\nasa_hls\\hdf2tiff_conversion.py\", line 82, in convert_hdf2tiffs\n",
      "    subprocess.check_call(cmd, shell=True)\n",
      "  File \"C:\\Users\\mcecil\\AppData\\Local\\anaconda3\\envs\\IBM_CDL\\lib\\subprocess.py\", line 369, in check_call\n",
      "    raise CalledProcessError(retcode, cmd)\n",
      "subprocess.CalledProcessError: Command 'gdal_translate HDF4_EOS:EOS_GRID:'C:\\Users\\mcecil\\CGA\\CDL\\hdf\\HLS.S30.T14RNS.2020010.v1.4.hdf':Grid:B01 C:\\Users\\mcecil\\CGA\\CDL\\tif\\HLS.S30.T14RNS.2020010.v1.4\\HLS.S30.T14RNS.2020010.v1.4__Coastal_Aerosol.tif' returned non-zero exit status 1.\n",
      "ERROR DURING CONVERSION WITH CMD: gdal_translate HDF4_EOS:EOS_GRID:'C:\\Users\\mcecil\\CGA\\CDL\\hdf\\HLS.S30.T14RNS.2020010.v1.4.hdf':Grid:B02 C:\\Users\\mcecil\\CGA\\CDL\\tif\\HLS.S30.T14RNS.2020010.v1.4\\HLS.S30.T14RNS.2020010.v1.4__Blue.tif.\n",
      "Traceback (most recent call last):\n",
      "  File \"C:\\Users\\mcecil\\AppData\\Local\\anaconda3\\envs\\IBM_CDL\\lib\\site-packages\\nasa_hls\\hdf2tiff_conversion.py\", line 82, in convert_hdf2tiffs\n",
      "    subprocess.check_call(cmd, shell=True)\n",
      "  File \"C:\\Users\\mcecil\\AppData\\Local\\anaconda3\\envs\\IBM_CDL\\lib\\subprocess.py\", line 369, in check_call\n",
      "    raise CalledProcessError(retcode, cmd)\n",
      "subprocess.CalledProcessError: Command 'gdal_translate HDF4_EOS:EOS_GRID:'C:\\Users\\mcecil\\CGA\\CDL\\hdf\\HLS.S30.T14RNS.2020010.v1.4.hdf':Grid:B02 C:\\Users\\mcecil\\CGA\\CDL\\tif\\HLS.S30.T14RNS.2020010.v1.4\\HLS.S30.T14RNS.2020010.v1.4__Blue.tif' returned non-zero exit status 1.\n",
      "ERROR DURING CONVERSION WITH CMD: gdal_translate HDF4_EOS:EOS_GRID:'C:\\Users\\mcecil\\CGA\\CDL\\hdf\\HLS.S30.T14RNS.2020010.v1.4.hdf':Grid:B03 C:\\Users\\mcecil\\CGA\\CDL\\tif\\HLS.S30.T14RNS.2020010.v1.4\\HLS.S30.T14RNS.2020010.v1.4__Green.tif.\n",
      "Traceback (most recent call last):\n",
      "  File \"C:\\Users\\mcecil\\AppData\\Local\\anaconda3\\envs\\IBM_CDL\\lib\\site-packages\\nasa_hls\\hdf2tiff_conversion.py\", line 82, in convert_hdf2tiffs\n",
      "    subprocess.check_call(cmd, shell=True)\n",
      "  File \"C:\\Users\\mcecil\\AppData\\Local\\anaconda3\\envs\\IBM_CDL\\lib\\subprocess.py\", line 369, in check_call\n",
      "    raise CalledProcessError(retcode, cmd)\n",
      "subprocess.CalledProcessError: Command 'gdal_translate HDF4_EOS:EOS_GRID:'C:\\Users\\mcecil\\CGA\\CDL\\hdf\\HLS.S30.T14RNS.2020010.v1.4.hdf':Grid:B03 C:\\Users\\mcecil\\CGA\\CDL\\tif\\HLS.S30.T14RNS.2020010.v1.4\\HLS.S30.T14RNS.2020010.v1.4__Green.tif' returned non-zero exit status 1.\n",
      "ERROR DURING CONVERSION WITH CMD: gdal_translate HDF4_EOS:EOS_GRID:'C:\\Users\\mcecil\\CGA\\CDL\\hdf\\HLS.S30.T14RNS.2020010.v1.4.hdf':Grid:B04 C:\\Users\\mcecil\\CGA\\CDL\\tif\\HLS.S30.T14RNS.2020010.v1.4\\HLS.S30.T14RNS.2020010.v1.4__Red.tif.\n",
      "Traceback (most recent call last):\n",
      "  File \"C:\\Users\\mcecil\\AppData\\Local\\anaconda3\\envs\\IBM_CDL\\lib\\site-packages\\nasa_hls\\hdf2tiff_conversion.py\", line 82, in convert_hdf2tiffs\n",
      "    subprocess.check_call(cmd, shell=True)\n",
      "  File \"C:\\Users\\mcecil\\AppData\\Local\\anaconda3\\envs\\IBM_CDL\\lib\\subprocess.py\", line 369, in check_call\n",
      "    raise CalledProcessError(retcode, cmd)\n",
      "subprocess.CalledProcessError: Command 'gdal_translate HDF4_EOS:EOS_GRID:'C:\\Users\\mcecil\\CGA\\CDL\\hdf\\HLS.S30.T14RNS.2020010.v1.4.hdf':Grid:B04 C:\\Users\\mcecil\\CGA\\CDL\\tif\\HLS.S30.T14RNS.2020010.v1.4\\HLS.S30.T14RNS.2020010.v1.4__Red.tif' returned non-zero exit status 1.\n",
      "ERROR DURING CONVERSION WITH CMD: gdal_translate HDF4_EOS:EOS_GRID:'C:\\Users\\mcecil\\CGA\\CDL\\hdf\\HLS.S30.T14RNS.2020010.v1.4.hdf':Grid:B05 C:\\Users\\mcecil\\CGA\\CDL\\tif\\HLS.S30.T14RNS.2020010.v1.4\\HLS.S30.T14RNS.2020010.v1.4__Red_Edge1.tif.\n",
      "Traceback (most recent call last):\n",
      "  File \"C:\\Users\\mcecil\\AppData\\Local\\anaconda3\\envs\\IBM_CDL\\lib\\site-packages\\nasa_hls\\hdf2tiff_conversion.py\", line 82, in convert_hdf2tiffs\n",
      "    subprocess.check_call(cmd, shell=True)\n",
      "  File \"C:\\Users\\mcecil\\AppData\\Local\\anaconda3\\envs\\IBM_CDL\\lib\\subprocess.py\", line 369, in check_call\n",
      "    raise CalledProcessError(retcode, cmd)\n",
      "subprocess.CalledProcessError: Command 'gdal_translate HDF4_EOS:EOS_GRID:'C:\\Users\\mcecil\\CGA\\CDL\\hdf\\HLS.S30.T14RNS.2020010.v1.4.hdf':Grid:B05 C:\\Users\\mcecil\\CGA\\CDL\\tif\\HLS.S30.T14RNS.2020010.v1.4\\HLS.S30.T14RNS.2020010.v1.4__Red_Edge1.tif' returned non-zero exit status 1.\n",
      "ERROR DURING CONVERSION WITH CMD: gdal_translate HDF4_EOS:EOS_GRID:'C:\\Users\\mcecil\\CGA\\CDL\\hdf\\HLS.S30.T14RNS.2020010.v1.4.hdf':Grid:B06 C:\\Users\\mcecil\\CGA\\CDL\\tif\\HLS.S30.T14RNS.2020010.v1.4\\HLS.S30.T14RNS.2020010.v1.4__Red_Edge2.tif.\n",
      "Traceback (most recent call last):\n",
      "  File \"C:\\Users\\mcecil\\AppData\\Local\\anaconda3\\envs\\IBM_CDL\\lib\\site-packages\\nasa_hls\\hdf2tiff_conversion.py\", line 82, in convert_hdf2tiffs\n",
      "    subprocess.check_call(cmd, shell=True)\n",
      "  File \"C:\\Users\\mcecil\\AppData\\Local\\anaconda3\\envs\\IBM_CDL\\lib\\subprocess.py\", line 369, in check_call\n",
      "    raise CalledProcessError(retcode, cmd)\n",
      "subprocess.CalledProcessError: Command 'gdal_translate HDF4_EOS:EOS_GRID:'C:\\Users\\mcecil\\CGA\\CDL\\hdf\\HLS.S30.T14RNS.2020010.v1.4.hdf':Grid:B06 C:\\Users\\mcecil\\CGA\\CDL\\tif\\HLS.S30.T14RNS.2020010.v1.4\\HLS.S30.T14RNS.2020010.v1.4__Red_Edge2.tif' returned non-zero exit status 1.\n",
      "ERROR DURING CONVERSION WITH CMD: gdal_translate HDF4_EOS:EOS_GRID:'C:\\Users\\mcecil\\CGA\\CDL\\hdf\\HLS.S30.T14RNS.2020010.v1.4.hdf':Grid:B07 C:\\Users\\mcecil\\CGA\\CDL\\tif\\HLS.S30.T14RNS.2020010.v1.4\\HLS.S30.T14RNS.2020010.v1.4__Red_Edge3.tif.\n",
      "Traceback (most recent call last):\n",
      "  File \"C:\\Users\\mcecil\\AppData\\Local\\anaconda3\\envs\\IBM_CDL\\lib\\site-packages\\nasa_hls\\hdf2tiff_conversion.py\", line 82, in convert_hdf2tiffs\n",
      "    subprocess.check_call(cmd, shell=True)\n",
      "  File \"C:\\Users\\mcecil\\AppData\\Local\\anaconda3\\envs\\IBM_CDL\\lib\\subprocess.py\", line 369, in check_call\n",
      "    raise CalledProcessError(retcode, cmd)\n",
      "subprocess.CalledProcessError: Command 'gdal_translate HDF4_EOS:EOS_GRID:'C:\\Users\\mcecil\\CGA\\CDL\\hdf\\HLS.S30.T14RNS.2020010.v1.4.hdf':Grid:B07 C:\\Users\\mcecil\\CGA\\CDL\\tif\\HLS.S30.T14RNS.2020010.v1.4\\HLS.S30.T14RNS.2020010.v1.4__Red_Edge3.tif' returned non-zero exit status 1.\n",
      "ERROR DURING CONVERSION WITH CMD: gdal_translate HDF4_EOS:EOS_GRID:'C:\\Users\\mcecil\\CGA\\CDL\\hdf\\HLS.S30.T14RNS.2020010.v1.4.hdf':Grid:B08 C:\\Users\\mcecil\\CGA\\CDL\\tif\\HLS.S30.T14RNS.2020010.v1.4\\HLS.S30.T14RNS.2020010.v1.4__NIR_Broad.tif.\n",
      "Traceback (most recent call last):\n",
      "  File \"C:\\Users\\mcecil\\AppData\\Local\\anaconda3\\envs\\IBM_CDL\\lib\\site-packages\\nasa_hls\\hdf2tiff_conversion.py\", line 82, in convert_hdf2tiffs\n",
      "    subprocess.check_call(cmd, shell=True)\n",
      "  File \"C:\\Users\\mcecil\\AppData\\Local\\anaconda3\\envs\\IBM_CDL\\lib\\subprocess.py\", line 369, in check_call\n",
      "    raise CalledProcessError(retcode, cmd)\n",
      "subprocess.CalledProcessError: Command 'gdal_translate HDF4_EOS:EOS_GRID:'C:\\Users\\mcecil\\CGA\\CDL\\hdf\\HLS.S30.T14RNS.2020010.v1.4.hdf':Grid:B08 C:\\Users\\mcecil\\CGA\\CDL\\tif\\HLS.S30.T14RNS.2020010.v1.4\\HLS.S30.T14RNS.2020010.v1.4__NIR_Broad.tif' returned non-zero exit status 1.\n",
      "ERROR DURING CONVERSION WITH CMD: gdal_translate HDF4_EOS:EOS_GRID:'C:\\Users\\mcecil\\CGA\\CDL\\hdf\\HLS.S30.T14RNS.2020010.v1.4.hdf':Grid:B8A C:\\Users\\mcecil\\CGA\\CDL\\tif\\HLS.S30.T14RNS.2020010.v1.4\\HLS.S30.T14RNS.2020010.v1.4__NIR_Narrow.tif.\n",
      "Traceback (most recent call last):\n",
      "  File \"C:\\Users\\mcecil\\AppData\\Local\\anaconda3\\envs\\IBM_CDL\\lib\\site-packages\\nasa_hls\\hdf2tiff_conversion.py\", line 82, in convert_hdf2tiffs\n",
      "    subprocess.check_call(cmd, shell=True)\n",
      "  File \"C:\\Users\\mcecil\\AppData\\Local\\anaconda3\\envs\\IBM_CDL\\lib\\subprocess.py\", line 369, in check_call\n",
      "    raise CalledProcessError(retcode, cmd)\n",
      "subprocess.CalledProcessError: Command 'gdal_translate HDF4_EOS:EOS_GRID:'C:\\Users\\mcecil\\CGA\\CDL\\hdf\\HLS.S30.T14RNS.2020010.v1.4.hdf':Grid:B8A C:\\Users\\mcecil\\CGA\\CDL\\tif\\HLS.S30.T14RNS.2020010.v1.4\\HLS.S30.T14RNS.2020010.v1.4__NIR_Narrow.tif' returned non-zero exit status 1.\n",
      "ERROR DURING CONVERSION WITH CMD: gdal_translate HDF4_EOS:EOS_GRID:'C:\\Users\\mcecil\\CGA\\CDL\\hdf\\HLS.S30.T14RNS.2020010.v1.4.hdf':Grid:B09 C:\\Users\\mcecil\\CGA\\CDL\\tif\\HLS.S30.T14RNS.2020010.v1.4\\HLS.S30.T14RNS.2020010.v1.4__Water_Vapor.tif.\n",
      "Traceback (most recent call last):\n",
      "  File \"C:\\Users\\mcecil\\AppData\\Local\\anaconda3\\envs\\IBM_CDL\\lib\\site-packages\\nasa_hls\\hdf2tiff_conversion.py\", line 82, in convert_hdf2tiffs\n",
      "    subprocess.check_call(cmd, shell=True)\n",
      "  File \"C:\\Users\\mcecil\\AppData\\Local\\anaconda3\\envs\\IBM_CDL\\lib\\subprocess.py\", line 369, in check_call\n",
      "    raise CalledProcessError(retcode, cmd)\n",
      "subprocess.CalledProcessError: Command 'gdal_translate HDF4_EOS:EOS_GRID:'C:\\Users\\mcecil\\CGA\\CDL\\hdf\\HLS.S30.T14RNS.2020010.v1.4.hdf':Grid:B09 C:\\Users\\mcecil\\CGA\\CDL\\tif\\HLS.S30.T14RNS.2020010.v1.4\\HLS.S30.T14RNS.2020010.v1.4__Water_Vapor.tif' returned non-zero exit status 1.\n",
      "ERROR DURING CONVERSION WITH CMD: gdal_translate HDF4_EOS:EOS_GRID:'C:\\Users\\mcecil\\CGA\\CDL\\hdf\\HLS.S30.T14RNS.2020010.v1.4.hdf':Grid:B10 C:\\Users\\mcecil\\CGA\\CDL\\tif\\HLS.S30.T14RNS.2020010.v1.4\\HLS.S30.T14RNS.2020010.v1.4__Cirrus.tif.\n",
      "Traceback (most recent call last):\n",
      "  File \"C:\\Users\\mcecil\\AppData\\Local\\anaconda3\\envs\\IBM_CDL\\lib\\site-packages\\nasa_hls\\hdf2tiff_conversion.py\", line 82, in convert_hdf2tiffs\n",
      "    subprocess.check_call(cmd, shell=True)\n",
      "  File \"C:\\Users\\mcecil\\AppData\\Local\\anaconda3\\envs\\IBM_CDL\\lib\\subprocess.py\", line 369, in check_call\n",
      "    raise CalledProcessError(retcode, cmd)\n",
      "subprocess.CalledProcessError: Command 'gdal_translate HDF4_EOS:EOS_GRID:'C:\\Users\\mcecil\\CGA\\CDL\\hdf\\HLS.S30.T14RNS.2020010.v1.4.hdf':Grid:B10 C:\\Users\\mcecil\\CGA\\CDL\\tif\\HLS.S30.T14RNS.2020010.v1.4\\HLS.S30.T14RNS.2020010.v1.4__Cirrus.tif' returned non-zero exit status 1.\n",
      "ERROR DURING CONVERSION WITH CMD: gdal_translate HDF4_EOS:EOS_GRID:'C:\\Users\\mcecil\\CGA\\CDL\\hdf\\HLS.S30.T14RNS.2020010.v1.4.hdf':Grid:B11 C:\\Users\\mcecil\\CGA\\CDL\\tif\\HLS.S30.T14RNS.2020010.v1.4\\HLS.S30.T14RNS.2020010.v1.4__SWIR1.tif.\n",
      "Traceback (most recent call last):\n",
      "  File \"C:\\Users\\mcecil\\AppData\\Local\\anaconda3\\envs\\IBM_CDL\\lib\\site-packages\\nasa_hls\\hdf2tiff_conversion.py\", line 82, in convert_hdf2tiffs\n",
      "    subprocess.check_call(cmd, shell=True)\n",
      "  File \"C:\\Users\\mcecil\\AppData\\Local\\anaconda3\\envs\\IBM_CDL\\lib\\subprocess.py\", line 369, in check_call\n",
      "    raise CalledProcessError(retcode, cmd)\n",
      "subprocess.CalledProcessError: Command 'gdal_translate HDF4_EOS:EOS_GRID:'C:\\Users\\mcecil\\CGA\\CDL\\hdf\\HLS.S30.T14RNS.2020010.v1.4.hdf':Grid:B11 C:\\Users\\mcecil\\CGA\\CDL\\tif\\HLS.S30.T14RNS.2020010.v1.4\\HLS.S30.T14RNS.2020010.v1.4__SWIR1.tif' returned non-zero exit status 1.\n",
      "ERROR DURING CONVERSION WITH CMD: gdal_translate HDF4_EOS:EOS_GRID:'C:\\Users\\mcecil\\CGA\\CDL\\hdf\\HLS.S30.T14RNS.2020010.v1.4.hdf':Grid:B12 C:\\Users\\mcecil\\CGA\\CDL\\tif\\HLS.S30.T14RNS.2020010.v1.4\\HLS.S30.T14RNS.2020010.v1.4__SWIR2.tif.\n",
      "Traceback (most recent call last):\n",
      "  File \"C:\\Users\\mcecil\\AppData\\Local\\anaconda3\\envs\\IBM_CDL\\lib\\site-packages\\nasa_hls\\hdf2tiff_conversion.py\", line 82, in convert_hdf2tiffs\n",
      "    subprocess.check_call(cmd, shell=True)\n",
      "  File \"C:\\Users\\mcecil\\AppData\\Local\\anaconda3\\envs\\IBM_CDL\\lib\\subprocess.py\", line 369, in check_call\n",
      "    raise CalledProcessError(retcode, cmd)\n",
      "subprocess.CalledProcessError: Command 'gdal_translate HDF4_EOS:EOS_GRID:'C:\\Users\\mcecil\\CGA\\CDL\\hdf\\HLS.S30.T14RNS.2020010.v1.4.hdf':Grid:B12 C:\\Users\\mcecil\\CGA\\CDL\\tif\\HLS.S30.T14RNS.2020010.v1.4\\HLS.S30.T14RNS.2020010.v1.4__SWIR2.tif' returned non-zero exit status 1.\n",
      "ERROR DURING CONVERSION WITH CMD: gdal_translate HDF4_EOS:EOS_GRID:'C:\\Users\\mcecil\\CGA\\CDL\\hdf\\HLS.S30.T14RNS.2020010.v1.4.hdf':Grid:QA C:\\Users\\mcecil\\CGA\\CDL\\tif\\HLS.S30.T14RNS.2020010.v1.4\\HLS.S30.T14RNS.2020010.v1.4__QA.tif.\n",
      "Traceback (most recent call last):\n",
      "  File \"C:\\Users\\mcecil\\AppData\\Local\\anaconda3\\envs\\IBM_CDL\\lib\\site-packages\\nasa_hls\\hdf2tiff_conversion.py\", line 82, in convert_hdf2tiffs\n",
      "    subprocess.check_call(cmd, shell=True)\n",
      "  File \"C:\\Users\\mcecil\\AppData\\Local\\anaconda3\\envs\\IBM_CDL\\lib\\subprocess.py\", line 369, in check_call\n",
      "    raise CalledProcessError(retcode, cmd)\n",
      "subprocess.CalledProcessError: Command 'gdal_translate HDF4_EOS:EOS_GRID:'C:\\Users\\mcecil\\CGA\\CDL\\hdf\\HLS.S30.T14RNS.2020010.v1.4.hdf':Grid:QA C:\\Users\\mcecil\\CGA\\CDL\\tif\\HLS.S30.T14RNS.2020010.v1.4\\HLS.S30.T14RNS.2020010.v1.4__QA.tif' returned non-zero exit status 1.\n",
      "ERROR DURING CONVERSION WITH CMD: gdal_translate HDF4_EOS:EOS_GRID:'C:\\Users\\mcecil\\CGA\\CDL\\hdf\\HLS.S30.T14RNS.2020012.v1.4.hdf':Grid:B01 C:\\Users\\mcecil\\CGA\\CDL\\tif\\HLS.S30.T14RNS.2020012.v1.4\\HLS.S30.T14RNS.2020012.v1.4__Coastal_Aerosol.tif.\n",
      "Traceback (most recent call last):\n",
      "  File \"C:\\Users\\mcecil\\AppData\\Local\\anaconda3\\envs\\IBM_CDL\\lib\\site-packages\\nasa_hls\\hdf2tiff_conversion.py\", line 82, in convert_hdf2tiffs\n",
      "    subprocess.check_call(cmd, shell=True)\n",
      "  File \"C:\\Users\\mcecil\\AppData\\Local\\anaconda3\\envs\\IBM_CDL\\lib\\subprocess.py\", line 369, in check_call\n",
      "    raise CalledProcessError(retcode, cmd)\n",
      "subprocess.CalledProcessError: Command 'gdal_translate HDF4_EOS:EOS_GRID:'C:\\Users\\mcecil\\CGA\\CDL\\hdf\\HLS.S30.T14RNS.2020012.v1.4.hdf':Grid:B01 C:\\Users\\mcecil\\CGA\\CDL\\tif\\HLS.S30.T14RNS.2020012.v1.4\\HLS.S30.T14RNS.2020012.v1.4__Coastal_Aerosol.tif' returned non-zero exit status 1.\n",
      "ERROR DURING CONVERSION WITH CMD: gdal_translate HDF4_EOS:EOS_GRID:'C:\\Users\\mcecil\\CGA\\CDL\\hdf\\HLS.S30.T14RNS.2020012.v1.4.hdf':Grid:B02 C:\\Users\\mcecil\\CGA\\CDL\\tif\\HLS.S30.T14RNS.2020012.v1.4\\HLS.S30.T14RNS.2020012.v1.4__Blue.tif.\n",
      "Traceback (most recent call last):\n",
      "  File \"C:\\Users\\mcecil\\AppData\\Local\\anaconda3\\envs\\IBM_CDL\\lib\\site-packages\\nasa_hls\\hdf2tiff_conversion.py\", line 82, in convert_hdf2tiffs\n",
      "    subprocess.check_call(cmd, shell=True)\n",
      "  File \"C:\\Users\\mcecil\\AppData\\Local\\anaconda3\\envs\\IBM_CDL\\lib\\subprocess.py\", line 369, in check_call\n",
      "    raise CalledProcessError(retcode, cmd)\n",
      "subprocess.CalledProcessError: Command 'gdal_translate HDF4_EOS:EOS_GRID:'C:\\Users\\mcecil\\CGA\\CDL\\hdf\\HLS.S30.T14RNS.2020012.v1.4.hdf':Grid:B02 C:\\Users\\mcecil\\CGA\\CDL\\tif\\HLS.S30.T14RNS.2020012.v1.4\\HLS.S30.T14RNS.2020012.v1.4__Blue.tif' returned non-zero exit status 1.\n",
      "ERROR DURING CONVERSION WITH CMD: gdal_translate HDF4_EOS:EOS_GRID:'C:\\Users\\mcecil\\CGA\\CDL\\hdf\\HLS.S30.T14RNS.2020012.v1.4.hdf':Grid:B03 C:\\Users\\mcecil\\CGA\\CDL\\tif\\HLS.S30.T14RNS.2020012.v1.4\\HLS.S30.T14RNS.2020012.v1.4__Green.tif.\n",
      "Traceback (most recent call last):\n",
      "  File \"C:\\Users\\mcecil\\AppData\\Local\\anaconda3\\envs\\IBM_CDL\\lib\\site-packages\\nasa_hls\\hdf2tiff_conversion.py\", line 82, in convert_hdf2tiffs\n",
      "    subprocess.check_call(cmd, shell=True)\n",
      "  File \"C:\\Users\\mcecil\\AppData\\Local\\anaconda3\\envs\\IBM_CDL\\lib\\subprocess.py\", line 369, in check_call\n",
      "    raise CalledProcessError(retcode, cmd)\n",
      "subprocess.CalledProcessError: Command 'gdal_translate HDF4_EOS:EOS_GRID:'C:\\Users\\mcecil\\CGA\\CDL\\hdf\\HLS.S30.T14RNS.2020012.v1.4.hdf':Grid:B03 C:\\Users\\mcecil\\CGA\\CDL\\tif\\HLS.S30.T14RNS.2020012.v1.4\\HLS.S30.T14RNS.2020012.v1.4__Green.tif' returned non-zero exit status 1.\n",
      "ERROR DURING CONVERSION WITH CMD: gdal_translate HDF4_EOS:EOS_GRID:'C:\\Users\\mcecil\\CGA\\CDL\\hdf\\HLS.S30.T14RNS.2020012.v1.4.hdf':Grid:B04 C:\\Users\\mcecil\\CGA\\CDL\\tif\\HLS.S30.T14RNS.2020012.v1.4\\HLS.S30.T14RNS.2020012.v1.4__Red.tif.\n",
      "Traceback (most recent call last):\n",
      "  File \"C:\\Users\\mcecil\\AppData\\Local\\anaconda3\\envs\\IBM_CDL\\lib\\site-packages\\nasa_hls\\hdf2tiff_conversion.py\", line 82, in convert_hdf2tiffs\n",
      "    subprocess.check_call(cmd, shell=True)\n",
      "  File \"C:\\Users\\mcecil\\AppData\\Local\\anaconda3\\envs\\IBM_CDL\\lib\\subprocess.py\", line 369, in check_call\n",
      "    raise CalledProcessError(retcode, cmd)\n",
      "subprocess.CalledProcessError: Command 'gdal_translate HDF4_EOS:EOS_GRID:'C:\\Users\\mcecil\\CGA\\CDL\\hdf\\HLS.S30.T14RNS.2020012.v1.4.hdf':Grid:B04 C:\\Users\\mcecil\\CGA\\CDL\\tif\\HLS.S30.T14RNS.2020012.v1.4\\HLS.S30.T14RNS.2020012.v1.4__Red.tif' returned non-zero exit status 1.\n",
      "ERROR DURING CONVERSION WITH CMD: gdal_translate HDF4_EOS:EOS_GRID:'C:\\Users\\mcecil\\CGA\\CDL\\hdf\\HLS.S30.T14RNS.2020012.v1.4.hdf':Grid:B05 C:\\Users\\mcecil\\CGA\\CDL\\tif\\HLS.S30.T14RNS.2020012.v1.4\\HLS.S30.T14RNS.2020012.v1.4__Red_Edge1.tif.\n",
      "Traceback (most recent call last):\n",
      "  File \"C:\\Users\\mcecil\\AppData\\Local\\anaconda3\\envs\\IBM_CDL\\lib\\site-packages\\nasa_hls\\hdf2tiff_conversion.py\", line 82, in convert_hdf2tiffs\n",
      "    subprocess.check_call(cmd, shell=True)\n",
      "  File \"C:\\Users\\mcecil\\AppData\\Local\\anaconda3\\envs\\IBM_CDL\\lib\\subprocess.py\", line 369, in check_call\n",
      "    raise CalledProcessError(retcode, cmd)\n",
      "subprocess.CalledProcessError: Command 'gdal_translate HDF4_EOS:EOS_GRID:'C:\\Users\\mcecil\\CGA\\CDL\\hdf\\HLS.S30.T14RNS.2020012.v1.4.hdf':Grid:B05 C:\\Users\\mcecil\\CGA\\CDL\\tif\\HLS.S30.T14RNS.2020012.v1.4\\HLS.S30.T14RNS.2020012.v1.4__Red_Edge1.tif' returned non-zero exit status 1.\n",
      "ERROR DURING CONVERSION WITH CMD: gdal_translate HDF4_EOS:EOS_GRID:'C:\\Users\\mcecil\\CGA\\CDL\\hdf\\HLS.S30.T14RNS.2020012.v1.4.hdf':Grid:B06 C:\\Users\\mcecil\\CGA\\CDL\\tif\\HLS.S30.T14RNS.2020012.v1.4\\HLS.S30.T14RNS.2020012.v1.4__Red_Edge2.tif.\n",
      "Traceback (most recent call last):\n",
      "  File \"C:\\Users\\mcecil\\AppData\\Local\\anaconda3\\envs\\IBM_CDL\\lib\\site-packages\\nasa_hls\\hdf2tiff_conversion.py\", line 82, in convert_hdf2tiffs\n",
      "    subprocess.check_call(cmd, shell=True)\n",
      "  File \"C:\\Users\\mcecil\\AppData\\Local\\anaconda3\\envs\\IBM_CDL\\lib\\subprocess.py\", line 369, in check_call\n",
      "    raise CalledProcessError(retcode, cmd)\n",
      "subprocess.CalledProcessError: Command 'gdal_translate HDF4_EOS:EOS_GRID:'C:\\Users\\mcecil\\CGA\\CDL\\hdf\\HLS.S30.T14RNS.2020012.v1.4.hdf':Grid:B06 C:\\Users\\mcecil\\CGA\\CDL\\tif\\HLS.S30.T14RNS.2020012.v1.4\\HLS.S30.T14RNS.2020012.v1.4__Red_Edge2.tif' returned non-zero exit status 1.\n",
      "ERROR DURING CONVERSION WITH CMD: gdal_translate HDF4_EOS:EOS_GRID:'C:\\Users\\mcecil\\CGA\\CDL\\hdf\\HLS.S30.T14RNS.2020012.v1.4.hdf':Grid:B07 C:\\Users\\mcecil\\CGA\\CDL\\tif\\HLS.S30.T14RNS.2020012.v1.4\\HLS.S30.T14RNS.2020012.v1.4__Red_Edge3.tif.\n",
      "Traceback (most recent call last):\n",
      "  File \"C:\\Users\\mcecil\\AppData\\Local\\anaconda3\\envs\\IBM_CDL\\lib\\site-packages\\nasa_hls\\hdf2tiff_conversion.py\", line 82, in convert_hdf2tiffs\n",
      "    subprocess.check_call(cmd, shell=True)\n",
      "  File \"C:\\Users\\mcecil\\AppData\\Local\\anaconda3\\envs\\IBM_CDL\\lib\\subprocess.py\", line 369, in check_call\n",
      "    raise CalledProcessError(retcode, cmd)\n",
      "subprocess.CalledProcessError: Command 'gdal_translate HDF4_EOS:EOS_GRID:'C:\\Users\\mcecil\\CGA\\CDL\\hdf\\HLS.S30.T14RNS.2020012.v1.4.hdf':Grid:B07 C:\\Users\\mcecil\\CGA\\CDL\\tif\\HLS.S30.T14RNS.2020012.v1.4\\HLS.S30.T14RNS.2020012.v1.4__Red_Edge3.tif' returned non-zero exit status 1.\n",
      "ERROR DURING CONVERSION WITH CMD: gdal_translate HDF4_EOS:EOS_GRID:'C:\\Users\\mcecil\\CGA\\CDL\\hdf\\HLS.S30.T14RNS.2020012.v1.4.hdf':Grid:B08 C:\\Users\\mcecil\\CGA\\CDL\\tif\\HLS.S30.T14RNS.2020012.v1.4\\HLS.S30.T14RNS.2020012.v1.4__NIR_Broad.tif.\n",
      "Traceback (most recent call last):\n",
      "  File \"C:\\Users\\mcecil\\AppData\\Local\\anaconda3\\envs\\IBM_CDL\\lib\\site-packages\\nasa_hls\\hdf2tiff_conversion.py\", line 82, in convert_hdf2tiffs\n",
      "    subprocess.check_call(cmd, shell=True)\n",
      "  File \"C:\\Users\\mcecil\\AppData\\Local\\anaconda3\\envs\\IBM_CDL\\lib\\subprocess.py\", line 369, in check_call\n",
      "    raise CalledProcessError(retcode, cmd)\n",
      "subprocess.CalledProcessError: Command 'gdal_translate HDF4_EOS:EOS_GRID:'C:\\Users\\mcecil\\CGA\\CDL\\hdf\\HLS.S30.T14RNS.2020012.v1.4.hdf':Grid:B08 C:\\Users\\mcecil\\CGA\\CDL\\tif\\HLS.S30.T14RNS.2020012.v1.4\\HLS.S30.T14RNS.2020012.v1.4__NIR_Broad.tif' returned non-zero exit status 1.\n",
      "ERROR DURING CONVERSION WITH CMD: gdal_translate HDF4_EOS:EOS_GRID:'C:\\Users\\mcecil\\CGA\\CDL\\hdf\\HLS.S30.T14RNS.2020012.v1.4.hdf':Grid:B8A C:\\Users\\mcecil\\CGA\\CDL\\tif\\HLS.S30.T14RNS.2020012.v1.4\\HLS.S30.T14RNS.2020012.v1.4__NIR_Narrow.tif.\n",
      "Traceback (most recent call last):\n",
      "  File \"C:\\Users\\mcecil\\AppData\\Local\\anaconda3\\envs\\IBM_CDL\\lib\\site-packages\\nasa_hls\\hdf2tiff_conversion.py\", line 82, in convert_hdf2tiffs\n",
      "    subprocess.check_call(cmd, shell=True)\n",
      "  File \"C:\\Users\\mcecil\\AppData\\Local\\anaconda3\\envs\\IBM_CDL\\lib\\subprocess.py\", line 369, in check_call\n",
      "    raise CalledProcessError(retcode, cmd)\n",
      "subprocess.CalledProcessError: Command 'gdal_translate HDF4_EOS:EOS_GRID:'C:\\Users\\mcecil\\CGA\\CDL\\hdf\\HLS.S30.T14RNS.2020012.v1.4.hdf':Grid:B8A C:\\Users\\mcecil\\CGA\\CDL\\tif\\HLS.S30.T14RNS.2020012.v1.4\\HLS.S30.T14RNS.2020012.v1.4__NIR_Narrow.tif' returned non-zero exit status 1.\n",
      "ERROR DURING CONVERSION WITH CMD: gdal_translate HDF4_EOS:EOS_GRID:'C:\\Users\\mcecil\\CGA\\CDL\\hdf\\HLS.S30.T14RNS.2020012.v1.4.hdf':Grid:B09 C:\\Users\\mcecil\\CGA\\CDL\\tif\\HLS.S30.T14RNS.2020012.v1.4\\HLS.S30.T14RNS.2020012.v1.4__Water_Vapor.tif.\n",
      "Traceback (most recent call last):\n",
      "  File \"C:\\Users\\mcecil\\AppData\\Local\\anaconda3\\envs\\IBM_CDL\\lib\\site-packages\\nasa_hls\\hdf2tiff_conversion.py\", line 82, in convert_hdf2tiffs\n",
      "    subprocess.check_call(cmd, shell=True)\n",
      "  File \"C:\\Users\\mcecil\\AppData\\Local\\anaconda3\\envs\\IBM_CDL\\lib\\subprocess.py\", line 369, in check_call\n",
      "    raise CalledProcessError(retcode, cmd)\n",
      "subprocess.CalledProcessError: Command 'gdal_translate HDF4_EOS:EOS_GRID:'C:\\Users\\mcecil\\CGA\\CDL\\hdf\\HLS.S30.T14RNS.2020012.v1.4.hdf':Grid:B09 C:\\Users\\mcecil\\CGA\\CDL\\tif\\HLS.S30.T14RNS.2020012.v1.4\\HLS.S30.T14RNS.2020012.v1.4__Water_Vapor.tif' returned non-zero exit status 1.\n",
      "ERROR DURING CONVERSION WITH CMD: gdal_translate HDF4_EOS:EOS_GRID:'C:\\Users\\mcecil\\CGA\\CDL\\hdf\\HLS.S30.T14RNS.2020012.v1.4.hdf':Grid:B10 C:\\Users\\mcecil\\CGA\\CDL\\tif\\HLS.S30.T14RNS.2020012.v1.4\\HLS.S30.T14RNS.2020012.v1.4__Cirrus.tif.\n",
      "Traceback (most recent call last):\n",
      "  File \"C:\\Users\\mcecil\\AppData\\Local\\anaconda3\\envs\\IBM_CDL\\lib\\site-packages\\nasa_hls\\hdf2tiff_conversion.py\", line 82, in convert_hdf2tiffs\n",
      "    subprocess.check_call(cmd, shell=True)\n",
      "  File \"C:\\Users\\mcecil\\AppData\\Local\\anaconda3\\envs\\IBM_CDL\\lib\\subprocess.py\", line 369, in check_call\n",
      "    raise CalledProcessError(retcode, cmd)\n",
      "subprocess.CalledProcessError: Command 'gdal_translate HDF4_EOS:EOS_GRID:'C:\\Users\\mcecil\\CGA\\CDL\\hdf\\HLS.S30.T14RNS.2020012.v1.4.hdf':Grid:B10 C:\\Users\\mcecil\\CGA\\CDL\\tif\\HLS.S30.T14RNS.2020012.v1.4\\HLS.S30.T14RNS.2020012.v1.4__Cirrus.tif' returned non-zero exit status 1.\n",
      "ERROR DURING CONVERSION WITH CMD: gdal_translate HDF4_EOS:EOS_GRID:'C:\\Users\\mcecil\\CGA\\CDL\\hdf\\HLS.S30.T14RNS.2020012.v1.4.hdf':Grid:B11 C:\\Users\\mcecil\\CGA\\CDL\\tif\\HLS.S30.T14RNS.2020012.v1.4\\HLS.S30.T14RNS.2020012.v1.4__SWIR1.tif.\n",
      "Traceback (most recent call last):\n",
      "  File \"C:\\Users\\mcecil\\AppData\\Local\\anaconda3\\envs\\IBM_CDL\\lib\\site-packages\\nasa_hls\\hdf2tiff_conversion.py\", line 82, in convert_hdf2tiffs\n",
      "    subprocess.check_call(cmd, shell=True)\n",
      "  File \"C:\\Users\\mcecil\\AppData\\Local\\anaconda3\\envs\\IBM_CDL\\lib\\subprocess.py\", line 369, in check_call\n",
      "    raise CalledProcessError(retcode, cmd)\n",
      "subprocess.CalledProcessError: Command 'gdal_translate HDF4_EOS:EOS_GRID:'C:\\Users\\mcecil\\CGA\\CDL\\hdf\\HLS.S30.T14RNS.2020012.v1.4.hdf':Grid:B11 C:\\Users\\mcecil\\CGA\\CDL\\tif\\HLS.S30.T14RNS.2020012.v1.4\\HLS.S30.T14RNS.2020012.v1.4__SWIR1.tif' returned non-zero exit status 1.\n",
      "ERROR DURING CONVERSION WITH CMD: gdal_translate HDF4_EOS:EOS_GRID:'C:\\Users\\mcecil\\CGA\\CDL\\hdf\\HLS.S30.T14RNS.2020012.v1.4.hdf':Grid:B12 C:\\Users\\mcecil\\CGA\\CDL\\tif\\HLS.S30.T14RNS.2020012.v1.4\\HLS.S30.T14RNS.2020012.v1.4__SWIR2.tif.\n",
      "Traceback (most recent call last):\n",
      "  File \"C:\\Users\\mcecil\\AppData\\Local\\anaconda3\\envs\\IBM_CDL\\lib\\site-packages\\nasa_hls\\hdf2tiff_conversion.py\", line 82, in convert_hdf2tiffs\n",
      "    subprocess.check_call(cmd, shell=True)\n",
      "  File \"C:\\Users\\mcecil\\AppData\\Local\\anaconda3\\envs\\IBM_CDL\\lib\\subprocess.py\", line 369, in check_call\n",
      "    raise CalledProcessError(retcode, cmd)\n",
      "subprocess.CalledProcessError: Command 'gdal_translate HDF4_EOS:EOS_GRID:'C:\\Users\\mcecil\\CGA\\CDL\\hdf\\HLS.S30.T14RNS.2020012.v1.4.hdf':Grid:B12 C:\\Users\\mcecil\\CGA\\CDL\\tif\\HLS.S30.T14RNS.2020012.v1.4\\HLS.S30.T14RNS.2020012.v1.4__SWIR2.tif' returned non-zero exit status 1.\n",
      "ERROR DURING CONVERSION WITH CMD: gdal_translate HDF4_EOS:EOS_GRID:'C:\\Users\\mcecil\\CGA\\CDL\\hdf\\HLS.S30.T14RNS.2020012.v1.4.hdf':Grid:QA C:\\Users\\mcecil\\CGA\\CDL\\tif\\HLS.S30.T14RNS.2020012.v1.4\\HLS.S30.T14RNS.2020012.v1.4__QA.tif.\n",
      "Traceback (most recent call last):\n",
      "  File \"C:\\Users\\mcecil\\AppData\\Local\\anaconda3\\envs\\IBM_CDL\\lib\\site-packages\\nasa_hls\\hdf2tiff_conversion.py\", line 82, in convert_hdf2tiffs\n",
      "    subprocess.check_call(cmd, shell=True)\n",
      "  File \"C:\\Users\\mcecil\\AppData\\Local\\anaconda3\\envs\\IBM_CDL\\lib\\subprocess.py\", line 369, in check_call\n",
      "    raise CalledProcessError(retcode, cmd)\n",
      "subprocess.CalledProcessError: Command 'gdal_translate HDF4_EOS:EOS_GRID:'C:\\Users\\mcecil\\CGA\\CDL\\hdf\\HLS.S30.T14RNS.2020012.v1.4.hdf':Grid:QA C:\\Users\\mcecil\\CGA\\CDL\\tif\\HLS.S30.T14RNS.2020012.v1.4\\HLS.S30.T14RNS.2020012.v1.4__QA.tif' returned non-zero exit status 1.\n",
      "ERROR DURING CONVERSION WITH CMD: gdal_translate HDF4_EOS:EOS_GRID:'C:\\Users\\mcecil\\CGA\\CDL\\hdf\\HLS.S30.T14RNS.2020015.v1.4.hdf':Grid:B01 C:\\Users\\mcecil\\CGA\\CDL\\tif\\HLS.S30.T14RNS.2020015.v1.4\\HLS.S30.T14RNS.2020015.v1.4__Coastal_Aerosol.tif.\n",
      "Traceback (most recent call last):\n",
      "  File \"C:\\Users\\mcecil\\AppData\\Local\\anaconda3\\envs\\IBM_CDL\\lib\\site-packages\\nasa_hls\\hdf2tiff_conversion.py\", line 82, in convert_hdf2tiffs\n",
      "    subprocess.check_call(cmd, shell=True)\n",
      "  File \"C:\\Users\\mcecil\\AppData\\Local\\anaconda3\\envs\\IBM_CDL\\lib\\subprocess.py\", line 369, in check_call\n",
      "    raise CalledProcessError(retcode, cmd)\n",
      "subprocess.CalledProcessError: Command 'gdal_translate HDF4_EOS:EOS_GRID:'C:\\Users\\mcecil\\CGA\\CDL\\hdf\\HLS.S30.T14RNS.2020015.v1.4.hdf':Grid:B01 C:\\Users\\mcecil\\CGA\\CDL\\tif\\HLS.S30.T14RNS.2020015.v1.4\\HLS.S30.T14RNS.2020015.v1.4__Coastal_Aerosol.tif' returned non-zero exit status 1.\n",
      "ERROR DURING CONVERSION WITH CMD: gdal_translate HDF4_EOS:EOS_GRID:'C:\\Users\\mcecil\\CGA\\CDL\\hdf\\HLS.S30.T14RNS.2020015.v1.4.hdf':Grid:B02 C:\\Users\\mcecil\\CGA\\CDL\\tif\\HLS.S30.T14RNS.2020015.v1.4\\HLS.S30.T14RNS.2020015.v1.4__Blue.tif.\n",
      "Traceback (most recent call last):\n",
      "  File \"C:\\Users\\mcecil\\AppData\\Local\\anaconda3\\envs\\IBM_CDL\\lib\\site-packages\\nasa_hls\\hdf2tiff_conversion.py\", line 82, in convert_hdf2tiffs\n",
      "    subprocess.check_call(cmd, shell=True)\n",
      "  File \"C:\\Users\\mcecil\\AppData\\Local\\anaconda3\\envs\\IBM_CDL\\lib\\subprocess.py\", line 369, in check_call\n",
      "    raise CalledProcessError(retcode, cmd)\n",
      "subprocess.CalledProcessError: Command 'gdal_translate HDF4_EOS:EOS_GRID:'C:\\Users\\mcecil\\CGA\\CDL\\hdf\\HLS.S30.T14RNS.2020015.v1.4.hdf':Grid:B02 C:\\Users\\mcecil\\CGA\\CDL\\tif\\HLS.S30.T14RNS.2020015.v1.4\\HLS.S30.T14RNS.2020015.v1.4__Blue.tif' returned non-zero exit status 1.\n",
      "ERROR DURING CONVERSION WITH CMD: gdal_translate HDF4_EOS:EOS_GRID:'C:\\Users\\mcecil\\CGA\\CDL\\hdf\\HLS.S30.T14RNS.2020015.v1.4.hdf':Grid:B03 C:\\Users\\mcecil\\CGA\\CDL\\tif\\HLS.S30.T14RNS.2020015.v1.4\\HLS.S30.T14RNS.2020015.v1.4__Green.tif.\n",
      "Traceback (most recent call last):\n",
      "  File \"C:\\Users\\mcecil\\AppData\\Local\\anaconda3\\envs\\IBM_CDL\\lib\\site-packages\\nasa_hls\\hdf2tiff_conversion.py\", line 82, in convert_hdf2tiffs\n",
      "    subprocess.check_call(cmd, shell=True)\n",
      "  File \"C:\\Users\\mcecil\\AppData\\Local\\anaconda3\\envs\\IBM_CDL\\lib\\subprocess.py\", line 369, in check_call\n",
      "    raise CalledProcessError(retcode, cmd)\n",
      "subprocess.CalledProcessError: Command 'gdal_translate HDF4_EOS:EOS_GRID:'C:\\Users\\mcecil\\CGA\\CDL\\hdf\\HLS.S30.T14RNS.2020015.v1.4.hdf':Grid:B03 C:\\Users\\mcecil\\CGA\\CDL\\tif\\HLS.S30.T14RNS.2020015.v1.4\\HLS.S30.T14RNS.2020015.v1.4__Green.tif' returned non-zero exit status 1.\n",
      "ERROR DURING CONVERSION WITH CMD: gdal_translate HDF4_EOS:EOS_GRID:'C:\\Users\\mcecil\\CGA\\CDL\\hdf\\HLS.S30.T14RNS.2020015.v1.4.hdf':Grid:B04 C:\\Users\\mcecil\\CGA\\CDL\\tif\\HLS.S30.T14RNS.2020015.v1.4\\HLS.S30.T14RNS.2020015.v1.4__Red.tif.\n",
      "Traceback (most recent call last):\n",
      "  File \"C:\\Users\\mcecil\\AppData\\Local\\anaconda3\\envs\\IBM_CDL\\lib\\site-packages\\nasa_hls\\hdf2tiff_conversion.py\", line 82, in convert_hdf2tiffs\n",
      "    subprocess.check_call(cmd, shell=True)\n",
      "  File \"C:\\Users\\mcecil\\AppData\\Local\\anaconda3\\envs\\IBM_CDL\\lib\\subprocess.py\", line 369, in check_call\n",
      "    raise CalledProcessError(retcode, cmd)\n",
      "subprocess.CalledProcessError: Command 'gdal_translate HDF4_EOS:EOS_GRID:'C:\\Users\\mcecil\\CGA\\CDL\\hdf\\HLS.S30.T14RNS.2020015.v1.4.hdf':Grid:B04 C:\\Users\\mcecil\\CGA\\CDL\\tif\\HLS.S30.T14RNS.2020015.v1.4\\HLS.S30.T14RNS.2020015.v1.4__Red.tif' returned non-zero exit status 1.\n",
      "ERROR DURING CONVERSION WITH CMD: gdal_translate HDF4_EOS:EOS_GRID:'C:\\Users\\mcecil\\CGA\\CDL\\hdf\\HLS.S30.T14RNS.2020015.v1.4.hdf':Grid:B05 C:\\Users\\mcecil\\CGA\\CDL\\tif\\HLS.S30.T14RNS.2020015.v1.4\\HLS.S30.T14RNS.2020015.v1.4__Red_Edge1.tif.\n",
      "Traceback (most recent call last):\n",
      "  File \"C:\\Users\\mcecil\\AppData\\Local\\anaconda3\\envs\\IBM_CDL\\lib\\site-packages\\nasa_hls\\hdf2tiff_conversion.py\", line 82, in convert_hdf2tiffs\n",
      "    subprocess.check_call(cmd, shell=True)\n",
      "  File \"C:\\Users\\mcecil\\AppData\\Local\\anaconda3\\envs\\IBM_CDL\\lib\\subprocess.py\", line 369, in check_call\n",
      "    raise CalledProcessError(retcode, cmd)\n",
      "subprocess.CalledProcessError: Command 'gdal_translate HDF4_EOS:EOS_GRID:'C:\\Users\\mcecil\\CGA\\CDL\\hdf\\HLS.S30.T14RNS.2020015.v1.4.hdf':Grid:B05 C:\\Users\\mcecil\\CGA\\CDL\\tif\\HLS.S30.T14RNS.2020015.v1.4\\HLS.S30.T14RNS.2020015.v1.4__Red_Edge1.tif' returned non-zero exit status 1.\n",
      "ERROR DURING CONVERSION WITH CMD: gdal_translate HDF4_EOS:EOS_GRID:'C:\\Users\\mcecil\\CGA\\CDL\\hdf\\HLS.S30.T14RNS.2020015.v1.4.hdf':Grid:B06 C:\\Users\\mcecil\\CGA\\CDL\\tif\\HLS.S30.T14RNS.2020015.v1.4\\HLS.S30.T14RNS.2020015.v1.4__Red_Edge2.tif.\n",
      "Traceback (most recent call last):\n",
      "  File \"C:\\Users\\mcecil\\AppData\\Local\\anaconda3\\envs\\IBM_CDL\\lib\\site-packages\\nasa_hls\\hdf2tiff_conversion.py\", line 82, in convert_hdf2tiffs\n",
      "    subprocess.check_call(cmd, shell=True)\n",
      "  File \"C:\\Users\\mcecil\\AppData\\Local\\anaconda3\\envs\\IBM_CDL\\lib\\subprocess.py\", line 369, in check_call\n",
      "    raise CalledProcessError(retcode, cmd)\n",
      "subprocess.CalledProcessError: Command 'gdal_translate HDF4_EOS:EOS_GRID:'C:\\Users\\mcecil\\CGA\\CDL\\hdf\\HLS.S30.T14RNS.2020015.v1.4.hdf':Grid:B06 C:\\Users\\mcecil\\CGA\\CDL\\tif\\HLS.S30.T14RNS.2020015.v1.4\\HLS.S30.T14RNS.2020015.v1.4__Red_Edge2.tif' returned non-zero exit status 1.\n",
      "ERROR DURING CONVERSION WITH CMD: gdal_translate HDF4_EOS:EOS_GRID:'C:\\Users\\mcecil\\CGA\\CDL\\hdf\\HLS.S30.T14RNS.2020015.v1.4.hdf':Grid:B07 C:\\Users\\mcecil\\CGA\\CDL\\tif\\HLS.S30.T14RNS.2020015.v1.4\\HLS.S30.T14RNS.2020015.v1.4__Red_Edge3.tif.\n",
      "Traceback (most recent call last):\n",
      "  File \"C:\\Users\\mcecil\\AppData\\Local\\anaconda3\\envs\\IBM_CDL\\lib\\site-packages\\nasa_hls\\hdf2tiff_conversion.py\", line 82, in convert_hdf2tiffs\n",
      "    subprocess.check_call(cmd, shell=True)\n",
      "  File \"C:\\Users\\mcecil\\AppData\\Local\\anaconda3\\envs\\IBM_CDL\\lib\\subprocess.py\", line 369, in check_call\n",
      "    raise CalledProcessError(retcode, cmd)\n",
      "subprocess.CalledProcessError: Command 'gdal_translate HDF4_EOS:EOS_GRID:'C:\\Users\\mcecil\\CGA\\CDL\\hdf\\HLS.S30.T14RNS.2020015.v1.4.hdf':Grid:B07 C:\\Users\\mcecil\\CGA\\CDL\\tif\\HLS.S30.T14RNS.2020015.v1.4\\HLS.S30.T14RNS.2020015.v1.4__Red_Edge3.tif' returned non-zero exit status 1.\n",
      "ERROR DURING CONVERSION WITH CMD: gdal_translate HDF4_EOS:EOS_GRID:'C:\\Users\\mcecil\\CGA\\CDL\\hdf\\HLS.S30.T14RNS.2020015.v1.4.hdf':Grid:B08 C:\\Users\\mcecil\\CGA\\CDL\\tif\\HLS.S30.T14RNS.2020015.v1.4\\HLS.S30.T14RNS.2020015.v1.4__NIR_Broad.tif.\n",
      "Traceback (most recent call last):\n",
      "  File \"C:\\Users\\mcecil\\AppData\\Local\\anaconda3\\envs\\IBM_CDL\\lib\\site-packages\\nasa_hls\\hdf2tiff_conversion.py\", line 82, in convert_hdf2tiffs\n",
      "    subprocess.check_call(cmd, shell=True)\n",
      "  File \"C:\\Users\\mcecil\\AppData\\Local\\anaconda3\\envs\\IBM_CDL\\lib\\subprocess.py\", line 369, in check_call\n",
      "    raise CalledProcessError(retcode, cmd)\n",
      "subprocess.CalledProcessError: Command 'gdal_translate HDF4_EOS:EOS_GRID:'C:\\Users\\mcecil\\CGA\\CDL\\hdf\\HLS.S30.T14RNS.2020015.v1.4.hdf':Grid:B08 C:\\Users\\mcecil\\CGA\\CDL\\tif\\HLS.S30.T14RNS.2020015.v1.4\\HLS.S30.T14RNS.2020015.v1.4__NIR_Broad.tif' returned non-zero exit status 1.\n",
      "ERROR DURING CONVERSION WITH CMD: gdal_translate HDF4_EOS:EOS_GRID:'C:\\Users\\mcecil\\CGA\\CDL\\hdf\\HLS.S30.T14RNS.2020015.v1.4.hdf':Grid:B8A C:\\Users\\mcecil\\CGA\\CDL\\tif\\HLS.S30.T14RNS.2020015.v1.4\\HLS.S30.T14RNS.2020015.v1.4__NIR_Narrow.tif.\n",
      "Traceback (most recent call last):\n",
      "  File \"C:\\Users\\mcecil\\AppData\\Local\\anaconda3\\envs\\IBM_CDL\\lib\\site-packages\\nasa_hls\\hdf2tiff_conversion.py\", line 82, in convert_hdf2tiffs\n",
      "    subprocess.check_call(cmd, shell=True)\n",
      "  File \"C:\\Users\\mcecil\\AppData\\Local\\anaconda3\\envs\\IBM_CDL\\lib\\subprocess.py\", line 369, in check_call\n",
      "    raise CalledProcessError(retcode, cmd)\n",
      "subprocess.CalledProcessError: Command 'gdal_translate HDF4_EOS:EOS_GRID:'C:\\Users\\mcecil\\CGA\\CDL\\hdf\\HLS.S30.T14RNS.2020015.v1.4.hdf':Grid:B8A C:\\Users\\mcecil\\CGA\\CDL\\tif\\HLS.S30.T14RNS.2020015.v1.4\\HLS.S30.T14RNS.2020015.v1.4__NIR_Narrow.tif' returned non-zero exit status 1.\n",
      "ERROR DURING CONVERSION WITH CMD: gdal_translate HDF4_EOS:EOS_GRID:'C:\\Users\\mcecil\\CGA\\CDL\\hdf\\HLS.S30.T14RNS.2020015.v1.4.hdf':Grid:B09 C:\\Users\\mcecil\\CGA\\CDL\\tif\\HLS.S30.T14RNS.2020015.v1.4\\HLS.S30.T14RNS.2020015.v1.4__Water_Vapor.tif.\n",
      "Traceback (most recent call last):\n",
      "  File \"C:\\Users\\mcecil\\AppData\\Local\\anaconda3\\envs\\IBM_CDL\\lib\\site-packages\\nasa_hls\\hdf2tiff_conversion.py\", line 82, in convert_hdf2tiffs\n",
      "    subprocess.check_call(cmd, shell=True)\n",
      "  File \"C:\\Users\\mcecil\\AppData\\Local\\anaconda3\\envs\\IBM_CDL\\lib\\subprocess.py\", line 369, in check_call\n",
      "    raise CalledProcessError(retcode, cmd)\n",
      "subprocess.CalledProcessError: Command 'gdal_translate HDF4_EOS:EOS_GRID:'C:\\Users\\mcecil\\CGA\\CDL\\hdf\\HLS.S30.T14RNS.2020015.v1.4.hdf':Grid:B09 C:\\Users\\mcecil\\CGA\\CDL\\tif\\HLS.S30.T14RNS.2020015.v1.4\\HLS.S30.T14RNS.2020015.v1.4__Water_Vapor.tif' returned non-zero exit status 1.\n",
      "ERROR DURING CONVERSION WITH CMD: gdal_translate HDF4_EOS:EOS_GRID:'C:\\Users\\mcecil\\CGA\\CDL\\hdf\\HLS.S30.T14RNS.2020015.v1.4.hdf':Grid:B10 C:\\Users\\mcecil\\CGA\\CDL\\tif\\HLS.S30.T14RNS.2020015.v1.4\\HLS.S30.T14RNS.2020015.v1.4__Cirrus.tif.\n",
      "Traceback (most recent call last):\n",
      "  File \"C:\\Users\\mcecil\\AppData\\Local\\anaconda3\\envs\\IBM_CDL\\lib\\site-packages\\nasa_hls\\hdf2tiff_conversion.py\", line 82, in convert_hdf2tiffs\n",
      "    subprocess.check_call(cmd, shell=True)\n",
      "  File \"C:\\Users\\mcecil\\AppData\\Local\\anaconda3\\envs\\IBM_CDL\\lib\\subprocess.py\", line 369, in check_call\n",
      "    raise CalledProcessError(retcode, cmd)\n",
      "subprocess.CalledProcessError: Command 'gdal_translate HDF4_EOS:EOS_GRID:'C:\\Users\\mcecil\\CGA\\CDL\\hdf\\HLS.S30.T14RNS.2020015.v1.4.hdf':Grid:B10 C:\\Users\\mcecil\\CGA\\CDL\\tif\\HLS.S30.T14RNS.2020015.v1.4\\HLS.S30.T14RNS.2020015.v1.4__Cirrus.tif' returned non-zero exit status 1.\n",
      "ERROR DURING CONVERSION WITH CMD: gdal_translate HDF4_EOS:EOS_GRID:'C:\\Users\\mcecil\\CGA\\CDL\\hdf\\HLS.S30.T14RNS.2020015.v1.4.hdf':Grid:B11 C:\\Users\\mcecil\\CGA\\CDL\\tif\\HLS.S30.T14RNS.2020015.v1.4\\HLS.S30.T14RNS.2020015.v1.4__SWIR1.tif.\n",
      "Traceback (most recent call last):\n",
      "  File \"C:\\Users\\mcecil\\AppData\\Local\\anaconda3\\envs\\IBM_CDL\\lib\\site-packages\\nasa_hls\\hdf2tiff_conversion.py\", line 82, in convert_hdf2tiffs\n",
      "    subprocess.check_call(cmd, shell=True)\n",
      "  File \"C:\\Users\\mcecil\\AppData\\Local\\anaconda3\\envs\\IBM_CDL\\lib\\subprocess.py\", line 369, in check_call\n",
      "    raise CalledProcessError(retcode, cmd)\n",
      "subprocess.CalledProcessError: Command 'gdal_translate HDF4_EOS:EOS_GRID:'C:\\Users\\mcecil\\CGA\\CDL\\hdf\\HLS.S30.T14RNS.2020015.v1.4.hdf':Grid:B11 C:\\Users\\mcecil\\CGA\\CDL\\tif\\HLS.S30.T14RNS.2020015.v1.4\\HLS.S30.T14RNS.2020015.v1.4__SWIR1.tif' returned non-zero exit status 1.\n",
      "ERROR DURING CONVERSION WITH CMD: gdal_translate HDF4_EOS:EOS_GRID:'C:\\Users\\mcecil\\CGA\\CDL\\hdf\\HLS.S30.T14RNS.2020015.v1.4.hdf':Grid:B12 C:\\Users\\mcecil\\CGA\\CDL\\tif\\HLS.S30.T14RNS.2020015.v1.4\\HLS.S30.T14RNS.2020015.v1.4__SWIR2.tif.\n",
      "Traceback (most recent call last):\n",
      "  File \"C:\\Users\\mcecil\\AppData\\Local\\anaconda3\\envs\\IBM_CDL\\lib\\site-packages\\nasa_hls\\hdf2tiff_conversion.py\", line 82, in convert_hdf2tiffs\n",
      "    subprocess.check_call(cmd, shell=True)\n",
      "  File \"C:\\Users\\mcecil\\AppData\\Local\\anaconda3\\envs\\IBM_CDL\\lib\\subprocess.py\", line 369, in check_call\n",
      "    raise CalledProcessError(retcode, cmd)\n",
      "subprocess.CalledProcessError: Command 'gdal_translate HDF4_EOS:EOS_GRID:'C:\\Users\\mcecil\\CGA\\CDL\\hdf\\HLS.S30.T14RNS.2020015.v1.4.hdf':Grid:B12 C:\\Users\\mcecil\\CGA\\CDL\\tif\\HLS.S30.T14RNS.2020015.v1.4\\HLS.S30.T14RNS.2020015.v1.4__SWIR2.tif' returned non-zero exit status 1.\n",
      "ERROR DURING CONVERSION WITH CMD: gdal_translate HDF4_EOS:EOS_GRID:'C:\\Users\\mcecil\\CGA\\CDL\\hdf\\HLS.S30.T14RNS.2020015.v1.4.hdf':Grid:QA C:\\Users\\mcecil\\CGA\\CDL\\tif\\HLS.S30.T14RNS.2020015.v1.4\\HLS.S30.T14RNS.2020015.v1.4__QA.tif.\n",
      "Traceback (most recent call last):\n",
      "  File \"C:\\Users\\mcecil\\AppData\\Local\\anaconda3\\envs\\IBM_CDL\\lib\\site-packages\\nasa_hls\\hdf2tiff_conversion.py\", line 82, in convert_hdf2tiffs\n",
      "    subprocess.check_call(cmd, shell=True)\n",
      "  File \"C:\\Users\\mcecil\\AppData\\Local\\anaconda3\\envs\\IBM_CDL\\lib\\subprocess.py\", line 369, in check_call\n",
      "    raise CalledProcessError(retcode, cmd)\n",
      "subprocess.CalledProcessError: Command 'gdal_translate HDF4_EOS:EOS_GRID:'C:\\Users\\mcecil\\CGA\\CDL\\hdf\\HLS.S30.T14RNS.2020015.v1.4.hdf':Grid:QA C:\\Users\\mcecil\\CGA\\CDL\\tif\\HLS.S30.T14RNS.2020015.v1.4\\HLS.S30.T14RNS.2020015.v1.4__QA.tif' returned non-zero exit status 1.\n",
      "ERROR DURING CONVERSION WITH CMD: gdal_translate HDF4_EOS:EOS_GRID:'C:\\Users\\mcecil\\CGA\\CDL\\hdf\\HLS.S30.T14RNS.2020017.v1.4.hdf':Grid:B01 C:\\Users\\mcecil\\CGA\\CDL\\tif\\HLS.S30.T14RNS.2020017.v1.4\\HLS.S30.T14RNS.2020017.v1.4__Coastal_Aerosol.tif.\n",
      "Traceback (most recent call last):\n",
      "  File \"C:\\Users\\mcecil\\AppData\\Local\\anaconda3\\envs\\IBM_CDL\\lib\\site-packages\\nasa_hls\\hdf2tiff_conversion.py\", line 82, in convert_hdf2tiffs\n",
      "    subprocess.check_call(cmd, shell=True)\n",
      "  File \"C:\\Users\\mcecil\\AppData\\Local\\anaconda3\\envs\\IBM_CDL\\lib\\subprocess.py\", line 369, in check_call\n",
      "    raise CalledProcessError(retcode, cmd)\n",
      "subprocess.CalledProcessError: Command 'gdal_translate HDF4_EOS:EOS_GRID:'C:\\Users\\mcecil\\CGA\\CDL\\hdf\\HLS.S30.T14RNS.2020017.v1.4.hdf':Grid:B01 C:\\Users\\mcecil\\CGA\\CDL\\tif\\HLS.S30.T14RNS.2020017.v1.4\\HLS.S30.T14RNS.2020017.v1.4__Coastal_Aerosol.tif' returned non-zero exit status 1.\n",
      "ERROR DURING CONVERSION WITH CMD: gdal_translate HDF4_EOS:EOS_GRID:'C:\\Users\\mcecil\\CGA\\CDL\\hdf\\HLS.S30.T14RNS.2020017.v1.4.hdf':Grid:B02 C:\\Users\\mcecil\\CGA\\CDL\\tif\\HLS.S30.T14RNS.2020017.v1.4\\HLS.S30.T14RNS.2020017.v1.4__Blue.tif.\n",
      "Traceback (most recent call last):\n",
      "  File \"C:\\Users\\mcecil\\AppData\\Local\\anaconda3\\envs\\IBM_CDL\\lib\\site-packages\\nasa_hls\\hdf2tiff_conversion.py\", line 82, in convert_hdf2tiffs\n",
      "    subprocess.check_call(cmd, shell=True)\n",
      "  File \"C:\\Users\\mcecil\\AppData\\Local\\anaconda3\\envs\\IBM_CDL\\lib\\subprocess.py\", line 369, in check_call\n",
      "    raise CalledProcessError(retcode, cmd)\n",
      "subprocess.CalledProcessError: Command 'gdal_translate HDF4_EOS:EOS_GRID:'C:\\Users\\mcecil\\CGA\\CDL\\hdf\\HLS.S30.T14RNS.2020017.v1.4.hdf':Grid:B02 C:\\Users\\mcecil\\CGA\\CDL\\tif\\HLS.S30.T14RNS.2020017.v1.4\\HLS.S30.T14RNS.2020017.v1.4__Blue.tif' returned non-zero exit status 1.\n",
      "ERROR DURING CONVERSION WITH CMD: gdal_translate HDF4_EOS:EOS_GRID:'C:\\Users\\mcecil\\CGA\\CDL\\hdf\\HLS.S30.T14RNS.2020017.v1.4.hdf':Grid:B03 C:\\Users\\mcecil\\CGA\\CDL\\tif\\HLS.S30.T14RNS.2020017.v1.4\\HLS.S30.T14RNS.2020017.v1.4__Green.tif.\n",
      "Traceback (most recent call last):\n",
      "  File \"C:\\Users\\mcecil\\AppData\\Local\\anaconda3\\envs\\IBM_CDL\\lib\\site-packages\\nasa_hls\\hdf2tiff_conversion.py\", line 82, in convert_hdf2tiffs\n",
      "    subprocess.check_call(cmd, shell=True)\n",
      "  File \"C:\\Users\\mcecil\\AppData\\Local\\anaconda3\\envs\\IBM_CDL\\lib\\subprocess.py\", line 369, in check_call\n",
      "    raise CalledProcessError(retcode, cmd)\n",
      "subprocess.CalledProcessError: Command 'gdal_translate HDF4_EOS:EOS_GRID:'C:\\Users\\mcecil\\CGA\\CDL\\hdf\\HLS.S30.T14RNS.2020017.v1.4.hdf':Grid:B03 C:\\Users\\mcecil\\CGA\\CDL\\tif\\HLS.S30.T14RNS.2020017.v1.4\\HLS.S30.T14RNS.2020017.v1.4__Green.tif' returned non-zero exit status 1.\n",
      "ERROR DURING CONVERSION WITH CMD: gdal_translate HDF4_EOS:EOS_GRID:'C:\\Users\\mcecil\\CGA\\CDL\\hdf\\HLS.S30.T14RNS.2020017.v1.4.hdf':Grid:B04 C:\\Users\\mcecil\\CGA\\CDL\\tif\\HLS.S30.T14RNS.2020017.v1.4\\HLS.S30.T14RNS.2020017.v1.4__Red.tif.\n",
      "Traceback (most recent call last):\n",
      "  File \"C:\\Users\\mcecil\\AppData\\Local\\anaconda3\\envs\\IBM_CDL\\lib\\site-packages\\nasa_hls\\hdf2tiff_conversion.py\", line 82, in convert_hdf2tiffs\n",
      "    subprocess.check_call(cmd, shell=True)\n",
      "  File \"C:\\Users\\mcecil\\AppData\\Local\\anaconda3\\envs\\IBM_CDL\\lib\\subprocess.py\", line 369, in check_call\n",
      "    raise CalledProcessError(retcode, cmd)\n",
      "subprocess.CalledProcessError: Command 'gdal_translate HDF4_EOS:EOS_GRID:'C:\\Users\\mcecil\\CGA\\CDL\\hdf\\HLS.S30.T14RNS.2020017.v1.4.hdf':Grid:B04 C:\\Users\\mcecil\\CGA\\CDL\\tif\\HLS.S30.T14RNS.2020017.v1.4\\HLS.S30.T14RNS.2020017.v1.4__Red.tif' returned non-zero exit status 1.\n",
      "ERROR DURING CONVERSION WITH CMD: gdal_translate HDF4_EOS:EOS_GRID:'C:\\Users\\mcecil\\CGA\\CDL\\hdf\\HLS.S30.T14RNS.2020017.v1.4.hdf':Grid:B05 C:\\Users\\mcecil\\CGA\\CDL\\tif\\HLS.S30.T14RNS.2020017.v1.4\\HLS.S30.T14RNS.2020017.v1.4__Red_Edge1.tif.\n",
      "Traceback (most recent call last):\n",
      "  File \"C:\\Users\\mcecil\\AppData\\Local\\anaconda3\\envs\\IBM_CDL\\lib\\site-packages\\nasa_hls\\hdf2tiff_conversion.py\", line 82, in convert_hdf2tiffs\n",
      "    subprocess.check_call(cmd, shell=True)\n",
      "  File \"C:\\Users\\mcecil\\AppData\\Local\\anaconda3\\envs\\IBM_CDL\\lib\\subprocess.py\", line 369, in check_call\n",
      "    raise CalledProcessError(retcode, cmd)\n",
      "subprocess.CalledProcessError: Command 'gdal_translate HDF4_EOS:EOS_GRID:'C:\\Users\\mcecil\\CGA\\CDL\\hdf\\HLS.S30.T14RNS.2020017.v1.4.hdf':Grid:B05 C:\\Users\\mcecil\\CGA\\CDL\\tif\\HLS.S30.T14RNS.2020017.v1.4\\HLS.S30.T14RNS.2020017.v1.4__Red_Edge1.tif' returned non-zero exit status 1.\n",
      "ERROR DURING CONVERSION WITH CMD: gdal_translate HDF4_EOS:EOS_GRID:'C:\\Users\\mcecil\\CGA\\CDL\\hdf\\HLS.S30.T14RNS.2020017.v1.4.hdf':Grid:B06 C:\\Users\\mcecil\\CGA\\CDL\\tif\\HLS.S30.T14RNS.2020017.v1.4\\HLS.S30.T14RNS.2020017.v1.4__Red_Edge2.tif.\n",
      "Traceback (most recent call last):\n",
      "  File \"C:\\Users\\mcecil\\AppData\\Local\\anaconda3\\envs\\IBM_CDL\\lib\\site-packages\\nasa_hls\\hdf2tiff_conversion.py\", line 82, in convert_hdf2tiffs\n",
      "    subprocess.check_call(cmd, shell=True)\n",
      "  File \"C:\\Users\\mcecil\\AppData\\Local\\anaconda3\\envs\\IBM_CDL\\lib\\subprocess.py\", line 369, in check_call\n",
      "    raise CalledProcessError(retcode, cmd)\n",
      "subprocess.CalledProcessError: Command 'gdal_translate HDF4_EOS:EOS_GRID:'C:\\Users\\mcecil\\CGA\\CDL\\hdf\\HLS.S30.T14RNS.2020017.v1.4.hdf':Grid:B06 C:\\Users\\mcecil\\CGA\\CDL\\tif\\HLS.S30.T14RNS.2020017.v1.4\\HLS.S30.T14RNS.2020017.v1.4__Red_Edge2.tif' returned non-zero exit status 1.\n",
      "ERROR DURING CONVERSION WITH CMD: gdal_translate HDF4_EOS:EOS_GRID:'C:\\Users\\mcecil\\CGA\\CDL\\hdf\\HLS.S30.T14RNS.2020017.v1.4.hdf':Grid:B07 C:\\Users\\mcecil\\CGA\\CDL\\tif\\HLS.S30.T14RNS.2020017.v1.4\\HLS.S30.T14RNS.2020017.v1.4__Red_Edge3.tif.\n",
      "Traceback (most recent call last):\n",
      "  File \"C:\\Users\\mcecil\\AppData\\Local\\anaconda3\\envs\\IBM_CDL\\lib\\site-packages\\nasa_hls\\hdf2tiff_conversion.py\", line 82, in convert_hdf2tiffs\n",
      "    subprocess.check_call(cmd, shell=True)\n",
      "  File \"C:\\Users\\mcecil\\AppData\\Local\\anaconda3\\envs\\IBM_CDL\\lib\\subprocess.py\", line 369, in check_call\n",
      "    raise CalledProcessError(retcode, cmd)\n",
      "subprocess.CalledProcessError: Command 'gdal_translate HDF4_EOS:EOS_GRID:'C:\\Users\\mcecil\\CGA\\CDL\\hdf\\HLS.S30.T14RNS.2020017.v1.4.hdf':Grid:B07 C:\\Users\\mcecil\\CGA\\CDL\\tif\\HLS.S30.T14RNS.2020017.v1.4\\HLS.S30.T14RNS.2020017.v1.4__Red_Edge3.tif' returned non-zero exit status 1.\n",
      "ERROR DURING CONVERSION WITH CMD: gdal_translate HDF4_EOS:EOS_GRID:'C:\\Users\\mcecil\\CGA\\CDL\\hdf\\HLS.S30.T14RNS.2020017.v1.4.hdf':Grid:B08 C:\\Users\\mcecil\\CGA\\CDL\\tif\\HLS.S30.T14RNS.2020017.v1.4\\HLS.S30.T14RNS.2020017.v1.4__NIR_Broad.tif.\n",
      "Traceback (most recent call last):\n",
      "  File \"C:\\Users\\mcecil\\AppData\\Local\\anaconda3\\envs\\IBM_CDL\\lib\\site-packages\\nasa_hls\\hdf2tiff_conversion.py\", line 82, in convert_hdf2tiffs\n",
      "    subprocess.check_call(cmd, shell=True)\n",
      "  File \"C:\\Users\\mcecil\\AppData\\Local\\anaconda3\\envs\\IBM_CDL\\lib\\subprocess.py\", line 369, in check_call\n",
      "    raise CalledProcessError(retcode, cmd)\n",
      "subprocess.CalledProcessError: Command 'gdal_translate HDF4_EOS:EOS_GRID:'C:\\Users\\mcecil\\CGA\\CDL\\hdf\\HLS.S30.T14RNS.2020017.v1.4.hdf':Grid:B08 C:\\Users\\mcecil\\CGA\\CDL\\tif\\HLS.S30.T14RNS.2020017.v1.4\\HLS.S30.T14RNS.2020017.v1.4__NIR_Broad.tif' returned non-zero exit status 1.\n",
      "ERROR DURING CONVERSION WITH CMD: gdal_translate HDF4_EOS:EOS_GRID:'C:\\Users\\mcecil\\CGA\\CDL\\hdf\\HLS.S30.T14RNS.2020017.v1.4.hdf':Grid:B8A C:\\Users\\mcecil\\CGA\\CDL\\tif\\HLS.S30.T14RNS.2020017.v1.4\\HLS.S30.T14RNS.2020017.v1.4__NIR_Narrow.tif.\n",
      "Traceback (most recent call last):\n",
      "  File \"C:\\Users\\mcecil\\AppData\\Local\\anaconda3\\envs\\IBM_CDL\\lib\\site-packages\\nasa_hls\\hdf2tiff_conversion.py\", line 82, in convert_hdf2tiffs\n",
      "    subprocess.check_call(cmd, shell=True)\n",
      "  File \"C:\\Users\\mcecil\\AppData\\Local\\anaconda3\\envs\\IBM_CDL\\lib\\subprocess.py\", line 369, in check_call\n",
      "    raise CalledProcessError(retcode, cmd)\n",
      "subprocess.CalledProcessError: Command 'gdal_translate HDF4_EOS:EOS_GRID:'C:\\Users\\mcecil\\CGA\\CDL\\hdf\\HLS.S30.T14RNS.2020017.v1.4.hdf':Grid:B8A C:\\Users\\mcecil\\CGA\\CDL\\tif\\HLS.S30.T14RNS.2020017.v1.4\\HLS.S30.T14RNS.2020017.v1.4__NIR_Narrow.tif' returned non-zero exit status 1.\n",
      "ERROR DURING CONVERSION WITH CMD: gdal_translate HDF4_EOS:EOS_GRID:'C:\\Users\\mcecil\\CGA\\CDL\\hdf\\HLS.S30.T14RNS.2020017.v1.4.hdf':Grid:B09 C:\\Users\\mcecil\\CGA\\CDL\\tif\\HLS.S30.T14RNS.2020017.v1.4\\HLS.S30.T14RNS.2020017.v1.4__Water_Vapor.tif.\n",
      "Traceback (most recent call last):\n",
      "  File \"C:\\Users\\mcecil\\AppData\\Local\\anaconda3\\envs\\IBM_CDL\\lib\\site-packages\\nasa_hls\\hdf2tiff_conversion.py\", line 82, in convert_hdf2tiffs\n",
      "    subprocess.check_call(cmd, shell=True)\n",
      "  File \"C:\\Users\\mcecil\\AppData\\Local\\anaconda3\\envs\\IBM_CDL\\lib\\subprocess.py\", line 369, in check_call\n",
      "    raise CalledProcessError(retcode, cmd)\n",
      "subprocess.CalledProcessError: Command 'gdal_translate HDF4_EOS:EOS_GRID:'C:\\Users\\mcecil\\CGA\\CDL\\hdf\\HLS.S30.T14RNS.2020017.v1.4.hdf':Grid:B09 C:\\Users\\mcecil\\CGA\\CDL\\tif\\HLS.S30.T14RNS.2020017.v1.4\\HLS.S30.T14RNS.2020017.v1.4__Water_Vapor.tif' returned non-zero exit status 1.\n",
      "ERROR DURING CONVERSION WITH CMD: gdal_translate HDF4_EOS:EOS_GRID:'C:\\Users\\mcecil\\CGA\\CDL\\hdf\\HLS.S30.T14RNS.2020017.v1.4.hdf':Grid:B10 C:\\Users\\mcecil\\CGA\\CDL\\tif\\HLS.S30.T14RNS.2020017.v1.4\\HLS.S30.T14RNS.2020017.v1.4__Cirrus.tif.\n",
      "Traceback (most recent call last):\n",
      "  File \"C:\\Users\\mcecil\\AppData\\Local\\anaconda3\\envs\\IBM_CDL\\lib\\site-packages\\nasa_hls\\hdf2tiff_conversion.py\", line 82, in convert_hdf2tiffs\n",
      "    subprocess.check_call(cmd, shell=True)\n",
      "  File \"C:\\Users\\mcecil\\AppData\\Local\\anaconda3\\envs\\IBM_CDL\\lib\\subprocess.py\", line 369, in check_call\n",
      "    raise CalledProcessError(retcode, cmd)\n",
      "subprocess.CalledProcessError: Command 'gdal_translate HDF4_EOS:EOS_GRID:'C:\\Users\\mcecil\\CGA\\CDL\\hdf\\HLS.S30.T14RNS.2020017.v1.4.hdf':Grid:B10 C:\\Users\\mcecil\\CGA\\CDL\\tif\\HLS.S30.T14RNS.2020017.v1.4\\HLS.S30.T14RNS.2020017.v1.4__Cirrus.tif' returned non-zero exit status 1.\n",
      "ERROR DURING CONVERSION WITH CMD: gdal_translate HDF4_EOS:EOS_GRID:'C:\\Users\\mcecil\\CGA\\CDL\\hdf\\HLS.S30.T14RNS.2020017.v1.4.hdf':Grid:B11 C:\\Users\\mcecil\\CGA\\CDL\\tif\\HLS.S30.T14RNS.2020017.v1.4\\HLS.S30.T14RNS.2020017.v1.4__SWIR1.tif.\n",
      "Traceback (most recent call last):\n",
      "  File \"C:\\Users\\mcecil\\AppData\\Local\\anaconda3\\envs\\IBM_CDL\\lib\\site-packages\\nasa_hls\\hdf2tiff_conversion.py\", line 82, in convert_hdf2tiffs\n",
      "    subprocess.check_call(cmd, shell=True)\n",
      "  File \"C:\\Users\\mcecil\\AppData\\Local\\anaconda3\\envs\\IBM_CDL\\lib\\subprocess.py\", line 369, in check_call\n",
      "    raise CalledProcessError(retcode, cmd)\n",
      "subprocess.CalledProcessError: Command 'gdal_translate HDF4_EOS:EOS_GRID:'C:\\Users\\mcecil\\CGA\\CDL\\hdf\\HLS.S30.T14RNS.2020017.v1.4.hdf':Grid:B11 C:\\Users\\mcecil\\CGA\\CDL\\tif\\HLS.S30.T14RNS.2020017.v1.4\\HLS.S30.T14RNS.2020017.v1.4__SWIR1.tif' returned non-zero exit status 1.\n",
      "ERROR DURING CONVERSION WITH CMD: gdal_translate HDF4_EOS:EOS_GRID:'C:\\Users\\mcecil\\CGA\\CDL\\hdf\\HLS.S30.T14RNS.2020017.v1.4.hdf':Grid:B12 C:\\Users\\mcecil\\CGA\\CDL\\tif\\HLS.S30.T14RNS.2020017.v1.4\\HLS.S30.T14RNS.2020017.v1.4__SWIR2.tif.\n",
      "Traceback (most recent call last):\n",
      "  File \"C:\\Users\\mcecil\\AppData\\Local\\anaconda3\\envs\\IBM_CDL\\lib\\site-packages\\nasa_hls\\hdf2tiff_conversion.py\", line 82, in convert_hdf2tiffs\n",
      "    subprocess.check_call(cmd, shell=True)\n",
      "  File \"C:\\Users\\mcecil\\AppData\\Local\\anaconda3\\envs\\IBM_CDL\\lib\\subprocess.py\", line 369, in check_call\n",
      "    raise CalledProcessError(retcode, cmd)\n",
      "subprocess.CalledProcessError: Command 'gdal_translate HDF4_EOS:EOS_GRID:'C:\\Users\\mcecil\\CGA\\CDL\\hdf\\HLS.S30.T14RNS.2020017.v1.4.hdf':Grid:B12 C:\\Users\\mcecil\\CGA\\CDL\\tif\\HLS.S30.T14RNS.2020017.v1.4\\HLS.S30.T14RNS.2020017.v1.4__SWIR2.tif' returned non-zero exit status 1.\n",
      "ERROR DURING CONVERSION WITH CMD: gdal_translate HDF4_EOS:EOS_GRID:'C:\\Users\\mcecil\\CGA\\CDL\\hdf\\HLS.S30.T14RNS.2020017.v1.4.hdf':Grid:QA C:\\Users\\mcecil\\CGA\\CDL\\tif\\HLS.S30.T14RNS.2020017.v1.4\\HLS.S30.T14RNS.2020017.v1.4__QA.tif.\n",
      "Traceback (most recent call last):\n",
      "  File \"C:\\Users\\mcecil\\AppData\\Local\\anaconda3\\envs\\IBM_CDL\\lib\\site-packages\\nasa_hls\\hdf2tiff_conversion.py\", line 82, in convert_hdf2tiffs\n",
      "    subprocess.check_call(cmd, shell=True)\n",
      "  File \"C:\\Users\\mcecil\\AppData\\Local\\anaconda3\\envs\\IBM_CDL\\lib\\subprocess.py\", line 369, in check_call\n",
      "    raise CalledProcessError(retcode, cmd)\n",
      "subprocess.CalledProcessError: Command 'gdal_translate HDF4_EOS:EOS_GRID:'C:\\Users\\mcecil\\CGA\\CDL\\hdf\\HLS.S30.T14RNS.2020017.v1.4.hdf':Grid:QA C:\\Users\\mcecil\\CGA\\CDL\\tif\\HLS.S30.T14RNS.2020017.v1.4\\HLS.S30.T14RNS.2020017.v1.4__QA.tif' returned non-zero exit status 1.\n",
      "ERROR DURING CONVERSION WITH CMD: gdal_translate HDF4_EOS:EOS_GRID:'C:\\Users\\mcecil\\CGA\\CDL\\hdf\\HLS.S30.T14RNS.2020020.v1.4.hdf':Grid:B01 C:\\Users\\mcecil\\CGA\\CDL\\tif\\HLS.S30.T14RNS.2020020.v1.4\\HLS.S30.T14RNS.2020020.v1.4__Coastal_Aerosol.tif.\n",
      "Traceback (most recent call last):\n",
      "  File \"C:\\Users\\mcecil\\AppData\\Local\\anaconda3\\envs\\IBM_CDL\\lib\\site-packages\\nasa_hls\\hdf2tiff_conversion.py\", line 82, in convert_hdf2tiffs\n",
      "    subprocess.check_call(cmd, shell=True)\n",
      "  File \"C:\\Users\\mcecil\\AppData\\Local\\anaconda3\\envs\\IBM_CDL\\lib\\subprocess.py\", line 369, in check_call\n",
      "    raise CalledProcessError(retcode, cmd)\n",
      "subprocess.CalledProcessError: Command 'gdal_translate HDF4_EOS:EOS_GRID:'C:\\Users\\mcecil\\CGA\\CDL\\hdf\\HLS.S30.T14RNS.2020020.v1.4.hdf':Grid:B01 C:\\Users\\mcecil\\CGA\\CDL\\tif\\HLS.S30.T14RNS.2020020.v1.4\\HLS.S30.T14RNS.2020020.v1.4__Coastal_Aerosol.tif' returned non-zero exit status 1.\n",
      "ERROR DURING CONVERSION WITH CMD: gdal_translate HDF4_EOS:EOS_GRID:'C:\\Users\\mcecil\\CGA\\CDL\\hdf\\HLS.S30.T14RNS.2020020.v1.4.hdf':Grid:B02 C:\\Users\\mcecil\\CGA\\CDL\\tif\\HLS.S30.T14RNS.2020020.v1.4\\HLS.S30.T14RNS.2020020.v1.4__Blue.tif.\n",
      "Traceback (most recent call last):\n",
      "  File \"C:\\Users\\mcecil\\AppData\\Local\\anaconda3\\envs\\IBM_CDL\\lib\\site-packages\\nasa_hls\\hdf2tiff_conversion.py\", line 82, in convert_hdf2tiffs\n",
      "    subprocess.check_call(cmd, shell=True)\n",
      "  File \"C:\\Users\\mcecil\\AppData\\Local\\anaconda3\\envs\\IBM_CDL\\lib\\subprocess.py\", line 369, in check_call\n",
      "    raise CalledProcessError(retcode, cmd)\n",
      "subprocess.CalledProcessError: Command 'gdal_translate HDF4_EOS:EOS_GRID:'C:\\Users\\mcecil\\CGA\\CDL\\hdf\\HLS.S30.T14RNS.2020020.v1.4.hdf':Grid:B02 C:\\Users\\mcecil\\CGA\\CDL\\tif\\HLS.S30.T14RNS.2020020.v1.4\\HLS.S30.T14RNS.2020020.v1.4__Blue.tif' returned non-zero exit status 1.\n",
      "ERROR DURING CONVERSION WITH CMD: gdal_translate HDF4_EOS:EOS_GRID:'C:\\Users\\mcecil\\CGA\\CDL\\hdf\\HLS.S30.T14RNS.2020020.v1.4.hdf':Grid:B03 C:\\Users\\mcecil\\CGA\\CDL\\tif\\HLS.S30.T14RNS.2020020.v1.4\\HLS.S30.T14RNS.2020020.v1.4__Green.tif.\n",
      "Traceback (most recent call last):\n",
      "  File \"C:\\Users\\mcecil\\AppData\\Local\\anaconda3\\envs\\IBM_CDL\\lib\\site-packages\\nasa_hls\\hdf2tiff_conversion.py\", line 82, in convert_hdf2tiffs\n",
      "    subprocess.check_call(cmd, shell=True)\n",
      "  File \"C:\\Users\\mcecil\\AppData\\Local\\anaconda3\\envs\\IBM_CDL\\lib\\subprocess.py\", line 369, in check_call\n",
      "    raise CalledProcessError(retcode, cmd)\n",
      "subprocess.CalledProcessError: Command 'gdal_translate HDF4_EOS:EOS_GRID:'C:\\Users\\mcecil\\CGA\\CDL\\hdf\\HLS.S30.T14RNS.2020020.v1.4.hdf':Grid:B03 C:\\Users\\mcecil\\CGA\\CDL\\tif\\HLS.S30.T14RNS.2020020.v1.4\\HLS.S30.T14RNS.2020020.v1.4__Green.tif' returned non-zero exit status 1.\n",
      "ERROR DURING CONVERSION WITH CMD: gdal_translate HDF4_EOS:EOS_GRID:'C:\\Users\\mcecil\\CGA\\CDL\\hdf\\HLS.S30.T14RNS.2020020.v1.4.hdf':Grid:B04 C:\\Users\\mcecil\\CGA\\CDL\\tif\\HLS.S30.T14RNS.2020020.v1.4\\HLS.S30.T14RNS.2020020.v1.4__Red.tif.\n",
      "Traceback (most recent call last):\n",
      "  File \"C:\\Users\\mcecil\\AppData\\Local\\anaconda3\\envs\\IBM_CDL\\lib\\site-packages\\nasa_hls\\hdf2tiff_conversion.py\", line 82, in convert_hdf2tiffs\n",
      "    subprocess.check_call(cmd, shell=True)\n",
      "  File \"C:\\Users\\mcecil\\AppData\\Local\\anaconda3\\envs\\IBM_CDL\\lib\\subprocess.py\", line 369, in check_call\n",
      "    raise CalledProcessError(retcode, cmd)\n",
      "subprocess.CalledProcessError: Command 'gdal_translate HDF4_EOS:EOS_GRID:'C:\\Users\\mcecil\\CGA\\CDL\\hdf\\HLS.S30.T14RNS.2020020.v1.4.hdf':Grid:B04 C:\\Users\\mcecil\\CGA\\CDL\\tif\\HLS.S30.T14RNS.2020020.v1.4\\HLS.S30.T14RNS.2020020.v1.4__Red.tif' returned non-zero exit status 1.\n",
      "ERROR DURING CONVERSION WITH CMD: gdal_translate HDF4_EOS:EOS_GRID:'C:\\Users\\mcecil\\CGA\\CDL\\hdf\\HLS.S30.T14RNS.2020020.v1.4.hdf':Grid:B05 C:\\Users\\mcecil\\CGA\\CDL\\tif\\HLS.S30.T14RNS.2020020.v1.4\\HLS.S30.T14RNS.2020020.v1.4__Red_Edge1.tif.\n",
      "Traceback (most recent call last):\n",
      "  File \"C:\\Users\\mcecil\\AppData\\Local\\anaconda3\\envs\\IBM_CDL\\lib\\site-packages\\nasa_hls\\hdf2tiff_conversion.py\", line 82, in convert_hdf2tiffs\n",
      "    subprocess.check_call(cmd, shell=True)\n",
      "  File \"C:\\Users\\mcecil\\AppData\\Local\\anaconda3\\envs\\IBM_CDL\\lib\\subprocess.py\", line 369, in check_call\n",
      "    raise CalledProcessError(retcode, cmd)\n",
      "subprocess.CalledProcessError: Command 'gdal_translate HDF4_EOS:EOS_GRID:'C:\\Users\\mcecil\\CGA\\CDL\\hdf\\HLS.S30.T14RNS.2020020.v1.4.hdf':Grid:B05 C:\\Users\\mcecil\\CGA\\CDL\\tif\\HLS.S30.T14RNS.2020020.v1.4\\HLS.S30.T14RNS.2020020.v1.4__Red_Edge1.tif' returned non-zero exit status 1.\n",
      "ERROR DURING CONVERSION WITH CMD: gdal_translate HDF4_EOS:EOS_GRID:'C:\\Users\\mcecil\\CGA\\CDL\\hdf\\HLS.S30.T14RNS.2020020.v1.4.hdf':Grid:B06 C:\\Users\\mcecil\\CGA\\CDL\\tif\\HLS.S30.T14RNS.2020020.v1.4\\HLS.S30.T14RNS.2020020.v1.4__Red_Edge2.tif.\n",
      "Traceback (most recent call last):\n",
      "  File \"C:\\Users\\mcecil\\AppData\\Local\\anaconda3\\envs\\IBM_CDL\\lib\\site-packages\\nasa_hls\\hdf2tiff_conversion.py\", line 82, in convert_hdf2tiffs\n",
      "    subprocess.check_call(cmd, shell=True)\n",
      "  File \"C:\\Users\\mcecil\\AppData\\Local\\anaconda3\\envs\\IBM_CDL\\lib\\subprocess.py\", line 369, in check_call\n",
      "    raise CalledProcessError(retcode, cmd)\n",
      "subprocess.CalledProcessError: Command 'gdal_translate HDF4_EOS:EOS_GRID:'C:\\Users\\mcecil\\CGA\\CDL\\hdf\\HLS.S30.T14RNS.2020020.v1.4.hdf':Grid:B06 C:\\Users\\mcecil\\CGA\\CDL\\tif\\HLS.S30.T14RNS.2020020.v1.4\\HLS.S30.T14RNS.2020020.v1.4__Red_Edge2.tif' returned non-zero exit status 1.\n",
      "ERROR DURING CONVERSION WITH CMD: gdal_translate HDF4_EOS:EOS_GRID:'C:\\Users\\mcecil\\CGA\\CDL\\hdf\\HLS.S30.T14RNS.2020020.v1.4.hdf':Grid:B07 C:\\Users\\mcecil\\CGA\\CDL\\tif\\HLS.S30.T14RNS.2020020.v1.4\\HLS.S30.T14RNS.2020020.v1.4__Red_Edge3.tif.\n",
      "Traceback (most recent call last):\n",
      "  File \"C:\\Users\\mcecil\\AppData\\Local\\anaconda3\\envs\\IBM_CDL\\lib\\site-packages\\nasa_hls\\hdf2tiff_conversion.py\", line 82, in convert_hdf2tiffs\n",
      "    subprocess.check_call(cmd, shell=True)\n",
      "  File \"C:\\Users\\mcecil\\AppData\\Local\\anaconda3\\envs\\IBM_CDL\\lib\\subprocess.py\", line 369, in check_call\n",
      "    raise CalledProcessError(retcode, cmd)\n",
      "subprocess.CalledProcessError: Command 'gdal_translate HDF4_EOS:EOS_GRID:'C:\\Users\\mcecil\\CGA\\CDL\\hdf\\HLS.S30.T14RNS.2020020.v1.4.hdf':Grid:B07 C:\\Users\\mcecil\\CGA\\CDL\\tif\\HLS.S30.T14RNS.2020020.v1.4\\HLS.S30.T14RNS.2020020.v1.4__Red_Edge3.tif' returned non-zero exit status 1.\n",
      "ERROR DURING CONVERSION WITH CMD: gdal_translate HDF4_EOS:EOS_GRID:'C:\\Users\\mcecil\\CGA\\CDL\\hdf\\HLS.S30.T14RNS.2020020.v1.4.hdf':Grid:B08 C:\\Users\\mcecil\\CGA\\CDL\\tif\\HLS.S30.T14RNS.2020020.v1.4\\HLS.S30.T14RNS.2020020.v1.4__NIR_Broad.tif.\n",
      "Traceback (most recent call last):\n",
      "  File \"C:\\Users\\mcecil\\AppData\\Local\\anaconda3\\envs\\IBM_CDL\\lib\\site-packages\\nasa_hls\\hdf2tiff_conversion.py\", line 82, in convert_hdf2tiffs\n",
      "    subprocess.check_call(cmd, shell=True)\n",
      "  File \"C:\\Users\\mcecil\\AppData\\Local\\anaconda3\\envs\\IBM_CDL\\lib\\subprocess.py\", line 369, in check_call\n",
      "    raise CalledProcessError(retcode, cmd)\n",
      "subprocess.CalledProcessError: Command 'gdal_translate HDF4_EOS:EOS_GRID:'C:\\Users\\mcecil\\CGA\\CDL\\hdf\\HLS.S30.T14RNS.2020020.v1.4.hdf':Grid:B08 C:\\Users\\mcecil\\CGA\\CDL\\tif\\HLS.S30.T14RNS.2020020.v1.4\\HLS.S30.T14RNS.2020020.v1.4__NIR_Broad.tif' returned non-zero exit status 1.\n",
      "ERROR DURING CONVERSION WITH CMD: gdal_translate HDF4_EOS:EOS_GRID:'C:\\Users\\mcecil\\CGA\\CDL\\hdf\\HLS.S30.T14RNS.2020020.v1.4.hdf':Grid:B8A C:\\Users\\mcecil\\CGA\\CDL\\tif\\HLS.S30.T14RNS.2020020.v1.4\\HLS.S30.T14RNS.2020020.v1.4__NIR_Narrow.tif.\n",
      "Traceback (most recent call last):\n",
      "  File \"C:\\Users\\mcecil\\AppData\\Local\\anaconda3\\envs\\IBM_CDL\\lib\\site-packages\\nasa_hls\\hdf2tiff_conversion.py\", line 82, in convert_hdf2tiffs\n",
      "    subprocess.check_call(cmd, shell=True)\n",
      "  File \"C:\\Users\\mcecil\\AppData\\Local\\anaconda3\\envs\\IBM_CDL\\lib\\subprocess.py\", line 369, in check_call\n",
      "    raise CalledProcessError(retcode, cmd)\n",
      "subprocess.CalledProcessError: Command 'gdal_translate HDF4_EOS:EOS_GRID:'C:\\Users\\mcecil\\CGA\\CDL\\hdf\\HLS.S30.T14RNS.2020020.v1.4.hdf':Grid:B8A C:\\Users\\mcecil\\CGA\\CDL\\tif\\HLS.S30.T14RNS.2020020.v1.4\\HLS.S30.T14RNS.2020020.v1.4__NIR_Narrow.tif' returned non-zero exit status 1.\n",
      "ERROR DURING CONVERSION WITH CMD: gdal_translate HDF4_EOS:EOS_GRID:'C:\\Users\\mcecil\\CGA\\CDL\\hdf\\HLS.S30.T14RNS.2020020.v1.4.hdf':Grid:B09 C:\\Users\\mcecil\\CGA\\CDL\\tif\\HLS.S30.T14RNS.2020020.v1.4\\HLS.S30.T14RNS.2020020.v1.4__Water_Vapor.tif.\n",
      "Traceback (most recent call last):\n",
      "  File \"C:\\Users\\mcecil\\AppData\\Local\\anaconda3\\envs\\IBM_CDL\\lib\\site-packages\\nasa_hls\\hdf2tiff_conversion.py\", line 82, in convert_hdf2tiffs\n",
      "    subprocess.check_call(cmd, shell=True)\n",
      "  File \"C:\\Users\\mcecil\\AppData\\Local\\anaconda3\\envs\\IBM_CDL\\lib\\subprocess.py\", line 369, in check_call\n",
      "    raise CalledProcessError(retcode, cmd)\n",
      "subprocess.CalledProcessError: Command 'gdal_translate HDF4_EOS:EOS_GRID:'C:\\Users\\mcecil\\CGA\\CDL\\hdf\\HLS.S30.T14RNS.2020020.v1.4.hdf':Grid:B09 C:\\Users\\mcecil\\CGA\\CDL\\tif\\HLS.S30.T14RNS.2020020.v1.4\\HLS.S30.T14RNS.2020020.v1.4__Water_Vapor.tif' returned non-zero exit status 1.\n",
      "ERROR DURING CONVERSION WITH CMD: gdal_translate HDF4_EOS:EOS_GRID:'C:\\Users\\mcecil\\CGA\\CDL\\hdf\\HLS.S30.T14RNS.2020020.v1.4.hdf':Grid:B10 C:\\Users\\mcecil\\CGA\\CDL\\tif\\HLS.S30.T14RNS.2020020.v1.4\\HLS.S30.T14RNS.2020020.v1.4__Cirrus.tif.\n",
      "Traceback (most recent call last):\n",
      "  File \"C:\\Users\\mcecil\\AppData\\Local\\anaconda3\\envs\\IBM_CDL\\lib\\site-packages\\nasa_hls\\hdf2tiff_conversion.py\", line 82, in convert_hdf2tiffs\n",
      "    subprocess.check_call(cmd, shell=True)\n",
      "  File \"C:\\Users\\mcecil\\AppData\\Local\\anaconda3\\envs\\IBM_CDL\\lib\\subprocess.py\", line 369, in check_call\n",
      "    raise CalledProcessError(retcode, cmd)\n",
      "subprocess.CalledProcessError: Command 'gdal_translate HDF4_EOS:EOS_GRID:'C:\\Users\\mcecil\\CGA\\CDL\\hdf\\HLS.S30.T14RNS.2020020.v1.4.hdf':Grid:B10 C:\\Users\\mcecil\\CGA\\CDL\\tif\\HLS.S30.T14RNS.2020020.v1.4\\HLS.S30.T14RNS.2020020.v1.4__Cirrus.tif' returned non-zero exit status 1.\n",
      "ERROR DURING CONVERSION WITH CMD: gdal_translate HDF4_EOS:EOS_GRID:'C:\\Users\\mcecil\\CGA\\CDL\\hdf\\HLS.S30.T14RNS.2020020.v1.4.hdf':Grid:B11 C:\\Users\\mcecil\\CGA\\CDL\\tif\\HLS.S30.T14RNS.2020020.v1.4\\HLS.S30.T14RNS.2020020.v1.4__SWIR1.tif.\n",
      "Traceback (most recent call last):\n",
      "  File \"C:\\Users\\mcecil\\AppData\\Local\\anaconda3\\envs\\IBM_CDL\\lib\\site-packages\\nasa_hls\\hdf2tiff_conversion.py\", line 82, in convert_hdf2tiffs\n",
      "    subprocess.check_call(cmd, shell=True)\n",
      "  File \"C:\\Users\\mcecil\\AppData\\Local\\anaconda3\\envs\\IBM_CDL\\lib\\subprocess.py\", line 369, in check_call\n",
      "    raise CalledProcessError(retcode, cmd)\n",
      "subprocess.CalledProcessError: Command 'gdal_translate HDF4_EOS:EOS_GRID:'C:\\Users\\mcecil\\CGA\\CDL\\hdf\\HLS.S30.T14RNS.2020020.v1.4.hdf':Grid:B11 C:\\Users\\mcecil\\CGA\\CDL\\tif\\HLS.S30.T14RNS.2020020.v1.4\\HLS.S30.T14RNS.2020020.v1.4__SWIR1.tif' returned non-zero exit status 1.\n",
      "ERROR DURING CONVERSION WITH CMD: gdal_translate HDF4_EOS:EOS_GRID:'C:\\Users\\mcecil\\CGA\\CDL\\hdf\\HLS.S30.T14RNS.2020020.v1.4.hdf':Grid:B12 C:\\Users\\mcecil\\CGA\\CDL\\tif\\HLS.S30.T14RNS.2020020.v1.4\\HLS.S30.T14RNS.2020020.v1.4__SWIR2.tif.\n",
      "Traceback (most recent call last):\n",
      "  File \"C:\\Users\\mcecil\\AppData\\Local\\anaconda3\\envs\\IBM_CDL\\lib\\site-packages\\nasa_hls\\hdf2tiff_conversion.py\", line 82, in convert_hdf2tiffs\n",
      "    subprocess.check_call(cmd, shell=True)\n",
      "  File \"C:\\Users\\mcecil\\AppData\\Local\\anaconda3\\envs\\IBM_CDL\\lib\\subprocess.py\", line 369, in check_call\n",
      "    raise CalledProcessError(retcode, cmd)\n",
      "subprocess.CalledProcessError: Command 'gdal_translate HDF4_EOS:EOS_GRID:'C:\\Users\\mcecil\\CGA\\CDL\\hdf\\HLS.S30.T14RNS.2020020.v1.4.hdf':Grid:B12 C:\\Users\\mcecil\\CGA\\CDL\\tif\\HLS.S30.T14RNS.2020020.v1.4\\HLS.S30.T14RNS.2020020.v1.4__SWIR2.tif' returned non-zero exit status 1.\n",
      "ERROR DURING CONVERSION WITH CMD: gdal_translate HDF4_EOS:EOS_GRID:'C:\\Users\\mcecil\\CGA\\CDL\\hdf\\HLS.S30.T14RNS.2020020.v1.4.hdf':Grid:QA C:\\Users\\mcecil\\CGA\\CDL\\tif\\HLS.S30.T14RNS.2020020.v1.4\\HLS.S30.T14RNS.2020020.v1.4__QA.tif.\n",
      "Traceback (most recent call last):\n",
      "  File \"C:\\Users\\mcecil\\AppData\\Local\\anaconda3\\envs\\IBM_CDL\\lib\\site-packages\\nasa_hls\\hdf2tiff_conversion.py\", line 82, in convert_hdf2tiffs\n",
      "    subprocess.check_call(cmd, shell=True)\n",
      "  File \"C:\\Users\\mcecil\\AppData\\Local\\anaconda3\\envs\\IBM_CDL\\lib\\subprocess.py\", line 369, in check_call\n",
      "    raise CalledProcessError(retcode, cmd)\n",
      "subprocess.CalledProcessError: Command 'gdal_translate HDF4_EOS:EOS_GRID:'C:\\Users\\mcecil\\CGA\\CDL\\hdf\\HLS.S30.T14RNS.2020020.v1.4.hdf':Grid:QA C:\\Users\\mcecil\\CGA\\CDL\\tif\\HLS.S30.T14RNS.2020020.v1.4\\HLS.S30.T14RNS.2020020.v1.4__QA.tif' returned non-zero exit status 1.\n",
      "ERROR DURING CONVERSION WITH CMD: gdal_translate HDF4_EOS:EOS_GRID:'C:\\Users\\mcecil\\CGA\\CDL\\hdf\\HLS.S30.T14RNS.2020022.v1.4.hdf':Grid:B01 C:\\Users\\mcecil\\CGA\\CDL\\tif\\HLS.S30.T14RNS.2020022.v1.4\\HLS.S30.T14RNS.2020022.v1.4__Coastal_Aerosol.tif.\n",
      "Traceback (most recent call last):\n",
      "  File \"C:\\Users\\mcecil\\AppData\\Local\\anaconda3\\envs\\IBM_CDL\\lib\\site-packages\\nasa_hls\\hdf2tiff_conversion.py\", line 82, in convert_hdf2tiffs\n",
      "    subprocess.check_call(cmd, shell=True)\n",
      "  File \"C:\\Users\\mcecil\\AppData\\Local\\anaconda3\\envs\\IBM_CDL\\lib\\subprocess.py\", line 369, in check_call\n",
      "    raise CalledProcessError(retcode, cmd)\n",
      "subprocess.CalledProcessError: Command 'gdal_translate HDF4_EOS:EOS_GRID:'C:\\Users\\mcecil\\CGA\\CDL\\hdf\\HLS.S30.T14RNS.2020022.v1.4.hdf':Grid:B01 C:\\Users\\mcecil\\CGA\\CDL\\tif\\HLS.S30.T14RNS.2020022.v1.4\\HLS.S30.T14RNS.2020022.v1.4__Coastal_Aerosol.tif' returned non-zero exit status 1.\n",
      "ERROR DURING CONVERSION WITH CMD: gdal_translate HDF4_EOS:EOS_GRID:'C:\\Users\\mcecil\\CGA\\CDL\\hdf\\HLS.S30.T14RNS.2020022.v1.4.hdf':Grid:B02 C:\\Users\\mcecil\\CGA\\CDL\\tif\\HLS.S30.T14RNS.2020022.v1.4\\HLS.S30.T14RNS.2020022.v1.4__Blue.tif.\n",
      "Traceback (most recent call last):\n",
      "  File \"C:\\Users\\mcecil\\AppData\\Local\\anaconda3\\envs\\IBM_CDL\\lib\\site-packages\\nasa_hls\\hdf2tiff_conversion.py\", line 82, in convert_hdf2tiffs\n",
      "    subprocess.check_call(cmd, shell=True)\n",
      "  File \"C:\\Users\\mcecil\\AppData\\Local\\anaconda3\\envs\\IBM_CDL\\lib\\subprocess.py\", line 369, in check_call\n",
      "    raise CalledProcessError(retcode, cmd)\n",
      "subprocess.CalledProcessError: Command 'gdal_translate HDF4_EOS:EOS_GRID:'C:\\Users\\mcecil\\CGA\\CDL\\hdf\\HLS.S30.T14RNS.2020022.v1.4.hdf':Grid:B02 C:\\Users\\mcecil\\CGA\\CDL\\tif\\HLS.S30.T14RNS.2020022.v1.4\\HLS.S30.T14RNS.2020022.v1.4__Blue.tif' returned non-zero exit status 1.\n",
      "ERROR DURING CONVERSION WITH CMD: gdal_translate HDF4_EOS:EOS_GRID:'C:\\Users\\mcecil\\CGA\\CDL\\hdf\\HLS.S30.T14RNS.2020022.v1.4.hdf':Grid:B03 C:\\Users\\mcecil\\CGA\\CDL\\tif\\HLS.S30.T14RNS.2020022.v1.4\\HLS.S30.T14RNS.2020022.v1.4__Green.tif.\n",
      "Traceback (most recent call last):\n",
      "  File \"C:\\Users\\mcecil\\AppData\\Local\\anaconda3\\envs\\IBM_CDL\\lib\\site-packages\\nasa_hls\\hdf2tiff_conversion.py\", line 82, in convert_hdf2tiffs\n",
      "    subprocess.check_call(cmd, shell=True)\n",
      "  File \"C:\\Users\\mcecil\\AppData\\Local\\anaconda3\\envs\\IBM_CDL\\lib\\subprocess.py\", line 369, in check_call\n",
      "    raise CalledProcessError(retcode, cmd)\n",
      "subprocess.CalledProcessError: Command 'gdal_translate HDF4_EOS:EOS_GRID:'C:\\Users\\mcecil\\CGA\\CDL\\hdf\\HLS.S30.T14RNS.2020022.v1.4.hdf':Grid:B03 C:\\Users\\mcecil\\CGA\\CDL\\tif\\HLS.S30.T14RNS.2020022.v1.4\\HLS.S30.T14RNS.2020022.v1.4__Green.tif' returned non-zero exit status 1.\n",
      "ERROR DURING CONVERSION WITH CMD: gdal_translate HDF4_EOS:EOS_GRID:'C:\\Users\\mcecil\\CGA\\CDL\\hdf\\HLS.S30.T14RNS.2020022.v1.4.hdf':Grid:B04 C:\\Users\\mcecil\\CGA\\CDL\\tif\\HLS.S30.T14RNS.2020022.v1.4\\HLS.S30.T14RNS.2020022.v1.4__Red.tif.\n",
      "Traceback (most recent call last):\n",
      "  File \"C:\\Users\\mcecil\\AppData\\Local\\anaconda3\\envs\\IBM_CDL\\lib\\site-packages\\nasa_hls\\hdf2tiff_conversion.py\", line 82, in convert_hdf2tiffs\n",
      "    subprocess.check_call(cmd, shell=True)\n",
      "  File \"C:\\Users\\mcecil\\AppData\\Local\\anaconda3\\envs\\IBM_CDL\\lib\\subprocess.py\", line 369, in check_call\n",
      "    raise CalledProcessError(retcode, cmd)\n",
      "subprocess.CalledProcessError: Command 'gdal_translate HDF4_EOS:EOS_GRID:'C:\\Users\\mcecil\\CGA\\CDL\\hdf\\HLS.S30.T14RNS.2020022.v1.4.hdf':Grid:B04 C:\\Users\\mcecil\\CGA\\CDL\\tif\\HLS.S30.T14RNS.2020022.v1.4\\HLS.S30.T14RNS.2020022.v1.4__Red.tif' returned non-zero exit status 1.\n",
      "ERROR DURING CONVERSION WITH CMD: gdal_translate HDF4_EOS:EOS_GRID:'C:\\Users\\mcecil\\CGA\\CDL\\hdf\\HLS.S30.T14RNS.2020022.v1.4.hdf':Grid:B05 C:\\Users\\mcecil\\CGA\\CDL\\tif\\HLS.S30.T14RNS.2020022.v1.4\\HLS.S30.T14RNS.2020022.v1.4__Red_Edge1.tif.\n",
      "Traceback (most recent call last):\n",
      "  File \"C:\\Users\\mcecil\\AppData\\Local\\anaconda3\\envs\\IBM_CDL\\lib\\site-packages\\nasa_hls\\hdf2tiff_conversion.py\", line 82, in convert_hdf2tiffs\n",
      "    subprocess.check_call(cmd, shell=True)\n",
      "  File \"C:\\Users\\mcecil\\AppData\\Local\\anaconda3\\envs\\IBM_CDL\\lib\\subprocess.py\", line 369, in check_call\n",
      "    raise CalledProcessError(retcode, cmd)\n",
      "subprocess.CalledProcessError: Command 'gdal_translate HDF4_EOS:EOS_GRID:'C:\\Users\\mcecil\\CGA\\CDL\\hdf\\HLS.S30.T14RNS.2020022.v1.4.hdf':Grid:B05 C:\\Users\\mcecil\\CGA\\CDL\\tif\\HLS.S30.T14RNS.2020022.v1.4\\HLS.S30.T14RNS.2020022.v1.4__Red_Edge1.tif' returned non-zero exit status 1.\n",
      "ERROR DURING CONVERSION WITH CMD: gdal_translate HDF4_EOS:EOS_GRID:'C:\\Users\\mcecil\\CGA\\CDL\\hdf\\HLS.S30.T14RNS.2020022.v1.4.hdf':Grid:B06 C:\\Users\\mcecil\\CGA\\CDL\\tif\\HLS.S30.T14RNS.2020022.v1.4\\HLS.S30.T14RNS.2020022.v1.4__Red_Edge2.tif.\n",
      "Traceback (most recent call last):\n",
      "  File \"C:\\Users\\mcecil\\AppData\\Local\\anaconda3\\envs\\IBM_CDL\\lib\\site-packages\\nasa_hls\\hdf2tiff_conversion.py\", line 82, in convert_hdf2tiffs\n",
      "    subprocess.check_call(cmd, shell=True)\n",
      "  File \"C:\\Users\\mcecil\\AppData\\Local\\anaconda3\\envs\\IBM_CDL\\lib\\subprocess.py\", line 369, in check_call\n",
      "    raise CalledProcessError(retcode, cmd)\n",
      "subprocess.CalledProcessError: Command 'gdal_translate HDF4_EOS:EOS_GRID:'C:\\Users\\mcecil\\CGA\\CDL\\hdf\\HLS.S30.T14RNS.2020022.v1.4.hdf':Grid:B06 C:\\Users\\mcecil\\CGA\\CDL\\tif\\HLS.S30.T14RNS.2020022.v1.4\\HLS.S30.T14RNS.2020022.v1.4__Red_Edge2.tif' returned non-zero exit status 1.\n",
      "ERROR DURING CONVERSION WITH CMD: gdal_translate HDF4_EOS:EOS_GRID:'C:\\Users\\mcecil\\CGA\\CDL\\hdf\\HLS.S30.T14RNS.2020022.v1.4.hdf':Grid:B07 C:\\Users\\mcecil\\CGA\\CDL\\tif\\HLS.S30.T14RNS.2020022.v1.4\\HLS.S30.T14RNS.2020022.v1.4__Red_Edge3.tif.\n",
      "Traceback (most recent call last):\n",
      "  File \"C:\\Users\\mcecil\\AppData\\Local\\anaconda3\\envs\\IBM_CDL\\lib\\site-packages\\nasa_hls\\hdf2tiff_conversion.py\", line 82, in convert_hdf2tiffs\n",
      "    subprocess.check_call(cmd, shell=True)\n",
      "  File \"C:\\Users\\mcecil\\AppData\\Local\\anaconda3\\envs\\IBM_CDL\\lib\\subprocess.py\", line 369, in check_call\n",
      "    raise CalledProcessError(retcode, cmd)\n",
      "subprocess.CalledProcessError: Command 'gdal_translate HDF4_EOS:EOS_GRID:'C:\\Users\\mcecil\\CGA\\CDL\\hdf\\HLS.S30.T14RNS.2020022.v1.4.hdf':Grid:B07 C:\\Users\\mcecil\\CGA\\CDL\\tif\\HLS.S30.T14RNS.2020022.v1.4\\HLS.S30.T14RNS.2020022.v1.4__Red_Edge3.tif' returned non-zero exit status 1.\n",
      "ERROR DURING CONVERSION WITH CMD: gdal_translate HDF4_EOS:EOS_GRID:'C:\\Users\\mcecil\\CGA\\CDL\\hdf\\HLS.S30.T14RNS.2020022.v1.4.hdf':Grid:B08 C:\\Users\\mcecil\\CGA\\CDL\\tif\\HLS.S30.T14RNS.2020022.v1.4\\HLS.S30.T14RNS.2020022.v1.4__NIR_Broad.tif.\n",
      "Traceback (most recent call last):\n",
      "  File \"C:\\Users\\mcecil\\AppData\\Local\\anaconda3\\envs\\IBM_CDL\\lib\\site-packages\\nasa_hls\\hdf2tiff_conversion.py\", line 82, in convert_hdf2tiffs\n",
      "    subprocess.check_call(cmd, shell=True)\n",
      "  File \"C:\\Users\\mcecil\\AppData\\Local\\anaconda3\\envs\\IBM_CDL\\lib\\subprocess.py\", line 369, in check_call\n",
      "    raise CalledProcessError(retcode, cmd)\n",
      "subprocess.CalledProcessError: Command 'gdal_translate HDF4_EOS:EOS_GRID:'C:\\Users\\mcecil\\CGA\\CDL\\hdf\\HLS.S30.T14RNS.2020022.v1.4.hdf':Grid:B08 C:\\Users\\mcecil\\CGA\\CDL\\tif\\HLS.S30.T14RNS.2020022.v1.4\\HLS.S30.T14RNS.2020022.v1.4__NIR_Broad.tif' returned non-zero exit status 1.\n",
      "ERROR DURING CONVERSION WITH CMD: gdal_translate HDF4_EOS:EOS_GRID:'C:\\Users\\mcecil\\CGA\\CDL\\hdf\\HLS.S30.T14RNS.2020022.v1.4.hdf':Grid:B8A C:\\Users\\mcecil\\CGA\\CDL\\tif\\HLS.S30.T14RNS.2020022.v1.4\\HLS.S30.T14RNS.2020022.v1.4__NIR_Narrow.tif.\n",
      "Traceback (most recent call last):\n",
      "  File \"C:\\Users\\mcecil\\AppData\\Local\\anaconda3\\envs\\IBM_CDL\\lib\\site-packages\\nasa_hls\\hdf2tiff_conversion.py\", line 82, in convert_hdf2tiffs\n",
      "    subprocess.check_call(cmd, shell=True)\n",
      "  File \"C:\\Users\\mcecil\\AppData\\Local\\anaconda3\\envs\\IBM_CDL\\lib\\subprocess.py\", line 369, in check_call\n",
      "    raise CalledProcessError(retcode, cmd)\n",
      "subprocess.CalledProcessError: Command 'gdal_translate HDF4_EOS:EOS_GRID:'C:\\Users\\mcecil\\CGA\\CDL\\hdf\\HLS.S30.T14RNS.2020022.v1.4.hdf':Grid:B8A C:\\Users\\mcecil\\CGA\\CDL\\tif\\HLS.S30.T14RNS.2020022.v1.4\\HLS.S30.T14RNS.2020022.v1.4__NIR_Narrow.tif' returned non-zero exit status 1.\n",
      "ERROR DURING CONVERSION WITH CMD: gdal_translate HDF4_EOS:EOS_GRID:'C:\\Users\\mcecil\\CGA\\CDL\\hdf\\HLS.S30.T14RNS.2020022.v1.4.hdf':Grid:B09 C:\\Users\\mcecil\\CGA\\CDL\\tif\\HLS.S30.T14RNS.2020022.v1.4\\HLS.S30.T14RNS.2020022.v1.4__Water_Vapor.tif.\n",
      "Traceback (most recent call last):\n",
      "  File \"C:\\Users\\mcecil\\AppData\\Local\\anaconda3\\envs\\IBM_CDL\\lib\\site-packages\\nasa_hls\\hdf2tiff_conversion.py\", line 82, in convert_hdf2tiffs\n",
      "    subprocess.check_call(cmd, shell=True)\n",
      "  File \"C:\\Users\\mcecil\\AppData\\Local\\anaconda3\\envs\\IBM_CDL\\lib\\subprocess.py\", line 369, in check_call\n",
      "    raise CalledProcessError(retcode, cmd)\n",
      "subprocess.CalledProcessError: Command 'gdal_translate HDF4_EOS:EOS_GRID:'C:\\Users\\mcecil\\CGA\\CDL\\hdf\\HLS.S30.T14RNS.2020022.v1.4.hdf':Grid:B09 C:\\Users\\mcecil\\CGA\\CDL\\tif\\HLS.S30.T14RNS.2020022.v1.4\\HLS.S30.T14RNS.2020022.v1.4__Water_Vapor.tif' returned non-zero exit status 1.\n",
      "ERROR DURING CONVERSION WITH CMD: gdal_translate HDF4_EOS:EOS_GRID:'C:\\Users\\mcecil\\CGA\\CDL\\hdf\\HLS.S30.T14RNS.2020022.v1.4.hdf':Grid:B10 C:\\Users\\mcecil\\CGA\\CDL\\tif\\HLS.S30.T14RNS.2020022.v1.4\\HLS.S30.T14RNS.2020022.v1.4__Cirrus.tif.\n",
      "Traceback (most recent call last):\n",
      "  File \"C:\\Users\\mcecil\\AppData\\Local\\anaconda3\\envs\\IBM_CDL\\lib\\site-packages\\nasa_hls\\hdf2tiff_conversion.py\", line 82, in convert_hdf2tiffs\n",
      "    subprocess.check_call(cmd, shell=True)\n",
      "  File \"C:\\Users\\mcecil\\AppData\\Local\\anaconda3\\envs\\IBM_CDL\\lib\\subprocess.py\", line 369, in check_call\n",
      "    raise CalledProcessError(retcode, cmd)\n",
      "subprocess.CalledProcessError: Command 'gdal_translate HDF4_EOS:EOS_GRID:'C:\\Users\\mcecil\\CGA\\CDL\\hdf\\HLS.S30.T14RNS.2020022.v1.4.hdf':Grid:B10 C:\\Users\\mcecil\\CGA\\CDL\\tif\\HLS.S30.T14RNS.2020022.v1.4\\HLS.S30.T14RNS.2020022.v1.4__Cirrus.tif' returned non-zero exit status 1.\n",
      "ERROR DURING CONVERSION WITH CMD: gdal_translate HDF4_EOS:EOS_GRID:'C:\\Users\\mcecil\\CGA\\CDL\\hdf\\HLS.S30.T14RNS.2020022.v1.4.hdf':Grid:B11 C:\\Users\\mcecil\\CGA\\CDL\\tif\\HLS.S30.T14RNS.2020022.v1.4\\HLS.S30.T14RNS.2020022.v1.4__SWIR1.tif.\n",
      "Traceback (most recent call last):\n",
      "  File \"C:\\Users\\mcecil\\AppData\\Local\\anaconda3\\envs\\IBM_CDL\\lib\\site-packages\\nasa_hls\\hdf2tiff_conversion.py\", line 82, in convert_hdf2tiffs\n",
      "    subprocess.check_call(cmd, shell=True)\n",
      "  File \"C:\\Users\\mcecil\\AppData\\Local\\anaconda3\\envs\\IBM_CDL\\lib\\subprocess.py\", line 369, in check_call\n",
      "    raise CalledProcessError(retcode, cmd)\n",
      "subprocess.CalledProcessError: Command 'gdal_translate HDF4_EOS:EOS_GRID:'C:\\Users\\mcecil\\CGA\\CDL\\hdf\\HLS.S30.T14RNS.2020022.v1.4.hdf':Grid:B11 C:\\Users\\mcecil\\CGA\\CDL\\tif\\HLS.S30.T14RNS.2020022.v1.4\\HLS.S30.T14RNS.2020022.v1.4__SWIR1.tif' returned non-zero exit status 1.\n",
      "ERROR DURING CONVERSION WITH CMD: gdal_translate HDF4_EOS:EOS_GRID:'C:\\Users\\mcecil\\CGA\\CDL\\hdf\\HLS.S30.T14RNS.2020022.v1.4.hdf':Grid:B12 C:\\Users\\mcecil\\CGA\\CDL\\tif\\HLS.S30.T14RNS.2020022.v1.4\\HLS.S30.T14RNS.2020022.v1.4__SWIR2.tif.\n",
      "Traceback (most recent call last):\n",
      "  File \"C:\\Users\\mcecil\\AppData\\Local\\anaconda3\\envs\\IBM_CDL\\lib\\site-packages\\nasa_hls\\hdf2tiff_conversion.py\", line 82, in convert_hdf2tiffs\n",
      "    subprocess.check_call(cmd, shell=True)\n",
      "  File \"C:\\Users\\mcecil\\AppData\\Local\\anaconda3\\envs\\IBM_CDL\\lib\\subprocess.py\", line 369, in check_call\n",
      "    raise CalledProcessError(retcode, cmd)\n",
      "subprocess.CalledProcessError: Command 'gdal_translate HDF4_EOS:EOS_GRID:'C:\\Users\\mcecil\\CGA\\CDL\\hdf\\HLS.S30.T14RNS.2020022.v1.4.hdf':Grid:B12 C:\\Users\\mcecil\\CGA\\CDL\\tif\\HLS.S30.T14RNS.2020022.v1.4\\HLS.S30.T14RNS.2020022.v1.4__SWIR2.tif' returned non-zero exit status 1.\n",
      "ERROR DURING CONVERSION WITH CMD: gdal_translate HDF4_EOS:EOS_GRID:'C:\\Users\\mcecil\\CGA\\CDL\\hdf\\HLS.S30.T14RNS.2020022.v1.4.hdf':Grid:QA C:\\Users\\mcecil\\CGA\\CDL\\tif\\HLS.S30.T14RNS.2020022.v1.4\\HLS.S30.T14RNS.2020022.v1.4__QA.tif.\n",
      "Traceback (most recent call last):\n",
      "  File \"C:\\Users\\mcecil\\AppData\\Local\\anaconda3\\envs\\IBM_CDL\\lib\\site-packages\\nasa_hls\\hdf2tiff_conversion.py\", line 82, in convert_hdf2tiffs\n",
      "    subprocess.check_call(cmd, shell=True)\n",
      "  File \"C:\\Users\\mcecil\\AppData\\Local\\anaconda3\\envs\\IBM_CDL\\lib\\subprocess.py\", line 369, in check_call\n",
      "    raise CalledProcessError(retcode, cmd)\n",
      "subprocess.CalledProcessError: Command 'gdal_translate HDF4_EOS:EOS_GRID:'C:\\Users\\mcecil\\CGA\\CDL\\hdf\\HLS.S30.T14RNS.2020022.v1.4.hdf':Grid:QA C:\\Users\\mcecil\\CGA\\CDL\\tif\\HLS.S30.T14RNS.2020022.v1.4\\HLS.S30.T14RNS.2020022.v1.4__QA.tif' returned non-zero exit status 1.\n",
      "ERROR DURING CONVERSION WITH CMD: gdal_translate HDF4_EOS:EOS_GRID:'C:\\Users\\mcecil\\CGA\\CDL\\hdf\\HLS.S30.T14RNS.2020027.v1.4.hdf':Grid:B01 C:\\Users\\mcecil\\CGA\\CDL\\tif\\HLS.S30.T14RNS.2020027.v1.4\\HLS.S30.T14RNS.2020027.v1.4__Coastal_Aerosol.tif.\n",
      "Traceback (most recent call last):\n",
      "  File \"C:\\Users\\mcecil\\AppData\\Local\\anaconda3\\envs\\IBM_CDL\\lib\\site-packages\\nasa_hls\\hdf2tiff_conversion.py\", line 82, in convert_hdf2tiffs\n",
      "    subprocess.check_call(cmd, shell=True)\n",
      "  File \"C:\\Users\\mcecil\\AppData\\Local\\anaconda3\\envs\\IBM_CDL\\lib\\subprocess.py\", line 369, in check_call\n",
      "    raise CalledProcessError(retcode, cmd)\n",
      "subprocess.CalledProcessError: Command 'gdal_translate HDF4_EOS:EOS_GRID:'C:\\Users\\mcecil\\CGA\\CDL\\hdf\\HLS.S30.T14RNS.2020027.v1.4.hdf':Grid:B01 C:\\Users\\mcecil\\CGA\\CDL\\tif\\HLS.S30.T14RNS.2020027.v1.4\\HLS.S30.T14RNS.2020027.v1.4__Coastal_Aerosol.tif' returned non-zero exit status 1.\n",
      "ERROR DURING CONVERSION WITH CMD: gdal_translate HDF4_EOS:EOS_GRID:'C:\\Users\\mcecil\\CGA\\CDL\\hdf\\HLS.S30.T14RNS.2020027.v1.4.hdf':Grid:B02 C:\\Users\\mcecil\\CGA\\CDL\\tif\\HLS.S30.T14RNS.2020027.v1.4\\HLS.S30.T14RNS.2020027.v1.4__Blue.tif.\n",
      "Traceback (most recent call last):\n",
      "  File \"C:\\Users\\mcecil\\AppData\\Local\\anaconda3\\envs\\IBM_CDL\\lib\\site-packages\\nasa_hls\\hdf2tiff_conversion.py\", line 82, in convert_hdf2tiffs\n",
      "    subprocess.check_call(cmd, shell=True)\n",
      "  File \"C:\\Users\\mcecil\\AppData\\Local\\anaconda3\\envs\\IBM_CDL\\lib\\subprocess.py\", line 369, in check_call\n",
      "    raise CalledProcessError(retcode, cmd)\n",
      "subprocess.CalledProcessError: Command 'gdal_translate HDF4_EOS:EOS_GRID:'C:\\Users\\mcecil\\CGA\\CDL\\hdf\\HLS.S30.T14RNS.2020027.v1.4.hdf':Grid:B02 C:\\Users\\mcecil\\CGA\\CDL\\tif\\HLS.S30.T14RNS.2020027.v1.4\\HLS.S30.T14RNS.2020027.v1.4__Blue.tif' returned non-zero exit status 1.\n",
      "ERROR DURING CONVERSION WITH CMD: gdal_translate HDF4_EOS:EOS_GRID:'C:\\Users\\mcecil\\CGA\\CDL\\hdf\\HLS.S30.T14RNS.2020027.v1.4.hdf':Grid:B03 C:\\Users\\mcecil\\CGA\\CDL\\tif\\HLS.S30.T14RNS.2020027.v1.4\\HLS.S30.T14RNS.2020027.v1.4__Green.tif.\n",
      "Traceback (most recent call last):\n",
      "  File \"C:\\Users\\mcecil\\AppData\\Local\\anaconda3\\envs\\IBM_CDL\\lib\\site-packages\\nasa_hls\\hdf2tiff_conversion.py\", line 82, in convert_hdf2tiffs\n",
      "    subprocess.check_call(cmd, shell=True)\n",
      "  File \"C:\\Users\\mcecil\\AppData\\Local\\anaconda3\\envs\\IBM_CDL\\lib\\subprocess.py\", line 369, in check_call\n",
      "    raise CalledProcessError(retcode, cmd)\n",
      "subprocess.CalledProcessError: Command 'gdal_translate HDF4_EOS:EOS_GRID:'C:\\Users\\mcecil\\CGA\\CDL\\hdf\\HLS.S30.T14RNS.2020027.v1.4.hdf':Grid:B03 C:\\Users\\mcecil\\CGA\\CDL\\tif\\HLS.S30.T14RNS.2020027.v1.4\\HLS.S30.T14RNS.2020027.v1.4__Green.tif' returned non-zero exit status 1.\n",
      "ERROR DURING CONVERSION WITH CMD: gdal_translate HDF4_EOS:EOS_GRID:'C:\\Users\\mcecil\\CGA\\CDL\\hdf\\HLS.S30.T14RNS.2020027.v1.4.hdf':Grid:B04 C:\\Users\\mcecil\\CGA\\CDL\\tif\\HLS.S30.T14RNS.2020027.v1.4\\HLS.S30.T14RNS.2020027.v1.4__Red.tif.\n",
      "Traceback (most recent call last):\n",
      "  File \"C:\\Users\\mcecil\\AppData\\Local\\anaconda3\\envs\\IBM_CDL\\lib\\site-packages\\nasa_hls\\hdf2tiff_conversion.py\", line 82, in convert_hdf2tiffs\n",
      "    subprocess.check_call(cmd, shell=True)\n",
      "  File \"C:\\Users\\mcecil\\AppData\\Local\\anaconda3\\envs\\IBM_CDL\\lib\\subprocess.py\", line 369, in check_call\n",
      "    raise CalledProcessError(retcode, cmd)\n",
      "subprocess.CalledProcessError: Command 'gdal_translate HDF4_EOS:EOS_GRID:'C:\\Users\\mcecil\\CGA\\CDL\\hdf\\HLS.S30.T14RNS.2020027.v1.4.hdf':Grid:B04 C:\\Users\\mcecil\\CGA\\CDL\\tif\\HLS.S30.T14RNS.2020027.v1.4\\HLS.S30.T14RNS.2020027.v1.4__Red.tif' returned non-zero exit status 1.\n",
      "ERROR DURING CONVERSION WITH CMD: gdal_translate HDF4_EOS:EOS_GRID:'C:\\Users\\mcecil\\CGA\\CDL\\hdf\\HLS.S30.T14RNS.2020027.v1.4.hdf':Grid:B05 C:\\Users\\mcecil\\CGA\\CDL\\tif\\HLS.S30.T14RNS.2020027.v1.4\\HLS.S30.T14RNS.2020027.v1.4__Red_Edge1.tif.\n",
      "Traceback (most recent call last):\n",
      "  File \"C:\\Users\\mcecil\\AppData\\Local\\anaconda3\\envs\\IBM_CDL\\lib\\site-packages\\nasa_hls\\hdf2tiff_conversion.py\", line 82, in convert_hdf2tiffs\n",
      "    subprocess.check_call(cmd, shell=True)\n",
      "  File \"C:\\Users\\mcecil\\AppData\\Local\\anaconda3\\envs\\IBM_CDL\\lib\\subprocess.py\", line 369, in check_call\n",
      "    raise CalledProcessError(retcode, cmd)\n",
      "subprocess.CalledProcessError: Command 'gdal_translate HDF4_EOS:EOS_GRID:'C:\\Users\\mcecil\\CGA\\CDL\\hdf\\HLS.S30.T14RNS.2020027.v1.4.hdf':Grid:B05 C:\\Users\\mcecil\\CGA\\CDL\\tif\\HLS.S30.T14RNS.2020027.v1.4\\HLS.S30.T14RNS.2020027.v1.4__Red_Edge1.tif' returned non-zero exit status 1.\n",
      "ERROR DURING CONVERSION WITH CMD: gdal_translate HDF4_EOS:EOS_GRID:'C:\\Users\\mcecil\\CGA\\CDL\\hdf\\HLS.S30.T14RNS.2020027.v1.4.hdf':Grid:B06 C:\\Users\\mcecil\\CGA\\CDL\\tif\\HLS.S30.T14RNS.2020027.v1.4\\HLS.S30.T14RNS.2020027.v1.4__Red_Edge2.tif.\n",
      "Traceback (most recent call last):\n",
      "  File \"C:\\Users\\mcecil\\AppData\\Local\\anaconda3\\envs\\IBM_CDL\\lib\\site-packages\\nasa_hls\\hdf2tiff_conversion.py\", line 82, in convert_hdf2tiffs\n",
      "    subprocess.check_call(cmd, shell=True)\n",
      "  File \"C:\\Users\\mcecil\\AppData\\Local\\anaconda3\\envs\\IBM_CDL\\lib\\subprocess.py\", line 369, in check_call\n",
      "    raise CalledProcessError(retcode, cmd)\n",
      "subprocess.CalledProcessError: Command 'gdal_translate HDF4_EOS:EOS_GRID:'C:\\Users\\mcecil\\CGA\\CDL\\hdf\\HLS.S30.T14RNS.2020027.v1.4.hdf':Grid:B06 C:\\Users\\mcecil\\CGA\\CDL\\tif\\HLS.S30.T14RNS.2020027.v1.4\\HLS.S30.T14RNS.2020027.v1.4__Red_Edge2.tif' returned non-zero exit status 1.\n",
      "ERROR DURING CONVERSION WITH CMD: gdal_translate HDF4_EOS:EOS_GRID:'C:\\Users\\mcecil\\CGA\\CDL\\hdf\\HLS.S30.T14RNS.2020027.v1.4.hdf':Grid:B07 C:\\Users\\mcecil\\CGA\\CDL\\tif\\HLS.S30.T14RNS.2020027.v1.4\\HLS.S30.T14RNS.2020027.v1.4__Red_Edge3.tif.\n",
      "Traceback (most recent call last):\n",
      "  File \"C:\\Users\\mcecil\\AppData\\Local\\anaconda3\\envs\\IBM_CDL\\lib\\site-packages\\nasa_hls\\hdf2tiff_conversion.py\", line 82, in convert_hdf2tiffs\n",
      "    subprocess.check_call(cmd, shell=True)\n",
      "  File \"C:\\Users\\mcecil\\AppData\\Local\\anaconda3\\envs\\IBM_CDL\\lib\\subprocess.py\", line 369, in check_call\n",
      "    raise CalledProcessError(retcode, cmd)\n",
      "subprocess.CalledProcessError: Command 'gdal_translate HDF4_EOS:EOS_GRID:'C:\\Users\\mcecil\\CGA\\CDL\\hdf\\HLS.S30.T14RNS.2020027.v1.4.hdf':Grid:B07 C:\\Users\\mcecil\\CGA\\CDL\\tif\\HLS.S30.T14RNS.2020027.v1.4\\HLS.S30.T14RNS.2020027.v1.4__Red_Edge3.tif' returned non-zero exit status 1.\n",
      "ERROR DURING CONVERSION WITH CMD: gdal_translate HDF4_EOS:EOS_GRID:'C:\\Users\\mcecil\\CGA\\CDL\\hdf\\HLS.S30.T14RNS.2020027.v1.4.hdf':Grid:B08 C:\\Users\\mcecil\\CGA\\CDL\\tif\\HLS.S30.T14RNS.2020027.v1.4\\HLS.S30.T14RNS.2020027.v1.4__NIR_Broad.tif.\n",
      "Traceback (most recent call last):\n",
      "  File \"C:\\Users\\mcecil\\AppData\\Local\\anaconda3\\envs\\IBM_CDL\\lib\\site-packages\\nasa_hls\\hdf2tiff_conversion.py\", line 82, in convert_hdf2tiffs\n",
      "    subprocess.check_call(cmd, shell=True)\n",
      "  File \"C:\\Users\\mcecil\\AppData\\Local\\anaconda3\\envs\\IBM_CDL\\lib\\subprocess.py\", line 369, in check_call\n",
      "    raise CalledProcessError(retcode, cmd)\n",
      "subprocess.CalledProcessError: Command 'gdal_translate HDF4_EOS:EOS_GRID:'C:\\Users\\mcecil\\CGA\\CDL\\hdf\\HLS.S30.T14RNS.2020027.v1.4.hdf':Grid:B08 C:\\Users\\mcecil\\CGA\\CDL\\tif\\HLS.S30.T14RNS.2020027.v1.4\\HLS.S30.T14RNS.2020027.v1.4__NIR_Broad.tif' returned non-zero exit status 1.\n",
      "ERROR DURING CONVERSION WITH CMD: gdal_translate HDF4_EOS:EOS_GRID:'C:\\Users\\mcecil\\CGA\\CDL\\hdf\\HLS.S30.T14RNS.2020027.v1.4.hdf':Grid:B8A C:\\Users\\mcecil\\CGA\\CDL\\tif\\HLS.S30.T14RNS.2020027.v1.4\\HLS.S30.T14RNS.2020027.v1.4__NIR_Narrow.tif.\n",
      "Traceback (most recent call last):\n",
      "  File \"C:\\Users\\mcecil\\AppData\\Local\\anaconda3\\envs\\IBM_CDL\\lib\\site-packages\\nasa_hls\\hdf2tiff_conversion.py\", line 82, in convert_hdf2tiffs\n",
      "    subprocess.check_call(cmd, shell=True)\n",
      "  File \"C:\\Users\\mcecil\\AppData\\Local\\anaconda3\\envs\\IBM_CDL\\lib\\subprocess.py\", line 369, in check_call\n",
      "    raise CalledProcessError(retcode, cmd)\n",
      "subprocess.CalledProcessError: Command 'gdal_translate HDF4_EOS:EOS_GRID:'C:\\Users\\mcecil\\CGA\\CDL\\hdf\\HLS.S30.T14RNS.2020027.v1.4.hdf':Grid:B8A C:\\Users\\mcecil\\CGA\\CDL\\tif\\HLS.S30.T14RNS.2020027.v1.4\\HLS.S30.T14RNS.2020027.v1.4__NIR_Narrow.tif' returned non-zero exit status 1.\n",
      "ERROR DURING CONVERSION WITH CMD: gdal_translate HDF4_EOS:EOS_GRID:'C:\\Users\\mcecil\\CGA\\CDL\\hdf\\HLS.S30.T14RNS.2020027.v1.4.hdf':Grid:B09 C:\\Users\\mcecil\\CGA\\CDL\\tif\\HLS.S30.T14RNS.2020027.v1.4\\HLS.S30.T14RNS.2020027.v1.4__Water_Vapor.tif.\n",
      "Traceback (most recent call last):\n",
      "  File \"C:\\Users\\mcecil\\AppData\\Local\\anaconda3\\envs\\IBM_CDL\\lib\\site-packages\\nasa_hls\\hdf2tiff_conversion.py\", line 82, in convert_hdf2tiffs\n",
      "    subprocess.check_call(cmd, shell=True)\n",
      "  File \"C:\\Users\\mcecil\\AppData\\Local\\anaconda3\\envs\\IBM_CDL\\lib\\subprocess.py\", line 369, in check_call\n",
      "    raise CalledProcessError(retcode, cmd)\n",
      "subprocess.CalledProcessError: Command 'gdal_translate HDF4_EOS:EOS_GRID:'C:\\Users\\mcecil\\CGA\\CDL\\hdf\\HLS.S30.T14RNS.2020027.v1.4.hdf':Grid:B09 C:\\Users\\mcecil\\CGA\\CDL\\tif\\HLS.S30.T14RNS.2020027.v1.4\\HLS.S30.T14RNS.2020027.v1.4__Water_Vapor.tif' returned non-zero exit status 1.\n",
      "ERROR DURING CONVERSION WITH CMD: gdal_translate HDF4_EOS:EOS_GRID:'C:\\Users\\mcecil\\CGA\\CDL\\hdf\\HLS.S30.T14RNS.2020027.v1.4.hdf':Grid:B10 C:\\Users\\mcecil\\CGA\\CDL\\tif\\HLS.S30.T14RNS.2020027.v1.4\\HLS.S30.T14RNS.2020027.v1.4__Cirrus.tif.\n",
      "Traceback (most recent call last):\n",
      "  File \"C:\\Users\\mcecil\\AppData\\Local\\anaconda3\\envs\\IBM_CDL\\lib\\site-packages\\nasa_hls\\hdf2tiff_conversion.py\", line 82, in convert_hdf2tiffs\n",
      "    subprocess.check_call(cmd, shell=True)\n",
      "  File \"C:\\Users\\mcecil\\AppData\\Local\\anaconda3\\envs\\IBM_CDL\\lib\\subprocess.py\", line 369, in check_call\n",
      "    raise CalledProcessError(retcode, cmd)\n",
      "subprocess.CalledProcessError: Command 'gdal_translate HDF4_EOS:EOS_GRID:'C:\\Users\\mcecil\\CGA\\CDL\\hdf\\HLS.S30.T14RNS.2020027.v1.4.hdf':Grid:B10 C:\\Users\\mcecil\\CGA\\CDL\\tif\\HLS.S30.T14RNS.2020027.v1.4\\HLS.S30.T14RNS.2020027.v1.4__Cirrus.tif' returned non-zero exit status 1.\n",
      "ERROR DURING CONVERSION WITH CMD: gdal_translate HDF4_EOS:EOS_GRID:'C:\\Users\\mcecil\\CGA\\CDL\\hdf\\HLS.S30.T14RNS.2020027.v1.4.hdf':Grid:B11 C:\\Users\\mcecil\\CGA\\CDL\\tif\\HLS.S30.T14RNS.2020027.v1.4\\HLS.S30.T14RNS.2020027.v1.4__SWIR1.tif.\n",
      "Traceback (most recent call last):\n",
      "  File \"C:\\Users\\mcecil\\AppData\\Local\\anaconda3\\envs\\IBM_CDL\\lib\\site-packages\\nasa_hls\\hdf2tiff_conversion.py\", line 82, in convert_hdf2tiffs\n",
      "    subprocess.check_call(cmd, shell=True)\n",
      "  File \"C:\\Users\\mcecil\\AppData\\Local\\anaconda3\\envs\\IBM_CDL\\lib\\subprocess.py\", line 369, in check_call\n",
      "    raise CalledProcessError(retcode, cmd)\n",
      "subprocess.CalledProcessError: Command 'gdal_translate HDF4_EOS:EOS_GRID:'C:\\Users\\mcecil\\CGA\\CDL\\hdf\\HLS.S30.T14RNS.2020027.v1.4.hdf':Grid:B11 C:\\Users\\mcecil\\CGA\\CDL\\tif\\HLS.S30.T14RNS.2020027.v1.4\\HLS.S30.T14RNS.2020027.v1.4__SWIR1.tif' returned non-zero exit status 1.\n",
      "ERROR DURING CONVERSION WITH CMD: gdal_translate HDF4_EOS:EOS_GRID:'C:\\Users\\mcecil\\CGA\\CDL\\hdf\\HLS.S30.T14RNS.2020027.v1.4.hdf':Grid:B12 C:\\Users\\mcecil\\CGA\\CDL\\tif\\HLS.S30.T14RNS.2020027.v1.4\\HLS.S30.T14RNS.2020027.v1.4__SWIR2.tif.\n",
      "Traceback (most recent call last):\n",
      "  File \"C:\\Users\\mcecil\\AppData\\Local\\anaconda3\\envs\\IBM_CDL\\lib\\site-packages\\nasa_hls\\hdf2tiff_conversion.py\", line 82, in convert_hdf2tiffs\n",
      "    subprocess.check_call(cmd, shell=True)\n",
      "  File \"C:\\Users\\mcecil\\AppData\\Local\\anaconda3\\envs\\IBM_CDL\\lib\\subprocess.py\", line 369, in check_call\n",
      "    raise CalledProcessError(retcode, cmd)\n",
      "subprocess.CalledProcessError: Command 'gdal_translate HDF4_EOS:EOS_GRID:'C:\\Users\\mcecil\\CGA\\CDL\\hdf\\HLS.S30.T14RNS.2020027.v1.4.hdf':Grid:B12 C:\\Users\\mcecil\\CGA\\CDL\\tif\\HLS.S30.T14RNS.2020027.v1.4\\HLS.S30.T14RNS.2020027.v1.4__SWIR2.tif' returned non-zero exit status 1.\n",
      "ERROR DURING CONVERSION WITH CMD: gdal_translate HDF4_EOS:EOS_GRID:'C:\\Users\\mcecil\\CGA\\CDL\\hdf\\HLS.S30.T14RNS.2020027.v1.4.hdf':Grid:QA C:\\Users\\mcecil\\CGA\\CDL\\tif\\HLS.S30.T14RNS.2020027.v1.4\\HLS.S30.T14RNS.2020027.v1.4__QA.tif.\n",
      "Traceback (most recent call last):\n",
      "  File \"C:\\Users\\mcecil\\AppData\\Local\\anaconda3\\envs\\IBM_CDL\\lib\\site-packages\\nasa_hls\\hdf2tiff_conversion.py\", line 82, in convert_hdf2tiffs\n",
      "    subprocess.check_call(cmd, shell=True)\n",
      "  File \"C:\\Users\\mcecil\\AppData\\Local\\anaconda3\\envs\\IBM_CDL\\lib\\subprocess.py\", line 369, in check_call\n",
      "    raise CalledProcessError(retcode, cmd)\n",
      "subprocess.CalledProcessError: Command 'gdal_translate HDF4_EOS:EOS_GRID:'C:\\Users\\mcecil\\CGA\\CDL\\hdf\\HLS.S30.T14RNS.2020027.v1.4.hdf':Grid:QA C:\\Users\\mcecil\\CGA\\CDL\\tif\\HLS.S30.T14RNS.2020027.v1.4\\HLS.S30.T14RNS.2020027.v1.4__QA.tif' returned non-zero exit status 1.\n",
      "ERROR DURING CONVERSION WITH CMD: gdal_translate HDF4_EOS:EOS_GRID:'C:\\Users\\mcecil\\CGA\\CDL\\hdf\\HLS.S30.T14RNS.2020032.v1.4.hdf':Grid:B01 C:\\Users\\mcecil\\CGA\\CDL\\tif\\HLS.S30.T14RNS.2020032.v1.4\\HLS.S30.T14RNS.2020032.v1.4__Coastal_Aerosol.tif.\n",
      "Traceback (most recent call last):\n",
      "  File \"C:\\Users\\mcecil\\AppData\\Local\\anaconda3\\envs\\IBM_CDL\\lib\\site-packages\\nasa_hls\\hdf2tiff_conversion.py\", line 82, in convert_hdf2tiffs\n",
      "    subprocess.check_call(cmd, shell=True)\n",
      "  File \"C:\\Users\\mcecil\\AppData\\Local\\anaconda3\\envs\\IBM_CDL\\lib\\subprocess.py\", line 369, in check_call\n",
      "    raise CalledProcessError(retcode, cmd)\n",
      "subprocess.CalledProcessError: Command 'gdal_translate HDF4_EOS:EOS_GRID:'C:\\Users\\mcecil\\CGA\\CDL\\hdf\\HLS.S30.T14RNS.2020032.v1.4.hdf':Grid:B01 C:\\Users\\mcecil\\CGA\\CDL\\tif\\HLS.S30.T14RNS.2020032.v1.4\\HLS.S30.T14RNS.2020032.v1.4__Coastal_Aerosol.tif' returned non-zero exit status 1.\n",
      "ERROR DURING CONVERSION WITH CMD: gdal_translate HDF4_EOS:EOS_GRID:'C:\\Users\\mcecil\\CGA\\CDL\\hdf\\HLS.S30.T14RNS.2020032.v1.4.hdf':Grid:B02 C:\\Users\\mcecil\\CGA\\CDL\\tif\\HLS.S30.T14RNS.2020032.v1.4\\HLS.S30.T14RNS.2020032.v1.4__Blue.tif.\n",
      "Traceback (most recent call last):\n",
      "  File \"C:\\Users\\mcecil\\AppData\\Local\\anaconda3\\envs\\IBM_CDL\\lib\\site-packages\\nasa_hls\\hdf2tiff_conversion.py\", line 82, in convert_hdf2tiffs\n",
      "    subprocess.check_call(cmd, shell=True)\n",
      "  File \"C:\\Users\\mcecil\\AppData\\Local\\anaconda3\\envs\\IBM_CDL\\lib\\subprocess.py\", line 369, in check_call\n",
      "    raise CalledProcessError(retcode, cmd)\n",
      "subprocess.CalledProcessError: Command 'gdal_translate HDF4_EOS:EOS_GRID:'C:\\Users\\mcecil\\CGA\\CDL\\hdf\\HLS.S30.T14RNS.2020032.v1.4.hdf':Grid:B02 C:\\Users\\mcecil\\CGA\\CDL\\tif\\HLS.S30.T14RNS.2020032.v1.4\\HLS.S30.T14RNS.2020032.v1.4__Blue.tif' returned non-zero exit status 1.\n",
      "ERROR DURING CONVERSION WITH CMD: gdal_translate HDF4_EOS:EOS_GRID:'C:\\Users\\mcecil\\CGA\\CDL\\hdf\\HLS.S30.T14RNS.2020032.v1.4.hdf':Grid:B03 C:\\Users\\mcecil\\CGA\\CDL\\tif\\HLS.S30.T14RNS.2020032.v1.4\\HLS.S30.T14RNS.2020032.v1.4__Green.tif.\n",
      "Traceback (most recent call last):\n",
      "  File \"C:\\Users\\mcecil\\AppData\\Local\\anaconda3\\envs\\IBM_CDL\\lib\\site-packages\\nasa_hls\\hdf2tiff_conversion.py\", line 82, in convert_hdf2tiffs\n",
      "    subprocess.check_call(cmd, shell=True)\n",
      "  File \"C:\\Users\\mcecil\\AppData\\Local\\anaconda3\\envs\\IBM_CDL\\lib\\subprocess.py\", line 369, in check_call\n",
      "    raise CalledProcessError(retcode, cmd)\n",
      "subprocess.CalledProcessError: Command 'gdal_translate HDF4_EOS:EOS_GRID:'C:\\Users\\mcecil\\CGA\\CDL\\hdf\\HLS.S30.T14RNS.2020032.v1.4.hdf':Grid:B03 C:\\Users\\mcecil\\CGA\\CDL\\tif\\HLS.S30.T14RNS.2020032.v1.4\\HLS.S30.T14RNS.2020032.v1.4__Green.tif' returned non-zero exit status 1.\n",
      "ERROR DURING CONVERSION WITH CMD: gdal_translate HDF4_EOS:EOS_GRID:'C:\\Users\\mcecil\\CGA\\CDL\\hdf\\HLS.S30.T14RNS.2020032.v1.4.hdf':Grid:B04 C:\\Users\\mcecil\\CGA\\CDL\\tif\\HLS.S30.T14RNS.2020032.v1.4\\HLS.S30.T14RNS.2020032.v1.4__Red.tif.\n",
      "Traceback (most recent call last):\n",
      "  File \"C:\\Users\\mcecil\\AppData\\Local\\anaconda3\\envs\\IBM_CDL\\lib\\site-packages\\nasa_hls\\hdf2tiff_conversion.py\", line 82, in convert_hdf2tiffs\n",
      "    subprocess.check_call(cmd, shell=True)\n",
      "  File \"C:\\Users\\mcecil\\AppData\\Local\\anaconda3\\envs\\IBM_CDL\\lib\\subprocess.py\", line 369, in check_call\n",
      "    raise CalledProcessError(retcode, cmd)\n",
      "subprocess.CalledProcessError: Command 'gdal_translate HDF4_EOS:EOS_GRID:'C:\\Users\\mcecil\\CGA\\CDL\\hdf\\HLS.S30.T14RNS.2020032.v1.4.hdf':Grid:B04 C:\\Users\\mcecil\\CGA\\CDL\\tif\\HLS.S30.T14RNS.2020032.v1.4\\HLS.S30.T14RNS.2020032.v1.4__Red.tif' returned non-zero exit status 1.\n",
      "ERROR DURING CONVERSION WITH CMD: gdal_translate HDF4_EOS:EOS_GRID:'C:\\Users\\mcecil\\CGA\\CDL\\hdf\\HLS.S30.T14RNS.2020032.v1.4.hdf':Grid:B05 C:\\Users\\mcecil\\CGA\\CDL\\tif\\HLS.S30.T14RNS.2020032.v1.4\\HLS.S30.T14RNS.2020032.v1.4__Red_Edge1.tif.\n",
      "Traceback (most recent call last):\n",
      "  File \"C:\\Users\\mcecil\\AppData\\Local\\anaconda3\\envs\\IBM_CDL\\lib\\site-packages\\nasa_hls\\hdf2tiff_conversion.py\", line 82, in convert_hdf2tiffs\n",
      "    subprocess.check_call(cmd, shell=True)\n",
      "  File \"C:\\Users\\mcecil\\AppData\\Local\\anaconda3\\envs\\IBM_CDL\\lib\\subprocess.py\", line 369, in check_call\n",
      "    raise CalledProcessError(retcode, cmd)\n",
      "subprocess.CalledProcessError: Command 'gdal_translate HDF4_EOS:EOS_GRID:'C:\\Users\\mcecil\\CGA\\CDL\\hdf\\HLS.S30.T14RNS.2020032.v1.4.hdf':Grid:B05 C:\\Users\\mcecil\\CGA\\CDL\\tif\\HLS.S30.T14RNS.2020032.v1.4\\HLS.S30.T14RNS.2020032.v1.4__Red_Edge1.tif' returned non-zero exit status 1.\n"
     ]
    },
    {
     "ename": "KeyboardInterrupt",
     "evalue": "",
     "output_type": "error",
     "traceback": [
      "\u001b[1;31m---------------------------------------------------------------------------\u001b[0m",
      "\u001b[1;31mKeyboardInterrupt\u001b[0m                         Traceback (most recent call last)",
      "Cell \u001b[1;32mIn[19], line 32\u001b[0m\n\u001b[0;32m     29\u001b[0m \u001b[38;5;28;01mfor\u001b[39;00m cd, ct, cu \u001b[38;5;129;01min\u001b[39;00m \u001b[38;5;28mzip\u001b[39m(candidate_dates, candidate_tiles, candidate_urls):\n\u001b[0;32m     30\u001b[0m    \u001b[38;5;66;03m# print(cu)\u001b[39;00m\n\u001b[0;32m     31\u001b[0m     local_name \u001b[38;5;241m=\u001b[39m cu\u001b[38;5;241m.\u001b[39msplit(\u001b[38;5;124m'\u001b[39m\u001b[38;5;124m/\u001b[39m\u001b[38;5;124m'\u001b[39m)[\u001b[38;5;241m-\u001b[39m\u001b[38;5;241m1\u001b[39m]\u001b[38;5;241m.\u001b[39mreplace(\u001b[38;5;124m\"\u001b[39m\u001b[38;5;130;01m\\n\u001b[39;00m\u001b[38;5;124m\"\u001b[39m, \u001b[38;5;124m\"\u001b[39m\u001b[38;5;124m\"\u001b[39m)\n\u001b[1;32m---> 32\u001b[0m     \u001b[43mnasa_hls\u001b[49m\u001b[38;5;241;43m.\u001b[39;49m\u001b[43mconvert_hdf2tiffs\u001b[49m\u001b[43m(\u001b[49m\u001b[43mPath\u001b[49m\u001b[43m(\u001b[49m\u001b[43mhdf_dir\u001b[49m\u001b[38;5;241;43m+\u001b[39;49m\u001b[43mlocal_name\u001b[49m\u001b[43m)\u001b[49m\u001b[43m,\u001b[49m\u001b[43m \u001b[49m\u001b[43mPath\u001b[49m\u001b[43m(\u001b[49m\u001b[43mtiff_dir\u001b[49m\u001b[43m)\u001b[49m\u001b[43m)\u001b[49m\n",
      "File \u001b[1;32m~\\AppData\\Local\\anaconda3\\envs\\IBM_CDL\\lib\\site-packages\\nasa_hls\\hdf2tiff_conversion.py:82\u001b[0m, in \u001b[0;36mconvert_hdf2tiffs\u001b[1;34m(hdf_path, dstdir, bands, max_cloud_coverage, gdal_translate_options)\u001b[0m\n\u001b[0;32m     80\u001b[0m dst\u001b[38;5;241m.\u001b[39mparent\u001b[38;5;241m.\u001b[39mmkdir(exist_ok\u001b[38;5;241m=\u001b[39m\u001b[38;5;28;01mTrue\u001b[39;00m, parents\u001b[38;5;241m=\u001b[39m\u001b[38;5;28;01mTrue\u001b[39;00m)\n\u001b[0;32m     81\u001b[0m \u001b[38;5;28;01mtry\u001b[39;00m:\n\u001b[1;32m---> 82\u001b[0m     \u001b[43msubprocess\u001b[49m\u001b[38;5;241;43m.\u001b[39;49m\u001b[43mcheck_call\u001b[49m\u001b[43m(\u001b[49m\u001b[43mcmd\u001b[49m\u001b[43m,\u001b[49m\u001b[43m \u001b[49m\u001b[43mshell\u001b[49m\u001b[38;5;241;43m=\u001b[39;49m\u001b[38;5;28;43;01mTrue\u001b[39;49;00m\u001b[43m)\u001b[49m\n\u001b[0;32m     83\u001b[0m \u001b[38;5;28;01mexcept\u001b[39;00m \u001b[38;5;167;01mException\u001b[39;00m:\n\u001b[0;32m     84\u001b[0m     log\u001b[38;5;241m.\u001b[39mexception(\u001b[38;5;124mf\u001b[39m\u001b[38;5;124m\"\u001b[39m\u001b[38;5;124mERROR DURING CONVERSION WITH CMD: \u001b[39m\u001b[38;5;132;01m{\u001b[39;00mcmd\u001b[38;5;132;01m}\u001b[39;00m\u001b[38;5;124m.\u001b[39m\u001b[38;5;124m\"\u001b[39m)\n",
      "File \u001b[1;32m~\\AppData\\Local\\anaconda3\\envs\\IBM_CDL\\lib\\subprocess.py:364\u001b[0m, in \u001b[0;36mcheck_call\u001b[1;34m(*popenargs, **kwargs)\u001b[0m\n\u001b[0;32m    354\u001b[0m \u001b[38;5;28;01mdef\u001b[39;00m \u001b[38;5;21mcheck_call\u001b[39m(\u001b[38;5;241m*\u001b[39mpopenargs, \u001b[38;5;241m*\u001b[39m\u001b[38;5;241m*\u001b[39mkwargs):\n\u001b[0;32m    355\u001b[0m     \u001b[38;5;124;03m\"\"\"Run command with arguments.  Wait for command to complete.  If\u001b[39;00m\n\u001b[0;32m    356\u001b[0m \u001b[38;5;124;03m    the exit code was zero then return, otherwise raise\u001b[39;00m\n\u001b[0;32m    357\u001b[0m \u001b[38;5;124;03m    CalledProcessError.  The CalledProcessError object will have the\u001b[39;00m\n\u001b[1;32m   (...)\u001b[0m\n\u001b[0;32m    362\u001b[0m \u001b[38;5;124;03m    check_call([\"ls\", \"-l\"])\u001b[39;00m\n\u001b[0;32m    363\u001b[0m \u001b[38;5;124;03m    \"\"\"\u001b[39;00m\n\u001b[1;32m--> 364\u001b[0m     retcode \u001b[38;5;241m=\u001b[39m call(\u001b[38;5;241m*\u001b[39mpopenargs, \u001b[38;5;241m*\u001b[39m\u001b[38;5;241m*\u001b[39mkwargs)\n\u001b[0;32m    365\u001b[0m     \u001b[38;5;28;01mif\u001b[39;00m retcode:\n\u001b[0;32m    366\u001b[0m         cmd \u001b[38;5;241m=\u001b[39m kwargs\u001b[38;5;241m.\u001b[39mget(\u001b[38;5;124m\"\u001b[39m\u001b[38;5;124margs\u001b[39m\u001b[38;5;124m\"\u001b[39m)\n",
      "File \u001b[1;32m~\\AppData\\Local\\anaconda3\\envs\\IBM_CDL\\lib\\subprocess.py:347\u001b[0m, in \u001b[0;36mcall\u001b[1;34m(timeout, *popenargs, **kwargs)\u001b[0m\n\u001b[0;32m    345\u001b[0m \u001b[38;5;28;01mwith\u001b[39;00m Popen(\u001b[38;5;241m*\u001b[39mpopenargs, \u001b[38;5;241m*\u001b[39m\u001b[38;5;241m*\u001b[39mkwargs) \u001b[38;5;28;01mas\u001b[39;00m p:\n\u001b[0;32m    346\u001b[0m     \u001b[38;5;28;01mtry\u001b[39;00m:\n\u001b[1;32m--> 347\u001b[0m         \u001b[38;5;28;01mreturn\u001b[39;00m \u001b[43mp\u001b[49m\u001b[38;5;241;43m.\u001b[39;49m\u001b[43mwait\u001b[49m\u001b[43m(\u001b[49m\u001b[43mtimeout\u001b[49m\u001b[38;5;241;43m=\u001b[39;49m\u001b[43mtimeout\u001b[49m\u001b[43m)\u001b[49m\n\u001b[0;32m    348\u001b[0m     \u001b[38;5;28;01mexcept\u001b[39;00m:  \u001b[38;5;66;03m# Including KeyboardInterrupt, wait handled that.\u001b[39;00m\n\u001b[0;32m    349\u001b[0m         p\u001b[38;5;241m.\u001b[39mkill()\n",
      "File \u001b[1;32m~\\AppData\\Local\\anaconda3\\envs\\IBM_CDL\\lib\\subprocess.py:1209\u001b[0m, in \u001b[0;36mPopen.wait\u001b[1;34m(self, timeout)\u001b[0m\n\u001b[0;32m   1207\u001b[0m     endtime \u001b[38;5;241m=\u001b[39m _time() \u001b[38;5;241m+\u001b[39m timeout\n\u001b[0;32m   1208\u001b[0m \u001b[38;5;28;01mtry\u001b[39;00m:\n\u001b[1;32m-> 1209\u001b[0m     \u001b[38;5;28;01mreturn\u001b[39;00m \u001b[38;5;28;43mself\u001b[39;49m\u001b[38;5;241;43m.\u001b[39;49m\u001b[43m_wait\u001b[49m\u001b[43m(\u001b[49m\u001b[43mtimeout\u001b[49m\u001b[38;5;241;43m=\u001b[39;49m\u001b[43mtimeout\u001b[49m\u001b[43m)\u001b[49m\n\u001b[0;32m   1210\u001b[0m \u001b[38;5;28;01mexcept\u001b[39;00m \u001b[38;5;167;01mKeyboardInterrupt\u001b[39;00m:\n\u001b[0;32m   1211\u001b[0m     \u001b[38;5;66;03m# https://bugs.python.org/issue25942\u001b[39;00m\n\u001b[0;32m   1212\u001b[0m     \u001b[38;5;66;03m# The first keyboard interrupt waits briefly for the child to\u001b[39;00m\n\u001b[0;32m   1213\u001b[0m     \u001b[38;5;66;03m# exit under the common assumption that it also received the ^C\u001b[39;00m\n\u001b[0;32m   1214\u001b[0m     \u001b[38;5;66;03m# generated SIGINT and will exit rapidly.\u001b[39;00m\n\u001b[0;32m   1215\u001b[0m     \u001b[38;5;28;01mif\u001b[39;00m timeout \u001b[38;5;129;01mis\u001b[39;00m \u001b[38;5;129;01mnot\u001b[39;00m \u001b[38;5;28;01mNone\u001b[39;00m:\n",
      "File \u001b[1;32m~\\AppData\\Local\\anaconda3\\envs\\IBM_CDL\\lib\\subprocess.py:1490\u001b[0m, in \u001b[0;36mPopen._wait\u001b[1;34m(self, timeout)\u001b[0m\n\u001b[0;32m   1487\u001b[0m     timeout_millis \u001b[38;5;241m=\u001b[39m \u001b[38;5;28mint\u001b[39m(timeout \u001b[38;5;241m*\u001b[39m \u001b[38;5;241m1000\u001b[39m)\n\u001b[0;32m   1488\u001b[0m \u001b[38;5;28;01mif\u001b[39;00m \u001b[38;5;28mself\u001b[39m\u001b[38;5;241m.\u001b[39mreturncode \u001b[38;5;129;01mis\u001b[39;00m \u001b[38;5;28;01mNone\u001b[39;00m:\n\u001b[0;32m   1489\u001b[0m     \u001b[38;5;66;03m# API note: Returns immediately if timeout_millis == 0.\u001b[39;00m\n\u001b[1;32m-> 1490\u001b[0m     result \u001b[38;5;241m=\u001b[39m \u001b[43m_winapi\u001b[49m\u001b[38;5;241;43m.\u001b[39;49m\u001b[43mWaitForSingleObject\u001b[49m\u001b[43m(\u001b[49m\u001b[38;5;28;43mself\u001b[39;49m\u001b[38;5;241;43m.\u001b[39;49m\u001b[43m_handle\u001b[49m\u001b[43m,\u001b[49m\n\u001b[0;32m   1491\u001b[0m \u001b[43m                                         \u001b[49m\u001b[43mtimeout_millis\u001b[49m\u001b[43m)\u001b[49m\n\u001b[0;32m   1492\u001b[0m     \u001b[38;5;28;01mif\u001b[39;00m result \u001b[38;5;241m==\u001b[39m _winapi\u001b[38;5;241m.\u001b[39mWAIT_TIMEOUT:\n\u001b[0;32m   1493\u001b[0m         \u001b[38;5;28;01mraise\u001b[39;00m TimeoutExpired(\u001b[38;5;28mself\u001b[39m\u001b[38;5;241m.\u001b[39margs, timeout)\n",
      "\u001b[1;31mKeyboardInterrupt\u001b[0m: "
     ]
    }
   ],
   "source": [
    "for aoi_ind in range(nfeatures):\n",
    "    aoi_row = aoi_src.iloc[aoi_ind]\n",
    "    print(aoi_row)\n",
    "    print(aoi_src.bounds)\n",
    "    aoi_x = float(aoi_row.centroid_x)\n",
    "    aoi_y = float(aoi_row.centroid_y)\n",
    "        \n",
    "    # Identify what tile the burn scar is in\n",
    "    s = (tile_x-aoi_x)**2+(tile_y-aoi_y)**2\n",
    "    tname = tile_name[np.argmin(s)]\n",
    "    print(s)\n",
    "    print(tname)\n",
    "    aoi_src.at[aoi_ind, 'tile'] = tname\n",
    "    aoi_src.at[aoi_ind, 'chip_id'] = 'chip_' + str(aoi_ind)\n",
    "    \n",
    "    # Subset potential images based on tile and date\n",
    "    tile_mask = qtile == tname\n",
    "    # Subset based on date\n",
    "    date_mask1 = (qyear == yoi[0])\n",
    "  #  diff = (qmonth-bs_month)%12\n",
    "   # date_mask2 = ((diff <= month_threshold[1]) & (diff >= month_threshold[0]))\n",
    "    date_mask = date_mask1  #& date_mask2\n",
    "    \n",
    "    mask = tile_mask & date_mask\n",
    "    candidate_dates = qdate[mask]\n",
    "    candidate_tiles = qtile[mask]\n",
    "    candidate_urls = qurl[mask]\n",
    "    # Loop through images and check cloud cover\n",
    "    for cd, ct, cu in zip(candidate_dates, candidate_tiles, candidate_urls):\n",
    "       # print(cu)\n",
    "        local_name = cu.split('/')[-1].replace(\"\\n\", \"\")\n",
    "        nasa_hls.convert_hdf2tiffs(Path(hdf_dir+local_name), Path(tiff_dir))"
   ]
  },
  {
   "cell_type": "markdown",
   "id": "26661253-3d2e-4441-83f4-7f60c19838b9",
   "metadata": {},
   "source": [
    "Convert HDF to single-layer TIF (Mike's way - works)"
   ]
  },
  {
   "cell_type": "code",
   "execution_count": 18,
   "id": "177418f1-9c60-493d-9f88-106c992964d7",
   "metadata": {},
   "outputs": [
    {
     "name": "stdout",
     "output_type": "stream",
     "text": [
      "C:/Users/mcecil/CGA/CDL/hdf\\HLS.S30.T14RNS.2020002.v1.4.hdf\n",
      "C:/Users/mcecil/CGA/CDL/hdf\\HLS.S30.T14RNS.2020005.v1.4.hdf\n"
     ]
    },
    {
     "ename": "KeyboardInterrupt",
     "evalue": "",
     "output_type": "error",
     "traceback": [
      "\u001b[1;31m---------------------------------------------------------------------------\u001b[0m",
      "\u001b[1;31mKeyboardInterrupt\u001b[0m                         Traceback (most recent call last)",
      "Cell \u001b[1;32mIn[18], line 17\u001b[0m\n\u001b[0;32m     15\u001b[0m  p \u001b[38;5;241m=\u001b[39m Popen(cmd, stdout\u001b[38;5;241m=\u001b[39mPIPE, shell\u001b[38;5;241m=\u001b[39m\u001b[38;5;28;01mTrue\u001b[39;00m)\n\u001b[0;32m     16\u001b[0m \u001b[38;5;66;03m# print(p)\u001b[39;00m\n\u001b[1;32m---> 17\u001b[0m  output, err \u001b[38;5;241m=\u001b[39m \u001b[43mp\u001b[49m\u001b[38;5;241;43m.\u001b[39;49m\u001b[43mcommunicate\u001b[49m\u001b[43m(\u001b[49m\u001b[43m)\u001b[49m\n",
      "File \u001b[1;32m~\\AppData\\Local\\anaconda3\\envs\\IBM_CDL\\lib\\subprocess.py:1141\u001b[0m, in \u001b[0;36mPopen.communicate\u001b[1;34m(self, input, timeout)\u001b[0m\n\u001b[0;32m   1139\u001b[0m     \u001b[38;5;28mself\u001b[39m\u001b[38;5;241m.\u001b[39m_stdin_write(\u001b[38;5;28minput\u001b[39m)\n\u001b[0;32m   1140\u001b[0m \u001b[38;5;28;01melif\u001b[39;00m \u001b[38;5;28mself\u001b[39m\u001b[38;5;241m.\u001b[39mstdout:\n\u001b[1;32m-> 1141\u001b[0m     stdout \u001b[38;5;241m=\u001b[39m \u001b[38;5;28;43mself\u001b[39;49m\u001b[38;5;241;43m.\u001b[39;49m\u001b[43mstdout\u001b[49m\u001b[38;5;241;43m.\u001b[39;49m\u001b[43mread\u001b[49m\u001b[43m(\u001b[49m\u001b[43m)\u001b[49m\n\u001b[0;32m   1142\u001b[0m     \u001b[38;5;28mself\u001b[39m\u001b[38;5;241m.\u001b[39mstdout\u001b[38;5;241m.\u001b[39mclose()\n\u001b[0;32m   1143\u001b[0m \u001b[38;5;28;01melif\u001b[39;00m \u001b[38;5;28mself\u001b[39m\u001b[38;5;241m.\u001b[39mstderr:\n",
      "\u001b[1;31mKeyboardInterrupt\u001b[0m: "
     ]
    }
   ],
   "source": [
    "from osgeo import gdal\n",
    "import glob\n",
    "from subprocess import Popen, PIPE\n",
    "\n",
    "bands = ['B01', 'B02', 'B03', 'B04', 'B05', 'B06', 'B07', 'B08', 'B8A', 'B09', 'B10', 'B11', 'B12', 'QA']\n",
    "\n",
    "\n",
    "hdf_files = glob.glob(hdf_dir + \"*.hdf\")\n",
    "for hdf_file in hdf_files:\n",
    "    print(hdf_file)\n",
    "    file_name = hdf_file.split('\\\\')[-1].replace('.hdf', '')\n",
    "    for long_band_name in bands:\n",
    "        cmd = f'gdal_translate HDF4_EOS:EOS_GRID:\"' + hdf_file + '\":Grid:' + long_band_name + ' ' + tiff_dir + file_name + '__' + long_band_name + '.tif'\n",
    "       # print(cmd)\n",
    "        p = Popen(cmd, stdout=PIPE, shell=True)\n",
    "       # print(p)\n",
    "        output, err = p.communicate()\n",
    "      #  print(output)\n",
    "       # print(err)\n",
    "  #  nasa_hls.convert_hdf2tif_dirfs(Path(hdf_file), Path(tif_dir_dir))\n",
    "    # ds = gdal.Open(hdf_file)\n",
    "    # ds_t = gdal.Translate('output.tif', hdf_file)\n",
    "#ds = None\n",
    "#print(ds)\n"
   ]
  },
  {
   "cell_type": "code",
   "execution_count": null,
   "id": "64161c5c-c37c-4237-9f99-2bd726c43491",
   "metadata": {},
   "outputs": [],
   "source": []
  }
 ],
 "metadata": {
  "kernelspec": {
   "display_name": "Python 3 (ipykernel)",
   "language": "python",
   "name": "python3"
  },
  "language_info": {
   "codemirror_mode": {
    "name": "ipython",
    "version": 3
   },
   "file_extension": ".py",
   "mimetype": "text/x-python",
   "name": "python",
   "nbconvert_exporter": "python",
   "pygments_lexer": "ipython3",
   "version": "3.10.10"
  }
 },
 "nbformat": 4,
 "nbformat_minor": 5
}
